<?xml version="1.0" ?>
<!-- =================================================================================== -->
<!-- |    This document was autogenerated by xacro from v0.urdf.xacro                  | -->
<!-- |    EDITING THIS FILE BY HAND IS NOT RECOMMENDED                                 | -->
<!-- =================================================================================== -->
<robot name="v0">
  <material name="grey">
    <color rgba="0.5 0.5 0.5 1"/>
  </material>
  <material name="white">
    <color rgba="1 1 1 1"/>
  </material>
  <material name="yellow">
    <color rgba="0.91 0.7 0.14 1"/>
  </material>
  <material name="red">
    <color rgba="0.71 0.14 0.14 1"/>
  </material>
  <link name="body">
    <visual>
      <geometry>
        <box size="1.3 0.3 0.1"/>
      </geometry>
      <material name="grey"/>
      <origin rpy="0 0 0" xyz="0 0 0.7"/>
    </visual>
    <collision>
      <geometry>
        <box size="1.3 0.3 0.1"/>
      </geometry>
      <origin rpy="0 0 0" xyz="0 0 0.7"/>
    </collision>
    <inertial>
      <mass value="6.240000000000001"/>
      <inertia ixx="0.052000000000000005" ixy="0.0" ixz="0.0" iyy="0.8840000000000001" iyz="0.0" izz="0.9256000000000002"/>
    </inertial>
  </link>
  <link name="l1_segment_1">
    <visual>
      <geometry>
        <box size="0.1 0.1 0.2"/>
      </geometry>
      <material name="white"/>
      <origin rpy="0 0 0" xyz="0 0 0.1"/>
    </visual>
    <collision>
      <geometry>
        <box size="0.1 0.1 0.2"/>
      </geometry>
      <origin rpy="0 0 0" xyz="0 0 0.1"/>
    </collision>
    <inertial>
      <mass value="0.32000000000000006"/>
      <inertia ixx="0.001333333333333334" ixy="0.0" ixz="0.0" iyy="0.001333333333333334" iyz="0.0" izz="0.0005333333333333336"/>
    </inertial>
  </link>
  <joint name="l1_base_to_joint_1" type="fixed">
    <parent link="body"/>
    <child link="l1_segment_1"/>
    <origin rpy="0 0 0" xyz="0.5 0.1 .75"/>
  </joint>
  <link name="l1_segment_2_HIP">
    <visual>
      <geometry>
        <box size="0.1 0.6 0.1"/>
      </geometry>
      <material name="yellow"/>
      <origin rpy="0 0 0" xyz="0 0.25 0"/>
    </visual>
    <collision>
      <geometry>
        <box size="0.1 0.6 0.1"/>
      </geometry>
      <origin rpy="0 0 0" xyz="0 0.25 0"/>
    </collision>
    <inertial>
      <mass value="0.96"/>
      <inertia ixx="0.029599999999999994" ixy="0.0" ixz="0.0" iyy="0.0016" iyz="0.0" izz="0.029599999999999994"/>
    </inertial>
  </link>
  <joint name="l1_joint_1_to_2" type="revolute">
    <parent link="l1_segment_1"/>
    <child link="l1_segment_2_HIP"/>
    <origin rpy="0 0 0" xyz="0 0 0.25"/>
    <axis xyz="0.0 0.0 1.0"/>
    <limit effort="55" lower="-1.2" upper="1.2" velocity="29"/>
  </joint>
  <link name="l1_segment_3_THIGH">
    <visual>
      <geometry>
        <box size="0.1 0.1 0.7"/>
      </geometry>
      <material name="red"/>
      <origin rpy="0 0 0" xyz="0 0 -0.3"/>
    </visual>
    <collision>
      <geometry>
        <box size="0.1 0.1 0.7"/>
      </geometry>
      <origin rpy="0 0 0" xyz="0 0 -0.3"/>
    </collision>
    <inertial>
      <mass value="1.12"/>
      <inertia ixx="0.04666666666666666" ixy="0.0" ixz="0.0" iyy="0.04666666666666666" iyz="0.0" izz="0.001866666666666667"/>
    </inertial>
  </link>
  <joint name="l1_joint_2_to_3" type="revolute">
    <parent link="l1_segment_2_HIP"/>
    <child link="l1_segment_3_THIGH"/>
    <origin rpy="0 0 0" xyz="-0.1 0.5 0"/>
    <axis xyz="1.0 0.0 0.0"/>
    <limit effort="55" lower="-0.2" upper="0.75" velocity="29"/>
  </joint>
  <link name="l1_segment_4_FOOT">
    <visual>
      <geometry>
        <box size="0.1 0.1 0.4"/>
      </geometry>
      <material name="yellow"/>
      <origin rpy="0 0 0" xyz="0 0 -0.2"/>
    </visual>
    <collision>
      <geometry>
        <box size="0.1 0.1 0.4"/>
      </geometry>
      <origin rpy="0 0 0" xyz="0 0 -0.2"/>
    </collision>
    <inertial>
      <mass value="0.6400000000000001"/>
      <inertia ixx="0.00906666666666667" ixy="0.0" ixz="0.0" iyy="0.00906666666666667" iyz="0.0" izz="0.0010666666666666672"/>
    </inertial>
  </link>
  <joint name="l1_joint_3_to_4_FOOT" type="revolute">
    <parent link="l1_segment_3_THIGH"/>
    <child link="l1_segment_4_FOOT"/>
    <origin rpy="0 0 0" xyz="0.1 0 -0.55"/>
    <axis xyz="1.0 0.0 0.0"/>
    <limit effort="55" lower="-0.2" upper="0.5" velocity="29"/>
  </joint>
  <link name="l2_segment_1">
    <visual>
      <geometry>
        <box size="0.1 0.1 0.2"/>
      </geometry>
      <material name="white"/>
      <origin rpy="0 0 0" xyz="0 0 0.1"/>
    </visual>
    <collision>
      <geometry>
        <box size="0.1 0.1 0.2"/>
      </geometry>
      <origin rpy="0 0 0" xyz="0 0 0.1"/>
    </collision>
    <inertial>
      <mass value="0.32000000000000006"/>
      <inertia ixx="0.001333333333333334" ixy="0.0" ixz="0.0" iyy="0.001333333333333334" iyz="0.0" izz="0.0005333333333333336"/>
    </inertial>
  </link>
  <joint name="l2_base_to_joint_1" type="fixed">
    <parent link="body"/>
    <child link="l2_segment_1"/>
    <origin rpy="0 0 0" xyz="0 0.1 .75"/>
  </joint>
  <link name="l2_segment_2_HIP">
    <visual>
      <geometry>
        <box size="0.1 0.6 0.1"/>
      </geometry>
      <material name="yellow"/>
      <origin rpy="0 0 0" xyz="0 0.25 0"/>
    </visual>
    <collision>
      <geometry>
        <box size="0.1 0.6 0.1"/>
      </geometry>
      <origin rpy="0 0 0" xyz="0 0.25 0"/>
    </collision>
    <inertial>
      <mass value="0.96"/>
      <inertia ixx="0.029599999999999994" ixy="0.0" ixz="0.0" iyy="0.0016" iyz="0.0" izz="0.029599999999999994"/>
    </inertial>
  </link>
  <joint name="l2_joint_1_to_2" type="revolute">
    <parent link="l2_segment_1"/>
    <child link="l2_segment_2_HIP"/>
    <origin rpy="0 0 0" xyz="0 0 0.25"/>
    <axis xyz="0.0 0.0 1.0"/>
    <limit effort="55" lower="-1.2" upper="1.2" velocity="29"/>
  </joint>
  <link name="l2_segment_3_THIGH">
    <visual>
      <geometry>
        <box size="0.1 0.1 0.7"/>
      </geometry>
      <material name="red"/>
      <origin rpy="0 0 0" xyz="0 0 -0.3"/>
    </visual>
    <collision>
      <geometry>
        <box size="0.1 0.1 0.7"/>
      </geometry>
      <origin rpy="0 0 0" xyz="0 0 -0.3"/>
    </collision>
    <inertial>
      <mass value="1.12"/>
      <inertia ixx="0.04666666666666666" ixy="0.0" ixz="0.0" iyy="0.04666666666666666" iyz="0.0" izz="0.001866666666666667"/>
    </inertial>
  </link>
  <joint name="l2_joint_2_to_3" type="revolute">
    <parent link="l2_segment_2_HIP"/>
    <child link="l2_segment_3_THIGH"/>
    <origin rpy="0 0 0" xyz="-0.1 0.5 0"/>
    <axis xyz="1.0 0.0 0.0"/>
    <limit effort="55" lower="-0.2" upper="0.75" velocity="29"/>
  </joint>
  <link name="l2_segment_4_FOOT">
    <visual>
      <geometry>
        <box size="0.1 0.1 0.4"/>
      </geometry>
      <material name="yellow"/>
      <origin rpy="0 0 0" xyz="0 0 -0.2"/>
    </visual>
    <collision>
      <geometry>
        <box size="0.1 0.1 0.4"/>
      </geometry>
      <origin rpy="0 0 0" xyz="0 0 -0.2"/>
    </collision>
    <inertial>
      <mass value="0.6400000000000001"/>
      <inertia ixx="0.00906666666666667" ixy="0.0" ixz="0.0" iyy="0.00906666666666667" iyz="0.0" izz="0.0010666666666666672"/>
    </inertial>
  </link>
  <joint name="l2_joint_3_to_4_FOOT" type="revolute">
    <parent link="l2_segment_3_THIGH"/>
    <child link="l2_segment_4_FOOT"/>
    <origin rpy="0 0 0" xyz="0.1 0 -0.55"/>
    <axis xyz="1.0 0.0 0.0"/>
    <limit effort="55" lower="-0.2" upper="0.5" velocity="29"/>
  </joint>
  <link name="l3_segment_1">
    <visual>
      <geometry>
        <box size="0.1 0.1 0.2"/>
      </geometry>
      <material name="white"/>
      <origin rpy="0 0 0" xyz="0 0 0.1"/>
    </visual>
    <collision>
      <geometry>
        <box size="0.1 0.1 0.2"/>
      </geometry>
      <origin rpy="0 0 0" xyz="0 0 0.1"/>
    </collision>
    <inertial>
      <mass value="0.32000000000000006"/>
      <inertia ixx="0.001333333333333334" ixy="0.0" ixz="0.0" iyy="0.001333333333333334" iyz="0.0" izz="0.0005333333333333336"/>
    </inertial>
  </link>
  <joint name="l3_base_to_joint_1" type="fixed">
    <parent link="body"/>
    <child link="l3_segment_1"/>
    <origin rpy="0 0 0" xyz="-0.5 0.1 .75"/>
  </joint>
  <link name="l3_segment_2_HIP">
    <visual>
      <geometry>
        <box size="0.1 0.6 0.1"/>
      </geometry>
      <material name="yellow"/>
      <origin rpy="0 0 0" xyz="0 0.25 0"/>
    </visual>
    <collision>
      <geometry>
        <box size="0.1 0.6 0.1"/>
      </geometry>
      <origin rpy="0 0 0" xyz="0 0.25 0"/>
    </collision>
    <inertial>
      <mass value="0.96"/>
      <inertia ixx="0.029599999999999994" ixy="0.0" ixz="0.0" iyy="0.0016" iyz="0.0" izz="0.029599999999999994"/>
    </inertial>
  </link>
  <joint name="l3_joint_1_to_2" type="revolute">
    <parent link="l3_segment_1"/>
    <child link="l3_segment_2_HIP"/>
    <origin rpy="0 0 0" xyz="0 0 0.25"/>
    <axis xyz="0.0 0.0 1.0"/>
    <limit effort="55" lower="-1.2" upper="1.2" velocity="29"/>
  </joint>
  <link name="l3_segment_3_THIGH">
    <visual>
      <geometry>
        <box size="0.1 0.1 0.7"/>
      </geometry>
      <material name="red"/>
      <origin rpy="0 0 0" xyz="0 0 -0.3"/>
    </visual>
    <collision>
      <geometry>
        <box size="0.1 0.1 0.7"/>
      </geometry>
      <origin rpy="0 0 0" xyz="0 0 -0.3"/>
    </collision>
    <inertial>
      <mass value="1.12"/>
      <inertia ixx="0.04666666666666666" ixy="0.0" ixz="0.0" iyy="0.04666666666666666" iyz="0.0" izz="0.001866666666666667"/>
    </inertial>
  </link>
  <joint name="l3_joint_2_to_3" type="revolute">
    <parent link="l3_segment_2_HIP"/>
    <child link="l3_segment_3_THIGH"/>
    <origin rpy="0 0 0" xyz="-0.1 0.5 0"/>
    <axis xyz="1.0 0.0 0.0"/>
    <limit effort="55" lower="-0.2" upper="0.75" velocity="29"/>
  </joint>
  <link name="l3_segment_4_FOOT">
    <visual>
      <geometry>
        <box size="0.1 0.1 0.4"/>
      </geometry>
      <material name="yellow"/>
      <origin rpy="0 0 0" xyz="0 0 -0.2"/>
    </visual>
    <collision>
      <geometry>
        <box size="0.1 0.1 0.4"/>
      </geometry>
      <origin rpy="0 0 0" xyz="0 0 -0.2"/>
    </collision>
    <inertial>
      <mass value="0.6400000000000001"/>
      <inertia ixx="0.00906666666666667" ixy="0.0" ixz="0.0" iyy="0.00906666666666667" iyz="0.0" izz="0.0010666666666666672"/>
    </inertial>
  </link>
  <joint name="l3_joint_3_to_4_FOOT" type="revolute">
    <parent link="l3_segment_3_THIGH"/>
    <child link="l3_segment_4_FOOT"/>
    <origin rpy="0 0 0" xyz="0.1 0 -0.55"/>
    <axis xyz="1.0 0.0 0.0"/>
    <limit effort="55" lower="-0.2" upper="0.5" velocity="29"/>
  </joint>
  <link name="r1_segment_1">
    <visual>
      <geometry>
        <box size="0.1 0.1 0.2"/>
      </geometry>
      <material name="white"/>
      <origin rpy="0 0 0" xyz="0 0 0.1"/>
    </visual>
    <collision>
      <geometry>
        <box size="0.1 0.1 0.2"/>
      </geometry>
      <origin rpy="0 0 0" xyz="0 0 0.1"/>
    </collision>
    <inertial>
      <mass value="0.32000000000000006"/>
      <inertia ixx="0.001333333333333334" ixy="0.0" ixz="0.0" iyy="0.001333333333333334" iyz="0.0" izz="0.0005333333333333336"/>
    </inertial>
  </link>
  <joint name="r1_base_to_joint_1" type="fixed">
    <parent link="body"/>
    <child link="r1_segment_1"/>
    <origin rpy="0 0 0" xyz="0.5 -0.1 .75"/>
  </joint>
  <link name="r1_segment_2_HIP">
    <visual>
      <geometry>
        <box size="0.1 0.6 0.1"/>
      </geometry>
      <material name="yellow"/>
      <origin rpy="0 0 0" xyz="0 -0.25 0"/>
    </visual>
    <collision>
      <geometry>
        <box size="0.1 0.6 0.1"/>
      </geometry>
      <origin rpy="0 0 0" xyz="0 -0.25 0"/>
    </collision>
    <inertial>
      <mass value="0.96"/>
      <inertia ixx="0.029599999999999994" ixy="0.0" ixz="0.0" iyy="0.0016" iyz="0.0" izz="0.029599999999999994"/>
    </inertial>
  </link>
  <joint name="r1_joint_1_to_2" type="revolute">
    <parent link="r1_segment_1"/>
    <child link="r1_segment_2_HIP"/>
    <origin rpy="0 0 0" xyz="0 0 0.25"/>
    <axis xyz="0.0 0.0 1.0"/>
    <limit effort="55" lower="-1.2" upper="1.2" velocity="29"/>
  </joint>
  <link name="r1_segment_3_THIGH">
    <visual>
      <geometry>
        <box size="0.1 0.1 0.7"/>
      </geometry>
      <material name="red"/>
      <origin rpy="0 0 0" xyz="0 0 -0.3"/>
    </visual>
    <collision>
      <geometry>
        <box size="0.1 0.1 0.7"/>
      </geometry>
      <origin rpy="0 0 0" xyz="0 0 -0.3"/>
    </collision>
    <inertial>
      <mass value="1.12"/>
      <inertia ixx="0.04666666666666666" ixy="0.0" ixz="0.0" iyy="0.04666666666666666" iyz="0.0" izz="0.001866666666666667"/>
    </inertial>
  </link>
  <joint name="r1_joint_2_to_3" type="revolute">
    <parent link="r1_segment_2_HIP"/>
    <child link="r1_segment_3_THIGH"/>
    <origin rpy="0 0 0" xyz="-0.1 -0.5 0"/>
    <axis xyz="1.0 0.0 0.0"/>
    <limit effort="55" lower="-0.75" upper="0.2" velocity="29"/>
  </joint>
  <link name="r1_segment_4_FOOT">
    <visual>
      <geometry>
        <box size="0.1 0.1 0.4"/>
      </geometry>
      <material name="yellow"/>
      <origin rpy="0 0 0" xyz="0 0 -0.2"/>
    </visual>
    <collision>
      <geometry>
        <box size="0.1 0.1 0.4"/>
      </geometry>
      <origin rpy="0 0 0" xyz="0 0 -0.2"/>
    </collision>
    <inertial>
      <mass value="0.6400000000000001"/>
      <inertia ixx="0.00906666666666667" ixy="0.0" ixz="0.0" iyy="0.00906666666666667" iyz="0.0" izz="0.0010666666666666672"/>
    </inertial>
  </link>
  <joint name="r1_joint_3_to_4_FOOT" type="revolute">
    <parent link="r1_segment_3_THIGH"/>
    <child link="r1_segment_4_FOOT"/>
    <origin rpy="0 0 0" xyz="0.1 0 -0.55"/>
    <axis xyz="1.0 0.0 0.0"/>
    <limit effort="55" lower="-0.5" upper="0.2" velocity="29"/>
  </joint>
  <link name="r2_segment_1">
    <visual>
      <geometry>
        <box size="0.1 0.1 0.2"/>
      </geometry>
      <material name="white"/>
      <origin rpy="0 0 0" xyz="0 0 0.1"/>
    </visual>
    <collision>
      <geometry>
        <box size="0.1 0.1 0.2"/>
      </geometry>
      <origin rpy="0 0 0" xyz="0 0 0.1"/>
    </collision>
    <inertial>
      <mass value="0.32000000000000006"/>
      <inertia ixx="0.001333333333333334" ixy="0.0" ixz="0.0" iyy="0.001333333333333334" iyz="0.0" izz="0.0005333333333333336"/>
    </inertial>
  </link>
  <joint name="r2_base_to_joint_1" type="fixed">
    <parent link="body"/>
    <child link="r2_segment_1"/>
    <origin rpy="0 0 0" xyz="0 -0.1 .75"/>
  </joint>
  <link name="r2_segment_2_HIP">
    <visual>
      <geometry>
        <box size="0.1 0.6 0.1"/>
      </geometry>
      <material name="yellow"/>
      <origin rpy="0 0 0" xyz="0 -0.25 0"/>
    </visual>
    <collision>
      <geometry>
        <box size="0.1 0.6 0.1"/>
      </geometry>
      <origin rpy="0 0 0" xyz="0 -0.25 0"/>
    </collision>
    <inertial>
      <mass value="0.96"/>
      <inertia ixx="0.029599999999999994" ixy="0.0" ixz="0.0" iyy="0.0016" iyz="0.0" izz="0.029599999999999994"/>
    </inertial>
  </link>
  <joint name="r2_joint_1_to_2" type="revolute">
    <parent link="r2_segment_1"/>
    <child link="r2_segment_2_HIP"/>
    <origin rpy="0 0 0" xyz="0 0 0.25"/>
    <axis xyz="0.0 0.0 1.0"/>
    <limit effort="55" lower="-1.2" upper="1.2" velocity="29"/>
  </joint>
  <link name="r2_segment_3_THIGH">
    <visual>
      <geometry>
        <box size="0.1 0.1 0.7"/>
      </geometry>
      <material name="red"/>
      <origin rpy="0 0 0" xyz="0 0 -0.3"/>
    </visual>
    <collision>
      <geometry>
        <box size="0.1 0.1 0.7"/>
      </geometry>
      <origin rpy="0 0 0" xyz="0 0 -0.3"/>
    </collision>
    <inertial>
      <mass value="1.12"/>
      <inertia ixx="0.04666666666666666" ixy="0.0" ixz="0.0" iyy="0.04666666666666666" iyz="0.0" izz="0.001866666666666667"/>
    </inertial>
  </link>
  <joint name="r2_joint_2_to_3" type="revolute">
    <parent link="r2_segment_2_HIP"/>
    <child link="r2_segment_3_THIGH"/>
    <origin rpy="0 0 0" xyz="-0.1 -0.5 0"/>
    <axis xyz="1.0 0.0 0.0"/>
    <limit effort="55" lower="-0.75" upper="0.2" velocity="29"/>
  </joint>
  <link name="r2_segment_4_FOOT">
    <visual>
      <geometry>
        <box size="0.1 0.1 0.4"/>
      </geometry>
      <material name="yellow"/>
      <origin rpy="0 0 0" xyz="0 0 -0.2"/>
    </visual>
    <collision>
      <geometry>
        <box size="0.1 0.1 0.4"/>
      </geometry>
      <origin rpy="0 0 0" xyz="0 0 -0.2"/>
    </collision>
    <inertial>
      <mass value="0.6400000000000001"/>
      <inertia ixx="0.00906666666666667" ixy="0.0" ixz="0.0" iyy="0.00906666666666667" iyz="0.0" izz="0.0010666666666666672"/>
    </inertial>
  </link>
  <joint name="r2_joint_3_to_4_FOOT" type="revolute">
    <parent link="r2_segment_3_THIGH"/>
    <child link="r2_segment_4_FOOT"/>
    <origin rpy="0 0 0" xyz="0.1 0 -0.55"/>
    <axis xyz="1.0 0.0 0.0"/>
    <limit effort="55" lower="-0.5" upper="0.2" velocity="29"/>
  </joint>
  <link name="r3_segment_1">
    <visual>
      <geometry>
        <box size="0.1 0.1 0.2"/>
      </geometry>
      <material name="white"/>
      <origin rpy="0 0 0" xyz="0 0 0.1"/>
    </visual>
    <collision>
      <geometry>
        <box size="0.1 0.1 0.2"/>
      </geometry>
      <origin rpy="0 0 0" xyz="0 0 0.1"/>
    </collision>
    <inertial>
      <mass value="0.32000000000000006"/>
      <inertia ixx="0.001333333333333334" ixy="0.0" ixz="0.0" iyy="0.001333333333333334" iyz="0.0" izz="0.0005333333333333336"/>
    </inertial>
  </link>
  <joint name="r3_base_to_joint_1" type="fixed">
    <parent link="body"/>
    <child link="r3_segment_1"/>
    <origin rpy="0 0 0" xyz="-0.5 -0.1 .75"/>
  </joint>
  <link name="r3_segment_2_HIP">
    <visual>
      <geometry>
        <box size="0.1 0.6 0.1"/>
      </geometry>
      <material name="yellow"/>
      <origin rpy="0 0 0" xyz="0 -0.25 0"/>
    </visual>
    <collision>
      <geometry>
        <box size="0.1 0.6 0.1"/>
      </geometry>
      <origin rpy="0 0 0" xyz="0 -0.25 0"/>
    </collision>
    <inertial>
      <mass value="0.96"/>
      <inertia ixx="0.029599999999999994" ixy="0.0" ixz="0.0" iyy="0.0016" iyz="0.0" izz="0.029599999999999994"/>
    </inertial>
  </link>
  <joint name="r3_joint_1_to_2" type="revolute">
    <parent link="r3_segment_1"/>
    <child link="r3_segment_2_HIP"/>
    <origin rpy="0 0 0" xyz="0 0 0.25"/>
    <axis xyz="0.0 0.0 1.0"/>
    <limit effort="55" lower="-1.2" upper="1.2" velocity="29"/>
  </joint>
  <link name="r3_segment_3_THIGH">
    <visual>
      <geometry>
        <box size="0.1 0.1 0.7"/>
      </geometry>
      <material name="red"/>
      <origin rpy="0 0 0" xyz="0 0 -0.3"/>
    </visual>
    <collision>
      <geometry>
        <box size="0.1 0.1 0.7"/>
      </geometry>
      <origin rpy="0 0 0" xyz="0 0 -0.3"/>
    </collision>
    <inertial>
      <mass value="1.12"/>
      <inertia ixx="0.04666666666666666" ixy="0.0" ixz="0.0" iyy="0.04666666666666666" iyz="0.0" izz="0.001866666666666667"/>
    </inertial>
  </link>
  <joint name="r3_joint_2_to_3" type="revolute">
    <parent link="r3_segment_2_HIP"/>
    <child link="r3_segment_3_THIGH"/>
    <origin rpy="0 0 0" xyz="-0.1 -0.5 0"/>
    <axis xyz="1.0 0.0 0.0"/>
    <limit effort="55" lower="-0.75" upper="0.2" velocity="29"/>
  </joint>
  <link name="r3_segment_4_FOOT">
    <visual>
      <geometry>
        <box size="0.1 0.1 0.4"/>
      </geometry>
      <material name="yellow"/>
      <origin rpy="0 0 0" xyz="0 0 -0.2"/>
    </visual>
    <collision>
      <geometry>
        <box size="0.1 0.1 0.4"/>
      </geometry>
      <origin rpy="0 0 0" xyz="0 0 -0.2"/>
    </collision>
    <inertial>
      <mass value="0.6400000000000001"/>
      <inertia ixx="0.00906666666666667" ixy="0.0" ixz="0.0" iyy="0.00906666666666667" iyz="0.0" izz="0.0010666666666666672"/>
    </inertial>
  </link>
  <joint name="r3_joint_3_to_4_FOOT" type="revolute">
    <parent link="r3_segment_3_THIGH"/>
    <child link="r3_segment_4_FOOT"/>
    <origin rpy="0 0 0" xyz="0.1 0 -0.55"/>
    <axis xyz="1.0 0.0 0.0"/>
    <limit effort="55" lower="-0.5" upper="0.2" velocity="29"/>
  </joint>
</robot>
