<?xml version="1.0" ?>
<!-- =================================================================================== -->
<!-- |    This document was autogenerated by xacro from /home/ruehl/catkin_ws/install/share/soto_2_1_description/urdf/soto_2_1_description.xacro | -->
<!-- |    EDITING THIS FILE BY HAND IS NOT RECOMMENDED                                 | -->
<!-- =================================================================================== -->
<robot name="soto_2_1">
  <link name="base_footprint"/>
  <link name="base_link">
    <inertial>
      <origin rpy="0 0 0" xyz="0.01 -0.01 0.02"/>
      <mass value="167.45"/>
      <inertia ixx="18.33" ixy="-6.02" ixz="1.41" iyy="88.5" iyz="-0.08" izz="104.26"/>
    </inertial>
    <visual>
      <geometry>
        <mesh filename="package://soto_drive_base_2_1_description/meshes/base_link.STL"/>
      </geometry>
      <material name="">
        <color rgba="0.52941 0.54902 0.54902 1"/>
      </material>
    </visual>
    <collision>
      <geometry>
        <mesh filename="package://soto_drive_base_2_1_description/meshes/base_link_col.STL"/>
      </geometry>
    </collision>
  </link>
  <joint name="base_footprint_to_base" type="fixed">
    <origin rpy="0 0 0" xyz="0 0 0.1665"/>
    <parent link="base_footprint"/>
    <child link="base_link"/>
  </joint>
  <link name="pcw_front_right_base_link">
    <inertial>
      <origin rpy="0 0 0" xyz="0 0.03925 -0.038"/>
      <mass value="13.5"/>
      <inertia ixx="0.07596928" ixy="0" ixz="0" iyy="0.0390105" iyz="0" izz="0.10198378"/>
    </inertial>
    <visual>
      <origin rpy="0 0 0" xyz="0 0.03925 -0.038"/>
      <geometry>
        <box size="0.17 0.2485 0.076"/>
      </geometry>
      <material name="">
        <color rgba="0.79216 0.81961 0.93333 1"/>
      </material>
    </visual>
    <collision>
      <origin rpy="0 0 0" xyz="0 0.03925 -0.038"/>
      <geometry>
        <box size="0.17 0.2485 0.076"/>
      </geometry>
    </collision>
  </link>
  <joint name="base_to_pcw_front_right" type="fixed">
    <origin rpy="0 0 0" xyz="0.92259 -0.305 0.038"/>
    <parent link="base_link"/>
    <child link="pcw_front_right_base_link"/>
  </joint>
  <link name="pcw_rear_left_base_link">
    <inertial>
      <origin rpy="0 0 0" xyz="0 0.03925 -0.038"/>
      <mass value="13.5"/>
      <inertia ixx="0.07596928" ixy="0" ixz="0" iyy="0.0390105" iyz="0" izz="0.10198378"/>
    </inertial>
    <visual>
      <origin rpy="0 0 0" xyz="0 0.03925 -0.038"/>
      <geometry>
        <box size="0.17 0.2485 0.076"/>
      </geometry>
      <material name="">
        <color rgba="0.79216 0.81961 0.93333 1"/>
      </material>
    </visual>
    <collision>
      <origin rpy="0 0 0" xyz="0 0.03925 -0.038"/>
      <geometry>
        <box size="0.17 0.2485 0.076"/>
      </geometry>
    </collision>
  </link>
  <joint name="base_to_pcw_rear_left" type="fixed">
    <origin rpy="0 0 -1.5708" xyz="-0.60082 0.301 0.038"/>
    <parent link="base_link"/>
    <child link="pcw_rear_left_base_link"/>
  </joint>
  <link name="pcw_front_right_steer_link">
    <inertial>
      <origin rpy="0 0 0" xyz="0 0.03975 -0.0545"/>
      <mass value="2"/>
      <inertia ixx="0.022267099999999998" ixy="0" ixz="0" iyy="0.0399683" iyz="0" izz="0.0219021"/>
    </inertial>
    <visual>
      <origin rpy="0 0 0" xyz="0 0.03975 -0.0545"/>
      <geometry>
        <box size="0.109 0.0355 0.11"/>
      </geometry>
      <material name="">
        <color rgba="0.79216 0.81961 0.93333 1"/>
      </material>
    </visual>
    <collision>
      <origin rpy="0 0 0" xyz="0 0.03975 -0.0545"/>
      <geometry>
        <box size="0.109 0.0355 0.11"/>
      </geometry>
    </collision>
  </link>
  <joint name="pcw_front_right_steer" type="continuous">
    <origin rpy="0 0 0" xyz="0 0 -0.0765"/>
    <parent link="pcw_front_right_base_link"/>
    <child link="pcw_front_right_steer_link"/>
    <axis xyz="0 0 1"/>
    <dynamics damping="1.0" friction="0.0"/>
  </joint>
  <link name="pcw_rear_left_steer_link">
    <inertial>
      <origin rpy="0 0 0" xyz="0 0.03975 -0.0545"/>
      <mass value="2"/>
      <inertia ixx="0.022267099999999998" ixy="0" ixz="0" iyy="0.0399683" iyz="0" izz="0.0219021"/>
    </inertial>
    <visual>
      <origin rpy="0 0 0" xyz="0 0.03975 -0.0545"/>
      <geometry>
        <box size="0.109 0.0355 0.11"/>
      </geometry>
      <material name="">
        <color rgba="0.79216 0.81961 0.93333 1"/>
      </material>
    </visual>
    <collision>
      <origin rpy="0 0 0" xyz="0 0.03975 -0.0545"/>
      <geometry>
        <box size="0.109 0.0355 0.11"/>
      </geometry>
    </collision>
  </link>
  <joint name="pcw_rear_left_steer" type="continuous">
    <origin rpy="0 0 1.5707963267948966" xyz="0 0 -0.0765"/>
    <parent link="pcw_rear_left_base_link"/>
    <child link="pcw_rear_left_steer_link"/>
    <axis xyz="0 0 1"/>
    <dynamics damping="1.0" friction="0.0"/>
  </joint>
  <link name="pcw_front_right_wheel_link">
    <inertial>
      <origin rpy="0 0 0" xyz="0 0 0"/>
      <mass value="1.5"/>
      <inertia ixx="0.0217109" ixy="0" ixz="0" iyy="0.039421899999999996" iyz="0" izz="0.0217109"/>
    </inertial>
    <visual>
      <origin rpy="1.5707963267948966 0 0" xyz="0 0 0"/>
      <geometry>
        <cylinder length="0.04" radius="0.0725"/>
      </geometry>
      <material name="">
        <color rgba="0.79216 0.81961 0.93333 1"/>
      </material>
    </visual>
    <collision>
      <origin rpy="1.5707963267948966 0 0" xyz="0 0 0"/>
      <geometry>
        <cylinder length="0.04" radius="0.0725"/>
      </geometry>
    </collision>
  </link>
  <joint name="pcw_front_right_drive" type="continuous">
    <origin rpy="0 0 0" xyz="0 0 -0.055502"/>
    <parent link="pcw_front_right_steer_link"/>
    <child link="pcw_front_right_wheel_link"/>
    <axis xyz="0 1 0"/>
    <dynamics damping="1.0" friction="0.0"/>
  </joint>
  <link name="pcw_rear_left_wheel_link">
    <inertial>
      <origin rpy="0 0 0" xyz="0 0 0"/>
      <mass value="1.5"/>
      <inertia ixx="0.0217109" ixy="0" ixz="0" iyy="0.039421899999999996" iyz="0" izz="0.0217109"/>
    </inertial>
    <visual>
      <origin rpy="1.5707963267948966 0 0" xyz="0 0 0"/>
      <geometry>
        <cylinder length="0.04" radius="0.0725"/>
      </geometry>
      <material name="">
        <color rgba="0.79216 0.81961 0.93333 1"/>
      </material>
    </visual>
    <collision>
      <origin rpy="1.5707963267948966 0 0" xyz="0 0 0"/>
      <geometry>
        <cylinder length="0.04" radius="0.0725"/>
      </geometry>
    </collision>
  </link>
  <joint name="pcw_rear_left_drive" type="continuous">
    <origin rpy="0 0 0" xyz="0 0 -0.055502"/>
    <parent link="pcw_rear_left_steer_link"/>
    <child link="pcw_rear_left_wheel_link"/>
    <axis xyz="0 1 0"/>
    <dynamics damping="1.0" friction="0.0"/>
  </joint>
  <link name="caster_front_left_base_link">
    <inertial>
      <origin rpy="0 0 0" xyz="-0.02 0 0.02"/>
      <mass value="3.1"/>
      <inertia ixx="0.01" ixy="0" ixz="0" iyy="0.01" iyz="0" izz="0.01"/>
    </inertial>
    <visual>
      <geometry>
        <mesh filename="package://soto_drive_base_2_1_description/meshes/caster_base_link.STL"/>
      </geometry>
      <material name="">
        <color rgba="1 1 1 1"/>
      </material>
    </visual>
    <collision>
      <geometry>
        <sphere radius="0.04052"/>
      </geometry>
    </collision>
  </link>
  <joint name="base_to_caster_front_left" type="fixed">
    <origin rpy="0 0 0" xyz="0.94959 0.28625 -0.1248"/>
    <parent link="base_link"/>
    <child link="caster_front_left_base_link"/>
  </joint>
  <link name="caster_rear_right_base_link">
    <inertial>
      <origin rpy="0 0 0" xyz="-0.02 0 0.02"/>
      <mass value="3.1"/>
      <inertia ixx="0.01" ixy="0" ixz="0" iyy="0.01" iyz="0" izz="0.01"/>
    </inertial>
    <visual>
      <geometry>
        <mesh filename="package://soto_drive_base_2_1_description/meshes/caster_base_link.STL"/>
      </geometry>
      <material name="">
        <color rgba="1 1 1 1"/>
      </material>
    </visual>
    <collision>
      <geometry>
        <sphere radius="0.04052"/>
      </geometry>
    </collision>
  </link>
  <joint name="base_to_caster_rear_right" type="fixed">
    <origin rpy="0 0 1.5707963267948966" xyz="-0.60075 -0.229 -0.1248"/>
    <parent link="base_link"/>
    <child link="caster_rear_right_base_link"/>
  </joint>
  <link name="laser_scanner_base_front_link">
    <inertial>
      <origin rpy="0 0 0" xyz="-0.0030205 0 -0.042173"/>
      <mass value="1.45"/>
      <inertia ixx="0.0031605" ixy="0" ixz="0" iyy="0.0030628" iyz="0" izz="0.0018952"/>
    </inertial>
    <visual>
      <geometry>
        <mesh filename="package://soto_drive_base_2_1_description/meshes/laser_scanner_link.STL"/>
      </geometry>
      <material name="">
        <color rgba="1 1 0 1"/>
      </material>
    </visual>
    <collision>
      <origin rpy="0 0 0" xyz="0 0 -0.0353"/>
      <geometry>
        <cylinder length="0.150512" radius="0.05"/>
      </geometry>
    </collision>
  </link>
  <joint name="base_to_laser_scanner_front" type="fixed">
    <origin rpy="3.1416 0 0" xyz="1.0013 0 -0.04574"/>
    <parent link="base_link"/>
    <child link="laser_scanner_base_front_link"/>
  </joint>
  <link name="laser_scanner_base_rear_right_link">
    <inertial>
      <origin rpy="0 0 0" xyz="-0.0030205 0 -0.042173"/>
      <mass value="1.45"/>
      <inertia ixx="0.0031605" ixy="0" ixz="0" iyy="0.0030628" iyz="0" izz="0.0018952"/>
    </inertial>
    <visual>
      <geometry>
        <mesh filename="package://soto_drive_base_2_1_description/meshes/laser_scanner_link.STL"/>
      </geometry>
      <material name="">
        <color rgba="1 1 0 1"/>
      </material>
    </visual>
    <collision>
      <origin rpy="0 0 0" xyz="0 0 -0.0353"/>
      <geometry>
        <cylinder length="0.150512" radius="0.05"/>
      </geometry>
    </collision>
  </link>
  <joint name="base_to_laser_scanner_rear_right" type="fixed">
    <origin rpy="3.1416 0 -2.3562" xyz="-0.86928 -0.37856 -0.045761"/>
    <parent link="base_link"/>
    <child link="laser_scanner_base_rear_right_link"/>
  </joint>
  <link name="laser_scanner_base_rear_left_link">
    <inertial>
      <origin rpy="0 0 0" xyz="-0.0030205 0 -0.042173"/>
      <mass value="1.45"/>
      <inertia ixx="0.0031605" ixy="0" ixz="0" iyy="0.0030628" iyz="0" izz="0.0018952"/>
    </inertial>
    <visual>
      <geometry>
        <mesh filename="package://soto_drive_base_2_1_description/meshes/laser_scanner_link.STL"/>
      </geometry>
      <material name="">
        <color rgba="1 1 0 1"/>
      </material>
    </visual>
    <collision>
      <origin rpy="0 0 0" xyz="0 0 -0.0353"/>
      <geometry>
        <cylinder length="0.150512" radius="0.05"/>
      </geometry>
    </collision>
  </link>
  <joint name="base_to_laser_scanner_rear_left" type="fixed">
    <origin rpy="3.1416 0 2.3562" xyz="-0.86908 0.37856 -0.045761"/>
    <parent link="base_link"/>
    <child link="laser_scanner_base_rear_left_link"/>
  </joint>
  <link name="light_curtain_receiver_front_link">
    <inertial>
      <origin rpy="0 0 0" xyz="-0.013451 0.00046065 0"/>
      <mass value="0.63959"/>
      <inertia ixx="0.03084176" ixy="0" ixz="0" iyy="0.00013446" iyz="0" izz="0.03082808"/>
    </inertial>
    <visual>
      <geometry>
        <mesh filename="package://soto_drive_base_2_1_description/meshes/light_curtain_receiver_link.STL"/>
      </geometry>
      <material name="">
        <color rgba="0.9780 0.8557 0 1"/>
      </material>
    </visual>
    <collision>
      <origin rpy="1.5708 0 0" xyz="-0.015 0 0"/>
      <geometry>
        <cylinder length="0.7625" radius="0.015"/>
      </geometry>
    </collision>
  </link>
  <joint name="base_to_light_curtain_receiver_front" type="fixed">
    <origin rpy="3.1416 -1.5708 3.1416" xyz="0.9249 0 0.24363"/>
    <parent link="base_link"/>
    <child link="light_curtain_receiver_front_link"/>
  </joint>
  <link name="imu_link">
    <inertial>
      <origin rpy="0 0 0" xyz="0 0.00119 -0.00078463"/>
      <mass value="0.022358"/>
      <inertia ixx="2.7765E-06" ixy="1.8814E-21" ixz="-3.6866E-25" iyy="2.4313E-06" iyz="9.4639E-09" izz="4.9161E-06"/>
    </inertial>
    <visual>
      <geometry>
        <mesh filename="package://soto_drive_base_2_1_description/meshes/imu_link.STL"/>
      </geometry>
      <material name="">
        <color rgba="0.1 0.1 0.1 1"/>
      </material>
    </visual>
  </link>
  <joint name="base_to_imu" type="fixed">
    <origin rpy="-1.5708 1.5708 0.0" xyz="-0.51689 -0.38158 1.8366"/>
    <parent link="base_link"/>
    <child link="imu_link"/>
  </joint>
  <joint name="base_to_manipulator_base" type="fixed">
    <origin rpy="0 0 0" xyz="0.33418 0 -0.02188"/>
    <parent link="base_link"/>
    <child link="manipulator_base_link"/>
  </joint>
  <link name="manipulator_base_link">
    <inertial>
      <origin rpy="0 0 0" xyz="0.0083951 0.00056472 0.83616"/>
      <mass value="133"/>
      <inertia ixx="233.82" ixy="1.4667" ixz="-2.4067" iyy="235.13" iyz="-1.5083" izz="48.653"/>
    </inertial>
    <visual>
      <geometry>
        <mesh filename="package://soto_vertical_axis_2_1_description/meshes/manipulator_base_link.STL"/>
      </geometry>
      <material name="">
        <color rgba="0.89804 0.91765 0.92941 1"/>
      </material>
    </visual>
    <collision>
      <geometry>
        <mesh filename="package://soto_vertical_axis_2_1_description/meshes/manipulator_base_link_col.STL"/>
      </geometry>
    </collision>
  </link>
  <link name="vertical_axis_link">
    <inertial>
      <origin rpy="0 0 0" xyz="-0.017005 -0.012942 0.048502"/>
      <mass value="36.13"/>
      <inertia ixx="1.196522" ixy="0.120705" ixz="-0.048934" iyy="1.700861" iyz="-0.036322" izz="2.566171"/>
    </inertial>
    <visual>
      <geometry>
        <mesh filename="package://soto_vertical_axis_2_1_description/meshes/vertical_axis_link.STL"/>
      </geometry>
      <material name="">
        <color rgba="0.69804 0.69804 0.69804 1"/>
      </material>
    </visual>
    <collision>
      <geometry>
        <mesh filename="package://soto_vertical_axis_2_1_description/meshes/vertical_axis_link_col.STL"/>
      </geometry>
    </collision>
  </link>
  <joint name="vertical_axis" type="prismatic">
    <origin rpy="0 0 0" xyz="0 0 -0.47283"/>
    <parent link="manipulator_base_link"/>
    <child link="vertical_axis_link"/>
    <axis xyz="0 0 1"/>
    <dynamics damping="4000.0" friction="0.0"/>
    <limit effort="1650.32" lower="0.385" upper="1.91" velocity="0.45"/>
  </joint>
  <link name="light_curtain_emitter_right_link">
    <inertial>
      <origin rpy="0 0 0" xyz="-0.013451 0 0"/>
      <mass value="0.63959"/>
      <inertia ixx="0.03084176" ixy="0" ixz="0" iyy="0.00013446" iyz="0" izz="0.03082808"/>
    </inertial>
    <visual>
      <geometry>
        <mesh filename="package://soto_vertical_axis_2_1_description/meshes/light_curtain_emitter_link.STL"/>
      </geometry>
      <material name="">
        <color rgba="0.9780 0.8557 0 1"/>
      </material>
    </visual>
    <collision>
      <origin rpy="1.5708 0 0" xyz="-0.015 0 0"/>
      <geometry>
        <cylinder length="0.7625" radius="0.015"/>
      </geometry>
    </collision>
  </link>
  <joint name="base_to_light_curtain_emitter_right" type="fixed">
    <origin rpy="1.5708 1.5708 0" xyz="0.0012921 -0.505 1.9279"/>
    <parent link="manipulator_base_link"/>
    <child link="light_curtain_emitter_right_link"/>
  </joint>
  <link name="light_curtain_emitter_left_link">
    <inertial>
      <origin rpy="0 0 0" xyz="-0.013451 0 0"/>
      <mass value="0.63959"/>
      <inertia ixx="0.03084176" ixy="0" ixz="0" iyy="0.00013446" iyz="0" izz="0.03082808"/>
    </inertial>
    <visual>
      <geometry>
        <mesh filename="package://soto_vertical_axis_2_1_description/meshes/light_curtain_emitter_link.STL"/>
      </geometry>
      <material name="">
        <color rgba="0.9780 0.8557 0 1"/>
      </material>
    </visual>
    <collision>
      <origin rpy="1.5708 0 0" xyz="-0.015 0 0"/>
      <geometry>
        <cylinder length="0.7625" radius="0.015"/>
      </geometry>
    </collision>
  </link>
  <joint name="base_to_light_curtain_emitter_left" type="fixed">
    <origin rpy="1.5708 1.5708 0" xyz="-0.0012921 0.505 1.9279"/>
    <parent link="manipulator_base_link"/>
    <child link="light_curtain_emitter_left_link"/>
  </joint>
  <link name="light_curtain_receiver_right_link">
    <inertial>
      <origin rpy="0 0 0" xyz="-0.013451 0.00046065 0"/>
      <mass value="0.63959"/>
      <inertia ixx="0.03084176" ixy="0" ixz="0" iyy="0.00013446" iyz="0" izz="0.03082808"/>
    </inertial>
    <visual>
      <geometry>
        <mesh filename="package://soto_vertical_axis_2_1_description/meshes/light_curtain_receiver_link.STL"/>
      </geometry>
      <material name="">
        <color rgba="0.9780 0.8557 0 1"/>
      </material>
    </visual>
    <collision>
      <origin rpy="1.5708 0 0" xyz="-0.015 0 0"/>
      <geometry>
        <cylinder length="0.7625" radius="0.015"/>
      </geometry>
    </collision>
  </link>
  <joint name="base_to_light_curtain_receiver_right" type="fixed">
    <origin rpy="0 -1.5708 1.5708" xyz="0.00181 -0.505 0.0954"/>
    <parent link="manipulator_base_link"/>
    <child link="light_curtain_receiver_right_link"/>
  </joint>
  <link name="light_curtain_receiver_left_link">
    <inertial>
      <origin rpy="0 0 0" xyz="-0.013451 0.00046065 0"/>
      <mass value="0.63959"/>
      <inertia ixx="0.03084176" ixy="0" ixz="0" iyy="0.00013446" iyz="0" izz="0.03082808"/>
    </inertial>
    <visual>
      <geometry>
        <mesh filename="package://soto_vertical_axis_2_1_description/meshes/light_curtain_receiver_link.STL"/>
      </geometry>
      <material name="">
        <color rgba="0.9780 0.8557 0 1"/>
      </material>
    </visual>
    <collision>
      <origin rpy="1.5708 0 0" xyz="-0.015 0 0"/>
      <geometry>
        <cylinder length="0.7625" radius="0.015"/>
      </geometry>
    </collision>
  </link>
  <joint name="base_to_light_curtain_receiver_left" type="fixed">
    <origin rpy="1.5708 -1.5708 0" xyz="-0.00081 0.505 0.0954"/>
    <parent link="manipulator_base_link"/>
    <child link="light_curtain_receiver_left_link"/>
  </joint>
  <link name="nav_depth_camera_front_link">
    <inertial>
      <origin rpy="0 0 0" xyz="-0.025274 0.00013854 -0.023398"/>
      <mass value="1.0"/>
      <inertia ixx="0.00081667" ixy="0" ixz="0" iyy="0.00094167" iyz="0" izz="0.00094167"/>
    </inertial>
    <visual>
      <geometry>
        <mesh filename="package://soto_vertical_axis_2_1_description/meshes/nav_depth_camera_front_link.STL"/>
      </geometry>
      <material name="">
        <color rgba="0 0.292 0.403 1"/>
      </material>
    </visual>
    <collision>
      <origin rpy="0 0 0" xyz="0.0125 -0.01475 -0.035"/>
      <geometry>
        <box size="0.08 0.07 0.07"/>
      </geometry>
    </collision>
  </link>
  <joint name="nav_depth_camera_front" type="fixed">
    <origin rpy="-2.3213 0.0 -1.5708" xyz="0.70999 0.0135 1.92162"/>
    <parent link="manipulator_base_link"/>
    <child link="nav_depth_camera_front_link"/>
  </joint>
  <link name="blue_spot_front_link"/>
  <joint name="blue_spot_front" type="fixed">
    <origin rpy="0 2.3213 0" xyz="0.70999 0.117 1.92162"/>
    <parent link="manipulator_base_link"/>
    <child link="blue_spot_front_link"/>
  </joint>
  <link name="gripper_base_link">
    <inertial>
      <origin rpy="0 0 0" xyz="0 -0.003906 0.071229"/>
      <mass value="22.11"/>
      <inertia ixx="1.434512" ixy="0.01329" ixz="-0.275856" iyy="1.610174" iyz="-0.0066" izz="2.705717"/>
    </inertial>
    <visual>
      <geometry>
        <mesh filename="package://soto_conveyor_gripper_1_2_description/meshes/gripper_base_link.STL"/>
      </geometry>
      <material name="">
        <color rgba="0.75294 0.75294 0.75294 1"/>
      </material>
    </visual>
    <collision>
      <geometry>
        <mesh filename="package://soto_conveyor_gripper_1_2_description/meshes/gripper_base_link_col.STL"/>
      </geometry>
    </collision>
  </link>
  <joint name="gripper_rotate" type="revolute">
    <origin rpy="0 0 3.1416" xyz="0 0 0.1205"/>
    <parent link="vertical_axis_link"/>
    <child link="gripper_base_link"/>
    <axis xyz="0 0 1"/>
    <dynamics damping="12.0" friction="0.0"/>
    <limit effort="32.11" lower="-3.22886" upper="1.65806" velocity="3.72802"/>
  </joint>
  <link name="gripper_base_x_link">
    <inertial>
      <origin rpy="0 0 0" xyz="-0.10693 -0.020943 0.010393"/>
      <mass value="8.27"/>
      <inertia ixx="0.439749" ixy="0.029672" ixz="-0.0008" iyy="0.203588" iyz="0.00403" izz="0.632283"/>
    </inertial>
    <visual>
      <geometry>
        <mesh filename="package://soto_conveyor_gripper_1_2_description/meshes/gripper_base_x_link.STL"/>
      </geometry>
      <material name="">
        <color rgba="0.69804 0.69804 0.69804 1"/>
      </material>
    </visual>
    <collision>
      <geometry>
        <mesh filename="package://soto_conveyor_gripper_1_2_description/meshes/gripper_base_x_link_col.STL"/>
      </geometry>
    </collision>
  </link>
  <joint name="gripper_base_x" type="prismatic">
    <origin rpy="0 0 0" xyz="0 0 0.08655"/>
    <parent link="gripper_base_link"/>
    <child link="gripper_base_x_link"/>
    <axis xyz="1 0 0"/>
    <dynamics damping="200.0" friction="10.0"/>
    <limit effort="140.16" lower="0.002" upper="0.328" velocity="0.145711"/>
  </joint>
  <link name="gripper_y_right_link">
    <inertial>
      <origin rpy="0 0 0" xyz="0.31885 0.0033569 -0.031557"/>
      <mass value="4.7"/>
      <inertia ixx="0.017352" ixy="-0.011281" ixz="-0.039727" iyy="0.535979" iyz="0.000597" izz="0.530221"/>
    </inertial>
    <visual>
      <geometry>
        <mesh filename="package://soto_conveyor_gripper_1_2_description/meshes/gripper_y_right_link_with_belt.STL"/>
      </geometry>
      <material name="">
        <color rgba="0.75294 0.75294 0.75294 1"/>
      </material>
    </visual>
    <collision>
      <geometry>
        <mesh filename="package://soto_conveyor_gripper_1_2_description/meshes/gripper_y_right_link_with_belt_col.STL"/>
      </geometry>
    </collision>
  </link>
  <joint name="gripper_y_right" type="prismatic">
    <origin rpy="0 0 0" xyz="-0.337 -0.325 0.12155"/>
    <parent link="gripper_base_x_link"/>
    <child link="gripper_y_right_link"/>
    <axis xyz="0 1 0"/>
    <dynamics damping="300.0" friction="80.0"/>
    <limit effort="140.16" lower="0.002" upper="0.489" velocity="0.261799"/>
  </joint>
  <link name="distance_sensor_conveyor_right">
    <inertial>
      <origin rpy="0 0 0" xyz="-0.026935 0 -0.00089453"/>
      <mass value="0.035209"/>
      <inertia ixx="7.5071E-06" ixy="-4.8531E-10" ixz="-1.4593E-07" iyy="1.0074E-05" iyz="6.5654E-10" izz="5.2155E-06"/>
    </inertial>
    <visual>
      <geometry>
        <mesh filename="package://soto_conveyor_gripper_1_2_description/meshes/distance_sensor.STL"/>
      </geometry>
      <material name="">
        <color rgba="1 1 1 1"/>
      </material>
    </visual>
    <collision>
      <origin rpy="0 0 0" xyz="-0.029073 0 0"/>
      <geometry>
        <box size="0.0308 0.0225 0.049"/>
      </geometry>
    </collision>
  </link>
  <joint name="gripper_y_right_to_distance_sensor" type="fixed">
    <origin rpy="1.5708 0 0" xyz="0.00723 0 0.0425"/>
    <parent link="gripper_y_right_link"/>
    <child link="distance_sensor_conveyor_right"/>
  </joint>
  <link name="gripper_y_left_link">
    <inertial>
      <origin rpy="0 0 0" xyz="0.31885 -0.0033569 -0.031557"/>
      <mass value="4.7"/>
      <inertia ixx="0.017352" ixy="0.011281" ixz="-0.039727" iyy="0.535979" iyz="-0.000597" izz="0.530221"/>
    </inertial>
    <visual>
      <geometry>
        <mesh filename="package://soto_conveyor_gripper_1_2_description/meshes/gripper_y_left_link_with_belt.STL"/>
      </geometry>
      <material name="">
        <color rgba="0.75294 0.75294 0.75294 1"/>
      </material>
    </visual>
    <collision>
      <geometry>
        <mesh filename="package://soto_conveyor_gripper_1_2_description/meshes/gripper_y_left_link_with_belt_col.STL"/>
      </geometry>
    </collision>
  </link>
  <joint name="gripper_y_left" type="prismatic">
    <origin rpy="0 0 0" xyz="-0.337 0.325 0.12155"/>
    <parent link="gripper_base_x_link"/>
    <child link="gripper_y_left_link"/>
    <axis xyz="0 -1 0"/>
    <dynamics damping="300.0" friction="80.0"/>
    <limit effort="140.16" lower="0.002" upper="0.489" velocity="0.261799"/>
  </joint>
  <link name="distance_sensor_conveyor_left">
    <inertial>
      <origin rpy="0 0 0" xyz="-0.026935 0 -0.00089453"/>
      <mass value="0.035209"/>
      <inertia ixx="7.5071E-06" ixy="-4.8531E-10" ixz="-1.4593E-07" iyy="1.0074E-05" iyz="6.5654E-10" izz="5.2155E-06"/>
    </inertial>
    <visual>
      <geometry>
        <mesh filename="package://soto_conveyor_gripper_1_2_description/meshes/distance_sensor.STL"/>
      </geometry>
      <material name="">
        <color rgba="1 1 1 1"/>
      </material>
    </visual>
    <collision>
      <origin rpy="0 0 0" xyz="-0.029073 0 0"/>
      <geometry>
        <box size="0.0308 0.0225 0.049"/>
      </geometry>
    </collision>
  </link>
  <joint name="gripper_y_left_to_distance_sensor" type="fixed">
    <origin rpy="-1.5708 0 0" xyz="0.00723 0 0.0425"/>
    <parent link="gripper_y_left_link"/>
    <child link="distance_sensor_conveyor_left"/>
  </joint>
  <link name="conveyor_belt_right_link">
    <!-- Assumes a (size, size, size) cube link -->
    <inertial>
      <origin xyz="0 0 0"/>
      <mass value="0.5"/>
      <inertia ixx="0.0008333333333333335" ixy="0" ixz="0" iyy="0.0008333333333333335" iyz="0" izz="0.0008333333333333335"/>
    </inertial>
  </link>
  <joint name="conveyor_belt_right" type="prismatic">
    <origin rpy="0 0 0" xyz="0.68001 0 -0.0182"/>
    <parent link="gripper_y_right_link"/>
    <child link="conveyor_belt_right_link"/>
    <axis xyz="-1 0 0"/>
    <limit effort="55.4465" lower="-9999999999" upper="9999999999" velocity="0.247126"/>
  </joint>
  <link name="conveyor_belt_right_surface_foremost_link">
    <!-- Assumes a (size, size, size) cube link -->
    <inertial>
      <origin xyz="0 0 0"/>
      <mass value="0.01"/>
      <inertia ixx="1.666666666666667e-05" ixy="0" ixz="0" iyy="1.666666666666667e-05" iyz="0" izz="1.666666666666667e-05"/>
    </inertial>
  </link>
  <joint name="conveyor_belt_right_to_surface_foremost" type="fixed">
    <origin rpy="0 0 0" xyz="0.7050115 0 0"/>
    <parent link="gripper_y_right_link"/>
    <child link="conveyor_belt_right_surface_foremost_link"/>
  </joint>
  <link name="conveyor_belt_right_foremost_link"/>
  <joint name="conveyor_belt_right_surface_to_foremost" type="fixed">
    <origin rpy="0 0 0" xyz="0.0182 0 0"/>
    <parent link="conveyor_belt_right_surface_foremost_link"/>
    <child link="conveyor_belt_right_foremost_link"/>
  </joint>
  <link name="conveyor_belt_left_link">
    <!-- Assumes a (size, size, size) cube link -->
    <inertial>
      <origin xyz="0 0 0"/>
      <mass value="0.5"/>
      <inertia ixx="0.0008333333333333335" ixy="0" ixz="0" iyy="0.0008333333333333335" iyz="0" izz="0.0008333333333333335"/>
    </inertial>
  </link>
  <joint name="conveyor_belt_left" type="prismatic">
    <origin rpy="0 0 0" xyz="0.68001 0 -0.0182"/>
    <parent link="gripper_y_left_link"/>
    <child link="conveyor_belt_left_link"/>
    <axis xyz="-1 0 0"/>
    <limit effort="55.4465" lower="-9999999999" upper="9999999999" velocity="0.247126"/>
  </joint>
  <link name="conveyor_belt_left_surface_foremost_link">
    <!-- Assumes a (size, size, size) cube link -->
    <inertial>
      <origin xyz="0 0 0"/>
      <mass value="0.01"/>
      <inertia ixx="1.666666666666667e-05" ixy="0" ixz="0" iyy="1.666666666666667e-05" iyz="0" izz="1.666666666666667e-05"/>
    </inertial>
  </link>
  <joint name="conveyor_belt_left_to_surface_foremost" type="fixed">
    <origin rpy="0 0 0" xyz="0.7050115 0 0"/>
    <parent link="gripper_y_left_link"/>
    <child link="conveyor_belt_left_surface_foremost_link"/>
  </joint>
  <link name="conveyor_belt_left_foremost_link"/>
  <joint name="conveyor_belt_left_surface_to_foremost" type="fixed">
    <origin rpy="0 0 0" xyz="0.0182 0 0"/>
    <parent link="conveyor_belt_left_surface_foremost_link"/>
    <child link="conveyor_belt_left_foremost_link"/>
  </joint>
  <link name="gripper_depth_camera_link">
    <inertial>
      <origin rpy="0 0 0" xyz="-0.025274 0.00013854 -0.023398"/>
      <mass value="0.69"/>
      <inertia ixx="0.000887" ixy="0" ixz="0.000438" iyy="0.00153" iyz="0" izz="0.001364"/>
    </inertial>
    <visual>
      <geometry>
        <mesh filename="package://soto_conveyor_gripper_1_2_description/meshes/gripper_depth_camera_link.STL"/>
      </geometry>
      <material name="">
        <color rgba="1 1 1 1"/>
      </material>
    </visual>
  </link>
  <joint name="gripper_depth_camera" type="fixed">
    <origin rpy="0.0 0.0 0.0" xyz="-0.40375 -0.02367 0.2359"/>
    <parent link="gripper_base_link"/>
    <child link="gripper_depth_camera_link"/>
  </joint>
  <link name="gripper_barcode_camera">
    <inertial>
      <origin rpy="0 0 0" xyz="-0.399914 0 0.166337"/>
      <mass value="0.3"/>
      <inertia ixx="0.008384" ixy="0" ixz="-0.01991" iyy="0.056698" iyz="0" izz="0.048367"/>
    </inertial>
    <visual>
      <geometry>
        <mesh filename="package://soto_conveyor_gripper_1_2_description/meshes/gripper_barcode_camera.STL"/>
      </geometry>
      <material name="">
        <color rgba="1 1 1 1"/>
      </material>
    </visual>
  </link>
  <joint name="gripper_barcode_camera" type="fixed">
    <origin rpy="-1.309 0.0 -1.5708" xyz="-0.4078 0.0 0.16419"/>
    <parent link="gripper_base_link"/>
    <child link="gripper_barcode_camera"/>
  </joint>
  <link name="reflective_sensor_gripper">
    <inertial>
      <origin rpy="0 0 0" xyz="-0.010172 6.0056E-07 0.00078646"/>
      <mass value="0.02"/>
      <inertia ixx="1.0016E-06" ixy="-7.2534E-12" ixz="1.4276E-09" iyy="1.1697E-06" iyz="1.4704E-10" izz="4.3881E-07"/>
    </inertial>
    <visual>
      <geometry>
        <mesh filename="package://soto_conveyor_gripper_1_2_description/meshes/reflective_sensor.STL"/>
      </geometry>
      <material name="">
        <color rgba="1 1 1 1"/>
      </material>
    </visual>
    <collision>
      <origin rpy="0 0 0" xyz="-0.01 0 0.0015"/>
      <geometry>
        <box size="0.02 0.0136 0.032"/>
      </geometry>
    </collision>
  </link>
  <joint name="gripper_base_to_reflective_sensor" type="fixed">
    <origin rpy="1.5708 0 -0.058124" xyz="-0.44819 0.096981 0.16975"/>
    <parent link="gripper_base_link"/>
    <child link="reflective_sensor_gripper"/>
  </joint>
  <link name="distance_sensor_gripper">
    <inertial>
      <origin rpy="0 0 0" xyz="-0.026935 0 -0.00089453"/>
      <mass value="0.035209"/>
      <inertia ixx="7.5071E-06" ixy="-4.8531E-10" ixz="-1.4593E-07" iyy="1.0074E-05" iyz="6.5654E-10" izz="5.2155E-06"/>
    </inertial>
    <visual>
      <geometry>
        <mesh filename="package://soto_conveyor_gripper_1_2_description/meshes/distance_sensor.STL"/>
      </geometry>
      <material name="">
        <color rgba="1 1 1 1"/>
      </material>
    </visual>
    <collision>
      <origin rpy="0 0 0" xyz="-0.029073 0 0"/>
      <geometry>
        <box size="0.0308 0.0225 0.049"/>
      </geometry>
    </collision>
  </link>
  <joint name="gripper_base_to_distance_sensor" type="fixed">
    <origin rpy="1.5708 0 -0.058124" xyz="-0.42364 0.093946 0.1908"/>
    <parent link="gripper_base_link"/>
    <child link="distance_sensor_gripper"/>
  </joint>
  <link name="gripper_surface_tip_link"/>
  <joint name="gripper_base_x_to_surface_tip" type="fixed">
    <origin rpy="0 0 0" xyz="0.3862115 0 0.12155"/>
    <parent link="gripper_base_x_link"/>
    <child link="gripper_surface_tip_link"/>
  </joint>
  <link name="barcode_search_frame"/>
  <joint name="barcode_search_joint" type="fixed">
    <origin rpy="0 0 0" xyz="0.1 0 0.1"/>
    <parent link="gripper_surface_tip_link"/>
    <child link="barcode_search_frame"/>
  </joint>
  <joint name="manipulator_base_to_press_base" type="fixed">
    <origin rpy="0 0 0" xyz="0 0 1.92058"/>
    <parent link="manipulator_base_link"/>
    <child link="press_base_link"/>
  </joint>
  <link name="press_base_link">
    <inertial>
      <origin rpy="0 0 0" xyz="0.040186 -0.023445 0.040704"/>
      <mass value="21.5"/>
      <inertia ixx="2.637865" ixy="-0.29078" ixz="0.028211" iyy="3.376731" iyz="0.021101" izz="5.886895"/>
    </inertial>
    <visual>
      <geometry>
        <mesh filename="package://soto_klt_press_1_1_description/meshes/press_base_link.STL"/>
      </geometry>
      <material name="">
        <color rgba="1 1 1 1"/>
      </material>
    </visual>
    <collision>
      <geometry>
        <mesh filename="package://soto_klt_press_1_1_description/meshes/press_base_link_col.STL"/>
      </geometry>
    </collision>
  </link>
  <link name="press_jaw_link">
    <inertial>
      <origin rpy="0 0 0" xyz="0 -0.017586 0.057801"/>
      <mass value="1.77"/>
      <inertia ixx="0.009458" ixy="0" ixz="0" iyy="0.118996" iyz="-0.00189" izz="0.111931"/>
    </inertial>
    <visual>
      <geometry>
        <mesh filename="package://soto_klt_press_1_1_description/meshes/press_jaw_link.STL"/>
      </geometry>
      <material name="">
        <color rgba="1 1 1 1"/>
      </material>
    </visual>
    <collision>
      <geometry>
        <mesh filename="package://soto_klt_press_1_1_description/meshes/press_jaw_link_col.STL"/>
      </geometry>
    </collision>
  </link>
  <joint name="press_jaw" type="prismatic">
    <origin rpy="0 0 1.5708" xyz="0.32832 0 -0.085582"/>
    <parent link="press_base_link"/>
    <child link="press_jaw_link"/>
    <axis xyz="0 1 0"/>
    <dynamics damping="20.0" friction="0.0"/>
    <limit effort="348.099" lower="0.001" upper="0.229" velocity="0.154604"/>
  </joint>
  <link name="press_jaw_front_link">
    <inertial>
      <origin rpy="0 0 0" xyz="0 -0.017586 0.057801"/>
      <mass value="1.77"/>
      <inertia ixx="0.009458" ixy="0" ixz="0" iyy="0.118996" iyz="-0.00189" izz="0.111931"/>
    </inertial>
  </link>
  <joint name="press_jaw_front" type="prismatic">
    <origin rpy="0 0 1.5708" xyz="0.32832 0 -0.085582"/>
    <parent link="press_base_link"/>
    <child link="press_jaw_front_link"/>
    <axis xyz="0 1 0"/>
    <limit effort="348.099" lower="0.001" upper="0.229" velocity="0.154604"/>
    <mimic joint="press_jaw" multiplier="1" offset="0"/>
  </joint>
  <link name="press_jaw_rear_link">
    <inertial>
      <origin rpy="0 0 0" xyz="0 -0.017586 0.057801"/>
      <mass value="1.77"/>
      <inertia ixx="0.009458" ixy="0" ixz="0" iyy="0.118996" iyz="-0.00189" izz="0.111931"/>
    </inertial>
    <visual>
      <geometry>
        <mesh filename="package://soto_klt_press_1_1_description/meshes/press_jaw_link.STL"/>
      </geometry>
      <material name="">
        <color rgba="0.25098 0.25098 0.25098 1"/>
      </material>
    </visual>
    <collision>
      <geometry>
        <mesh filename="package://soto_klt_press_1_1_description/meshes/press_jaw_link_col.STL"/>
      </geometry>
    </collision>
  </link>
  <joint name="press_jaw_rear" type="prismatic">
    <origin rpy="0 0 -1.5708" xyz="-0.32832 0 -0.085582"/>
    <parent link="press_base_link"/>
    <child link="press_jaw_rear_link"/>
    <axis xyz="0 1 0"/>
    <limit effort="348.099" lower="0.001" upper="0.229" velocity="0.154604"/>
    <mimic joint="press_jaw" multiplier="1" offset="0"/>
  </joint>
  <link name="press_depth_camera_link">
    <inertial>
      <origin rpy="0 0 0" xyz="-0.025274 0.00013854 -0.023398"/>
      <mass value="0.69"/>
      <inertia ixx="0.000887" ixy="0" ixz="0.000438" iyy="0.00153" iyz="0" izz="0.001364"/>
    </inertial>
    <visual>
      <geometry>
        <mesh filename="package://soto_klt_press_1_1_description/meshes/press_depth_camera_link.STL"/>
      </geometry>
      <material name="">
        <color rgba="1 1 1 1"/>
      </material>
    </visual>
  </link>
  <joint name="press_depth_camera" type="fixed">
    <origin rpy="0.0 1.5708 0.0" xyz="0.00014582 -0.018369 0.00575"/>
    <parent link="press_base_link"/>
    <child link="press_depth_camera_link"/>
  </joint>
  <link name="light_curtain_emitter_front_link">
    <inertial>
      <origin rpy="0 0 0" xyz="-0.013451 -5.8672E-05 1.2777E-05"/>
      <mass value="0.63959"/>
      <inertia ixx="0.031871" ixy="-7.2138E-06" ixz="9.5339E-08" iyy="8.6079E-05" iyz="-2.9432E-06" izz="0.03186"/>
    </inertial>
    <visual>
      <geometry>
        <mesh filename="package://soto_klt_press_1_1_description/meshes/light_curtain_emitter_front_link.STL"/>
      </geometry>
      <material name="">
        <color rgba="0.9780 0.8557 0 1"/>
      </material>
    </visual>
    <collision>
      <origin rpy="1.5708 0 0" xyz="-0.015 0 0"/>
      <geometry>
        <cylinder length="0.7625" radius="0.015"/>
      </geometry>
    </collision>
  </link>
  <joint name="base_to_light_curtain_emitter_front" type="fixed">
    <origin rpy="0 1.5708 0" xyz="0.5907 -0.00019206 -0.033932"/>
    <parent link="press_base_link"/>
    <child link="light_curtain_emitter_front_link"/>
  </joint>
  <link name="reflective_sensor_klt_press">
    <inertial>
      <origin rpy="0 0 0" xyz="-0.010172 6.2215E-07 0.00078641"/>
      <mass value="0.009132"/>
      <inertia ixx="1.0016E-06" ixy="0" ixz="0" iyy="1.1697E-06" iyz="0" izz="4.3882E-07"/>
    </inertial>
    <visual>
      <geometry>
        <mesh filename="package://soto_klt_press_1_1_description/meshes/reflective_sensor.STL"/>
      </geometry>
      <material name="">
        <color rgba="1 1 1 1"/>
      </material>
    </visual>
    <collision>
      <origin rpy="0 0 0" xyz="-0.01 0 0.0015"/>
      <geometry>
        <box size="0.02 0.0136 0.032"/>
      </geometry>
    </collision>
  </link>
  <joint name="press_base_to_reflective_sensor" type="fixed">
    <origin rpy="0 0 0.63705" xyz="-0.57294 -0.29461 -0.098022"/>
    <parent link="press_base_link"/>
    <child link="reflective_sensor_klt_press"/>
  </joint>
  <link name="reflective_tape_klt_press">
    <!-- Assumes a (size, size, size) cube link -->
    <inertial>
      <origin xyz="0 0 0"/>
      <mass value="0.005"/>
      <inertia ixx="8.333333333333335e-06" ixy="0" ixz="0" iyy="8.333333333333335e-06" iyz="0" izz="8.333333333333335e-06"/>
    </inertial>
    <visual>
      <geometry>
        <box size="0.001 0.03 0.03"/>
      </geometry>
      <material name="">
        <color rgba="1 1 1 1"/>
      </material>
    </visual>
    <collision>
      <geometry>
        <box size="0.001 0.03 0.03"/>
      </geometry>
    </collision>
  </link>
  <joint name="press_base_to_reflective_tape" type="fixed">
    <origin rpy="0 0 0" xyz="0.3845 0.43 -0.098"/>
    <parent link="press_base_link"/>
    <child link="reflective_tape_klt_press"/>
  </joint>
  <link name="press_upper_limit_link"/>
  <joint name="press_base_to_upper_limit" type="fixed">
    <origin rpy="0 0 0" xyz="0 0 -0.005"/>
    <parent link="press_base_link"/>
    <child link="press_upper_limit_link"/>
  </joint>
  <joint name="base_to_backpack_base" type="fixed">
    <origin rpy="0 0 0" xyz="-0.26582 0.045 0.1535"/>
    <parent link="base_link"/>
    <child link="backpack_base_link"/>
  </joint>
  <link name="backpack_base_link">
    <inertial>
      <origin rpy="0 0 0" xyz="-0.335579 -0.131711 0.841435"/>
      <mass value="119.3"/>
      <inertia ixx="151.492794" ixy="4.538259" ixz="-34.246278" iyy="153.595002" iyz="-15.803417" izz="39.692906"/>
    </inertial>
    <visual>
      <geometry>
        <mesh filename="package://soto_backpack_5_1_description/meshes/backpack_base_link.STL"/>
      </geometry>
      <material name="">
        <color rgba="0.69804 0.69804 0.69804 1"/>
      </material>
    </visual>
    <collision>
      <geometry>
        <mesh filename="package://soto_backpack_5_1_description/meshes/backpack_base_link_col.STL"/>
      </geometry>
    </collision>
  </link>
  <link name="backpack_tilt_link">
    <!-- Assumes a (size, size, size) cube link -->
    <inertial>
      <origin xyz="0 0 0"/>
      <mass value="1"/>
      <inertia ixx="0.001666666666666667" ixy="0" ixz="0" iyy="0.001666666666666667" iyz="0" izz="0.001666666666666667"/>
    </inertial>
  </link>
  <joint name="backpack_tilt" type="revolute">
    <origin rpy="0 0 0" xyz="-0.45075 0.0005 0.0685"/>
    <parent link="backpack_base_link"/>
    <child link="backpack_tilt_link"/>
    <axis xyz="0 1 0"/>
    <limit effort="2468.18" lower="-0.115" upper="0.115" velocity="0.0353135"/>
  </joint>
  <!-- ====== START OF LAYERS ====== -->
  <joint name="backpack_base_to_layer_1" type="revolute">
    <origin rpy="0 0 0" xyz="-0.068 0 0.268"/>
    <parent link="backpack_base_link"/>
    <child link="backpack_layer_1_base_link"/>
    <axis xyz="0 1 0"/>
    <limit effort="2468.18" lower="-0.115" upper="0.115" velocity="0.0353135"/>
    <mimic joint="backpack_tilt" multiplier="1" offset="0"/>
  </joint>
  <link name="backpack_layer_1_base_link">
    <inertial>
      <origin rpy="0 0 0" xyz="0 0.040533 0"/>
      <mass value="12.78"/>
      <inertia ixx="0.775256" ixy="0" ixz="0" iyy="1.530399" iyz="0" izz="0.847638"/>
    </inertial>
    <visual>
      <geometry>
        <mesh filename="package://soto_backpack_layer_1_0_description/meshes/300/backpack_layer_base_link.STL"/>
      </geometry>
      <material name="">
        <color rgba="0.75294 0.75294 0.75294 1"/>
      </material>
    </visual>
    <collision>
      <geometry>
        <mesh filename="package://soto_backpack_layer_1_0_description/meshes/300/backpack_layer_base_link_col.STL"/>
      </geometry>
    </collision>
  </link>
  <link name="backpack_layer_1_link"/>
  <joint name="backpack_layer_1_base_to_layer" type="fixed">
    <origin rpy="0 0 -1.5708" xyz="0.0466 0 -0.15456"/>
    <parent link="backpack_layer_1_base_link"/>
    <child link="backpack_layer_1_link"/>
  </joint>
  <link name="backpack_layer_1_compartment_1_link"/>
  <joint name="backpack_layer_1_to_compartment_1" type="fixed">
    <origin rpy="0 0 0" xyz="-0.174 0 0"/>
    <parent link="backpack_layer_1_link"/>
    <child link="backpack_layer_1_compartment_1_link"/>
  </joint>
  <link name="backpack_layer_1_compartment_1_reference_1_link"/>
  <joint name="backpack_layer_1_compartment_1_to_reference_1" type="fixed">
    <origin rpy="0 0 0" xyz="-0.000749999999994533 0.10885 0.00142948789310615"/>
    <parent link="backpack_layer_1_compartment_1_link"/>
    <child link="backpack_layer_1_compartment_1_reference_1_link"/>
  </joint>
  <link name="backpack_layer_1_compartment_2_link"/>
  <joint name="backpack_layer_1_to_compartment_2" type="fixed">
    <origin rpy="0 0 0" xyz="0.174000000000006 0 0"/>
    <parent link="backpack_layer_1_link"/>
    <child link="backpack_layer_1_compartment_2_link"/>
  </joint>
  <link name="backpack_layer_1_compartment_2_reference_1_link"/>
  <joint name="backpack_layer_1_compartment_2_to_reference_1" type="fixed">
    <origin rpy="0 0 0" xyz="0.000749999999994394 0.10885 0.00142948789310616"/>
    <parent link="backpack_layer_1_compartment_2_link"/>
    <child link="backpack_layer_1_compartment_2_reference_1_link"/>
  </joint>
  <joint name="backpack_base_to_layer_2" type="revolute">
    <origin rpy="0 0 0" xyz="-0.068 0 0.668"/>
    <parent link="backpack_base_link"/>
    <child link="backpack_layer_2_base_link"/>
    <axis xyz="0 1 0"/>
    <limit effort="2468.18" lower="-0.115" upper="0.115" velocity="0.0353135"/>
    <mimic joint="backpack_tilt" multiplier="1" offset="0"/>
  </joint>
  <link name="backpack_layer_2_base_link">
    <inertial>
      <origin rpy="0 0 0" xyz="-0.23836 0 -0.14858"/>
      <mass value="10.12"/>
      <inertia ixx="0.791011" ixy="0" ixz="0" iyy="1.291287" iyz="0" izz="1.586023"/>
    </inertial>
    <visual>
      <geometry>
        <mesh filename="package://soto_backpack_layer_1_0_description/meshes/400/backpack_layer_base_link.STL"/>
      </geometry>
      <material name="">
        <color rgba="0.75294 0.75294 0.75294 1"/>
      </material>
    </visual>
    <collision>
      <geometry>
        <mesh filename="package://soto_backpack_layer_1_0_description/meshes/400/backpack_layer_base_link_col.STL"/>
      </geometry>
    </collision>
  </link>
  <link name="backpack_layer_2_link"/>
  <joint name="backpack_layer_2_base_to_layer" type="fixed">
    <origin rpy="0 0 -1.5708" xyz="0.0466 0 -0.15456"/>
    <parent link="backpack_layer_2_base_link"/>
    <child link="backpack_layer_2_link"/>
  </joint>
  <link name="backpack_layer_2_compartment_1_link"/>
  <joint name="backpack_layer_2_to_compartment_1" type="fixed">
    <origin rpy="0 0 0" xyz="0 0 0"/>
    <parent link="backpack_layer_2_link"/>
    <child link="backpack_layer_2_compartment_1_link"/>
  </joint>
  <link name="backpack_layer_2_compartment_1_reference_1_link"/>
  <joint name="backpack_layer_2_compartment_1_to_reference_1" type="fixed">
    <origin rpy="0 0 0" xyz="-0.0515 0.10885 0.0014295"/>
    <parent link="backpack_layer_2_compartment_1_link"/>
    <child link="backpack_layer_2_compartment_1_reference_1_link"/>
  </joint>
  <link name="backpack_layer_2_compartment_1_reference_2_link"/>
  <joint name="backpack_layer_2_compartment_1_to_reference_2" type="fixed">
    <origin rpy="0 0 0" xyz="0.0515 0.10885 0.0014295"/>
    <parent link="backpack_layer_2_compartment_1_link"/>
    <child link="backpack_layer_2_compartment_1_reference_2_link"/>
  </joint>
  <joint name="backpack_base_to_layer_3" type="revolute">
    <origin rpy="0 0 0" xyz="-0.068 0 1.0679999999999998"/>
    <parent link="backpack_base_link"/>
    <child link="backpack_layer_3_base_link"/>
    <axis xyz="0 1 0"/>
    <limit effort="2468.18" lower="-0.115" upper="0.115" velocity="0.0353135"/>
    <mimic joint="backpack_tilt" multiplier="1" offset="0"/>
  </joint>
  <link name="backpack_layer_3_base_link">
    <inertial>
      <origin rpy="0 0 0" xyz="-0.23175 0 -0.14936"/>
      <mass value="10.03"/>
      <inertia ixx="0.940346" ixy="0" ixz="0" iyy="1.283496" iyz="0" izz="1.732422"/>
    </inertial>
    <visual>
      <geometry>
        <mesh filename="package://soto_backpack_layer_1_0_description/meshes/600/backpack_layer_base_link.STL"/>
      </geometry>
      <material name="">
        <color rgba="0.75294 0.75294 0.75294 1"/>
      </material>
    </visual>
    <collision>
      <geometry>
        <mesh filename="package://soto_backpack_layer_1_0_description/meshes/600/backpack_layer_base_link_col.STL"/>
      </geometry>
    </collision>
  </link>
  <link name="backpack_layer_3_link"/>
  <joint name="backpack_layer_3_base_to_layer" type="fixed">
    <origin rpy="0 0 -1.5708" xyz="0.0466 0 -0.15456"/>
    <parent link="backpack_layer_3_base_link"/>
    <child link="backpack_layer_3_link"/>
  </joint>
  <link name="backpack_layer_3_compartment_1_link"/>
  <joint name="backpack_layer_3_to_compartment_1" type="fixed">
    <origin rpy="0 0 0" xyz="0 0 0"/>
    <parent link="backpack_layer_3_link"/>
    <child link="backpack_layer_3_compartment_1_link"/>
  </joint>
  <link name="backpack_layer_3_compartment_1_reference_1_link"/>
  <joint name="backpack_layer_3_compartment_1_to_reference_1" type="fixed">
    <origin rpy="0 0 0" xyz="-0.07225 0.10885 0.0014295"/>
    <parent link="backpack_layer_3_compartment_1_link"/>
    <child link="backpack_layer_3_compartment_1_reference_1_link"/>
  </joint>
  <link name="backpack_layer_3_compartment_1_reference_2_link"/>
  <joint name="backpack_layer_3_compartment_1_to_reference_2" type="fixed">
    <origin rpy="0 0 0" xyz="0.07225 0.10885 0.0014295"/>
    <parent link="backpack_layer_3_compartment_1_link"/>
    <child link="backpack_layer_3_compartment_1_reference_2_link"/>
  </joint>
  <joint name="backpack_base_to_layer_4" type="revolute">
    <origin rpy="0 0 0" xyz="-0.068 0 1.468"/>
    <parent link="backpack_base_link"/>
    <child link="backpack_layer_4_base_link"/>
    <axis xyz="0 1 0"/>
    <limit effort="2468.18" lower="-0.115" upper="0.115" velocity="0.0353135"/>
    <mimic joint="backpack_tilt" multiplier="1" offset="0"/>
  </joint>
  <link name="backpack_layer_4_base_link">
    <inertial>
      <origin rpy="0 0 0" xyz="-0.23175 0 -0.14936"/>
      <mass value="10.03"/>
      <inertia ixx="0.940346" ixy="0" ixz="0" iyy="1.283496" iyz="0" izz="1.732422"/>
    </inertial>
    <visual>
      <geometry>
        <mesh filename="package://soto_backpack_layer_1_0_description/meshes/600/backpack_layer_base_link.STL"/>
      </geometry>
      <material name="">
        <color rgba="0.75294 0.75294 0.75294 1"/>
      </material>
    </visual>
    <collision>
      <geometry>
        <mesh filename="package://soto_backpack_layer_1_0_description/meshes/600/backpack_layer_base_link_col.STL"/>
      </geometry>
    </collision>
  </link>
  <link name="backpack_layer_4_link"/>
  <joint name="backpack_layer_4_base_to_layer" type="fixed">
    <origin rpy="0 0 -1.5708" xyz="0.0466 0 -0.15456"/>
    <parent link="backpack_layer_4_base_link"/>
    <child link="backpack_layer_4_link"/>
  </joint>
  <link name="backpack_layer_4_compartment_1_link"/>
  <joint name="backpack_layer_4_to_compartment_1" type="fixed">
    <origin rpy="0 0 0" xyz="0 0 0"/>
    <parent link="backpack_layer_4_link"/>
    <child link="backpack_layer_4_compartment_1_link"/>
  </joint>
  <link name="backpack_layer_4_compartment_1_reference_1_link"/>
  <joint name="backpack_layer_4_compartment_1_to_reference_1" type="fixed">
    <origin rpy="0 0 0" xyz="-0.07225 0.10885 0.0014295"/>
    <parent link="backpack_layer_4_compartment_1_link"/>
    <child link="backpack_layer_4_compartment_1_reference_1_link"/>
  </joint>
  <link name="backpack_layer_4_compartment_1_reference_2_link"/>
  <joint name="backpack_layer_4_compartment_1_to_reference_2" type="fixed">
    <origin rpy="0 0 0" xyz="0.07225 0.10885 0.0014295"/>
    <parent link="backpack_layer_4_compartment_1_link"/>
    <child link="backpack_layer_4_compartment_1_reference_2_link"/>
  </joint>
  <!-- ====== END OF LAYERS ====== -->
  <link name="charger_connector">
    <inertial>
      <origin rpy="0 0 0" xyz="0 0 0"/>
      <mass value="2.5"/>
      <inertia ixx="0.02604167" ixy="0" ixz="0" iyy="0.01308413" iyz="0" izz="0.01308413"/>
    </inertial>
    <visual>
      <geometry>
        <mesh filename="package://soto_backpack_5_1_description/meshes/charger_connector.STL"/>
      </geometry>
      <material name="">
        <color rgba="0 0.4510 0.8275 1"/>
      </material>
    </visual>
  </link>
  <joint name="backpack_base_to_charger_connector" type="fixed">
    <origin rpy="-1.5708 0 1.5708" xyz="-0.41931 0.48443 0.17425"/>
    <parent link="backpack_base_link"/>
    <child link="charger_connector"/>
  </joint>
  <link name="nav_depth_camera_rear_link">
    <inertial>
      <origin rpy="0 0 0" xyz="-0.025274 0.00013854 -0.023398"/>
      <mass value="1.0"/>
      <inertia ixx="0.00081667" ixy="0" ixz="0" iyy="0.00094167" iyz="0" izz="0.00094167"/>
    </inertial>
    <visual>
      <geometry>
        <mesh filename="package://soto_backpack_5_1_description/meshes/nav_depth_camera_rear_link.STL"/>
      </geometry>
      <material name="">
        <color rgba="0 0.292 0.403 1"/>
      </material>
    </visual>
    <collision>
      <origin rpy="0 0 0" xyz="0.0125 -0.01475 -0.035"/>
      <geometry>
        <box size="0.08 0.07 0.07"/>
      </geometry>
    </collision>
  </link>
  <joint name="nav_depth_camera_rear" type="fixed">
    <origin rpy="-2.32129 0.0 1.5708" xyz="-0.77839 -0.0572 1.74081"/>
    <parent link="backpack_base_link"/>
    <child link="nav_depth_camera_rear_link"/>
  </joint>
  <link name="light_curtain_emitter_rear_link">
    <inertial>
      <origin rpy="0 0 0" xyz="-0.013451 0 0"/>
      <mass value="0.63959"/>
      <inertia ixx="0.03084176" ixy="0" ixz="0" iyy="0.00013446" iyz="0" izz="0.03082808"/>
    </inertial>
    <visual>
      <geometry>
        <mesh filename="package://soto_backpack_5_1_description/meshes/light_curtain_emitter_rear_link.STL"/>
      </geometry>
      <material name="">
        <color rgba="0.9780 0.8557 0 1"/>
      </material>
    </visual>
    <collision>
      <origin rpy="1.5708 0 0" xyz="-0.015 0 0"/>
      <geometry>
        <cylinder length="0.7625" radius="0.015"/>
      </geometry>
    </collision>
  </link>
  <joint name="base_to_light_curtain_emitter_rear" type="fixed">
    <origin rpy="3.1416 1.5708 0" xyz="-0.777 -0.046458 1.6655"/>
    <parent link="backpack_base_link"/>
    <child link="light_curtain_emitter_rear_link"/>
  </joint>
  <link name="light_curtain_receiver_rear_link">
    <inertial>
      <origin rpy="0 0 0" xyz="-0.013451 0.00046065 0"/>
      <mass value="0.63959"/>
      <inertia ixx="0.03084176" ixy="0" ixz="0" iyy="0.00013446" iyz="0" izz="0.03082808"/>
    </inertial>
    <visual>
      <geometry>
        <mesh filename="package://soto_backpack_5_1_description/meshes/light_curtain_receiver_rear_link.STL"/>
      </geometry>
      <material name="">
        <color rgba="0.9780 0.8557 0 1"/>
      </material>
    </visual>
    <collision>
      <origin rpy="1.5708 0 0" xyz="-0.015 0 0"/>
      <geometry>
        <cylinder length="0.7625" radius="0.015"/>
      </geometry>
    </collision>
  </link>
  <joint name="base_to_light_curtain_receiver_rear" type="fixed">
    <origin rpy="0 -1.5708 0" xyz="-0.777 -0.04594 -0.00093012"/>
    <parent link="backpack_base_link"/>
    <child link="light_curtain_receiver_rear_link"/>
  </joint>
  <link name="blue_spot_rear_link"/>
  <joint name="blue_spot_rear" type="fixed">
    <origin rpy="0 2.32129 0" xyz="-0.77839 -0.1632 1.74081"/>
    <parent link="backpack_base_link"/>
    <child link="blue_spot_rear_link"/>
  </joint>
  <link name="design_elements_link">
    <inertial>
      <origin rpy="0 0 0" xyz="0.10328 -0.024946 1.1175"/>
      <mass value="54.496"/>
      <inertia ixx="107.138" ixy="0.583689" ixz="6.542658" iyy="128.01832" iyz="-1.172259" izz="39.539432"/>
    </inertial>
    <visual>
      <geometry>
        <mesh filename="package://soto_2_1_description/meshes/design_elements_link.STL"/>
      </geometry>
      <material name="">
        <color rgba="0.69804 0.69804 0.69804 1"/>
      </material>
    </visual>
  </link>
  <joint name="base_to_design_elements" type="fixed">
    <parent link="base_link"/>
    <child link="design_elements_link"/>
  </joint>

  <link name="cylinder_left_4">
		<visual>
			<geometry>
				<cylinder length="0.05" radius="0.003"/>
			</geometry>
			<origin rpy="-1.57075 -1.57075 0"/>
			<material name="black"/>
		</visual>
		<collision>
			<geometry>
				<cylinder length="0.05" radius="0.003"/>
			</geometry>
			<origin rpy="-1.57075 -1.57075 0"/>
		</collision>
		<inertial>
			<origin rpy="-1.57075 -1.57075 0"/>
			<mass value="0.3"/>
			<inertia ixx="0.4" ixy="0" ixz="0" iyy="0.4" iyz="0.0" izz="0.2"/>
		</inertial>
	</link>
	<joint name="cylinder_left_4_to_belt" type="revolute">
		<parent link="conveyor_belt_left_foremost_link"/>
		<child link="cylinder_left_4"/>
		<axis xyz="0 1 0"/>
		<origin xyz="-0.68 0.0 0.005"/>
		<limit effort="100" lower="-100" upper="100" velocity="100"/>
	</joint>

	<link name="cylinder_left_5">
		<visual>
			<geometry>
				<cylinder length="0.05" radius="0.003"/>
			</geometry>
			<origin rpy="-1.57075 -1.57075 0"/>
			<material name="black"/>
		</visual>
		<collision>
			<geometry>
				<cylinder length="0.05" radius="0.003"/>
			</geometry>
			<origin rpy="-1.57075 -1.57075 0"/>
		</collision>
		<inertial>
			<origin rpy="-1.57075 -1.57075 0"/>
			<mass value="0.3"/>
			<inertia ixx="0.4" ixy="0" ixz="0" iyy="0.4" iyz="0.0" izz="0.2"/>
		</inertial>
	</link>
	<joint name="cylinder_left_5_to_belt" type="revolute">
		<parent link="conveyor_belt_left_foremost_link"/>
		<child link="cylinder_left_5"/>
		<axis xyz="0 1 0"/>
		<origin xyz="-0.655 0.0 0.005"/>
		<limit effort="100" lower="-100" upper="100" velocity="100"/>
	</joint>
	<link name="cylinder_left_6">
		<visual>
			<geometry>
				<cylinder length="0.05" radius="0.003"/>
			</geometry>
			<origin rpy="-1.57075 -1.57075 0"/>
			<material name="black"/>
		</visual>
		<collision>
			<geometry>
				<cylinder length="0.05" radius="0.003"/>
			</geometry>
			<origin rpy="-1.57075 -1.57075 0"/>
		</collision>
		<inertial>
			<origin rpy="-1.57075 -1.57075 0"/>
			<mass value="0.3"/>
			<inertia ixx="0.4" ixy="0" ixz="0" iyy="0.4" iyz="0.0" izz="0.2"/>
		</inertial>
	</link>
	<joint name="cylinder_left_6_to_belt" type="revolute">
		<parent link="conveyor_belt_left_foremost_link"/>
		<child link="cylinder_left_6"/>
		<axis xyz="0 1 0"/>
		<origin xyz="-0.63 0.0 0.005"/>
		<limit effort="100" lower="-100" upper="100" velocity="100"/>
	</joint>
	<link name="cylinder_left_7">
		<visual>
			<geometry>
				<cylinder length="0.05" radius="0.003"/>
			</geometry>
			<origin rpy="-1.57075 -1.57075 0"/>
			<material name="black"/>
		</visual>
		<collision>
			<geometry>
				<cylinder length="0.05" radius="0.003"/>
			</geometry>
			<origin rpy="-1.57075 -1.57075 0"/>
		</collision>
		<inertial>
			<origin rpy="-1.57075 -1.57075 0"/>
			<mass value="0.3"/>
			<inertia ixx="0.4" ixy="0" ixz="0" iyy="0.4" iyz="0.0" izz="0.2"/>
		</inertial>
	</link>
	<joint name="cylinder_left_7_to_belt" type="revolute">
		<parent link="conveyor_belt_left_foremost_link"/>
		<child link="cylinder_left_7"/>
		<axis xyz="0 1 0"/>
		<origin xyz="-0.605 0.0 0.005"/>
		<limit effort="100" lower="-100" upper="100" velocity="100"/>
	</joint>
	<link name="cylinder_left_8">
		<visual>
			<geometry>
				<cylinder length="0.05" radius="0.003"/>
			</geometry>
			<origin rpy="-1.57075 -1.57075 0"/>
			<material name="black"/>
		</visual>
		<collision>
			<geometry>
				<cylinder length="0.05" radius="0.003"/>
			</geometry>
			<origin rpy="-1.57075 -1.57075 0"/>
		</collision>
		<inertial>
			<origin rpy="-1.57075 -1.57075 0"/>
			<mass value="0.3"/>
			<inertia ixx="0.4" ixy="0" ixz="0" iyy="0.4" iyz="0.0" izz="0.2"/>
		</inertial>
	</link>
	<joint name="cylinder_left_8_to_belt" type="revolute">
		<parent link="conveyor_belt_left_foremost_link"/>
		<child link="cylinder_left_8"/>
		<axis xyz="0 1 0"/>
		<origin xyz="-0.5800000000000001 0.0 0.005"/>
		<limit effort="100" lower="-100" upper="100" velocity="100"/>
	</joint>
	<link name="cylinder_left_9">
		<visual>
			<geometry>
				<cylinder length="0.05" radius="0.003"/>
			</geometry>
			<origin rpy="-1.57075 -1.57075 0"/>
			<material name="black"/>
		</visual>
		<collision>
			<geometry>
				<cylinder length="0.05" radius="0.003"/>
			</geometry>
			<origin rpy="-1.57075 -1.57075 0"/>
		</collision>
		<inertial>
			<origin rpy="-1.57075 -1.57075 0"/>
			<mass value="0.3"/>
			<inertia ixx="0.4" ixy="0" ixz="0" iyy="0.4" iyz="0.0" izz="0.2"/>
		</inertial>
	</link>
	<joint name="cylinder_left_9_to_belt" type="revolute">
		<parent link="conveyor_belt_left_foremost_link"/>
		<child link="cylinder_left_9"/>
		<axis xyz="0 1 0"/>
		<origin xyz="-0.555 0.0 0.005"/>
		<limit effort="100" lower="-100" upper="100" velocity="100"/>
	</joint>
	<link name="cylinder_left_10">
		<visual>
			<geometry>
				<cylinder length="0.05" radius="0.003"/>
			</geometry>
			<origin rpy="-1.57075 -1.57075 0"/>
			<material name="black"/>
		</visual>
		<collision>
			<geometry>
				<cylinder length="0.05" radius="0.003"/>
			</geometry>
			<origin rpy="-1.57075 -1.57075 0"/>
		</collision>
		<inertial>
			<origin rpy="-1.57075 -1.57075 0"/>
			<mass value="0.3"/>
			<inertia ixx="0.4" ixy="0" ixz="0" iyy="0.4" iyz="0.0" izz="0.2"/>
		</inertial>
	</link>
	<joint name="cylinder_left_10_to_belt" type="revolute">
		<parent link="conveyor_belt_left_foremost_link"/>
		<child link="cylinder_left_10"/>
		<axis xyz="0 1 0"/>
		<origin xyz="-0.53 0.0 0.005"/>
		<limit effort="100" lower="-100" upper="100" velocity="100"/>
	</joint>
	<link name="cylinder_left_11">
		<visual>
			<geometry>
				<cylinder length="0.05" radius="0.003"/>
			</geometry>
			<origin rpy="-1.57075 -1.57075 0"/>
			<material name="black"/>
		</visual>
		<collision>
			<geometry>
				<cylinder length="0.05" radius="0.003"/>
			</geometry>
			<origin rpy="-1.57075 -1.57075 0"/>
		</collision>
		<inertial>
			<origin rpy="-1.57075 -1.57075 0"/>
			<mass value="0.3"/>
			<inertia ixx="0.4" ixy="0" ixz="0" iyy="0.4" iyz="0.0" izz="0.2"/>
		</inertial>
	</link>
	<joint name="cylinder_left_11_to_belt" type="revolute">
		<parent link="conveyor_belt_left_foremost_link"/>
		<child link="cylinder_left_11"/>
		<axis xyz="0 1 0"/>
		<origin xyz="-0.505 0.0 0.005"/>
		<limit effort="100" lower="-100" upper="100" velocity="100"/>
	</joint>
	<link name="cylinder_left_12">
		<visual>
			<geometry>
				<cylinder length="0.05" radius="0.003"/>
			</geometry>
			<origin rpy="-1.57075 -1.57075 0"/>
			<material name="black"/>
		</visual>
		<collision>
			<geometry>
				<cylinder length="0.05" radius="0.003"/>
			</geometry>
			<origin rpy="-1.57075 -1.57075 0"/>
		</collision>
		<inertial>
			<origin rpy="-1.57075 -1.57075 0"/>
			<mass value="0.3"/>
			<inertia ixx="0.4" ixy="0" ixz="0" iyy="0.4" iyz="0.0" izz="0.2"/>
		</inertial>
	</link>
	<joint name="cylinder_left_12_to_belt" type="revolute">
		<parent link="conveyor_belt_left_foremost_link"/>
		<child link="cylinder_left_12"/>
		<axis xyz="0 1 0"/>
		<origin xyz="-0.48 0.0 0.005"/>
		<limit effort="100" lower="-100" upper="100" velocity="100"/>
	</joint>
	<link name="cylinder_left_13">
		<visual>
			<geometry>
				<cylinder length="0.05" radius="0.003"/>
			</geometry>
			<origin rpy="-1.57075 -1.57075 0"/>
			<material name="black"/>
		</visual>
		<collision>
			<geometry>
				<cylinder length="0.05" radius="0.003"/>
			</geometry>
			<origin rpy="-1.57075 -1.57075 0"/>
		</collision>
		<inertial>
			<origin rpy="-1.57075 -1.57075 0"/>
			<mass value="0.3"/>
			<inertia ixx="0.4" ixy="0" ixz="0" iyy="0.4" iyz="0.0" izz="0.2"/>
		</inertial>
	</link>
	<joint name="cylinder_left_13_to_belt" type="revolute">
		<parent link="conveyor_belt_left_foremost_link"/>
		<child link="cylinder_left_13"/>
		<axis xyz="0 1 0"/>
		<origin xyz="-0.455 0.0 0.005"/>
		<limit effort="100" lower="-100" upper="100" velocity="100"/>
	</joint>
	<link name="cylinder_left_14">
		<visual>
			<geometry>
				<cylinder length="0.05" radius="0.003"/>
			</geometry>
			<origin rpy="-1.57075 -1.57075 0"/>
			<material name="black"/>
		</visual>
		<collision>
			<geometry>
				<cylinder length="0.05" radius="0.003"/>
			</geometry>
			<origin rpy="-1.57075 -1.57075 0"/>
		</collision>
		<inertial>
			<origin rpy="-1.57075 -1.57075 0"/>
			<mass value="0.3"/>
			<inertia ixx="0.4" ixy="0" ixz="0" iyy="0.4" iyz="0.0" izz="0.2"/>
		</inertial>
	</link>
	<joint name="cylinder_left_14_to_belt" type="revolute">
		<parent link="conveyor_belt_left_foremost_link"/>
		<child link="cylinder_left_14"/>
		<axis xyz="0 1 0"/>
		<origin xyz="-0.43 0.0 0.005"/>
		<limit effort="100" lower="-100" upper="100" velocity="100"/>
	</joint>
	<link name="cylinder_left_15">
		<visual>
			<geometry>
				<cylinder length="0.05" radius="0.003"/>
			</geometry>
			<origin rpy="-1.57075 -1.57075 0"/>
			<material name="black"/>
		</visual>
		<collision>
			<geometry>
				<cylinder length="0.05" radius="0.003"/>
			</geometry>
			<origin rpy="-1.57075 -1.57075 0"/>
		</collision>
		<inertial>
			<origin rpy="-1.57075 -1.57075 0"/>
			<mass value="0.3"/>
			<inertia ixx="0.4" ixy="0" ixz="0" iyy="0.4" iyz="0.0" izz="0.2"/>
		</inertial>
	</link>
	<joint name="cylinder_left_15_to_belt" type="revolute">
		<parent link="conveyor_belt_left_foremost_link"/>
		<child link="cylinder_left_15"/>
		<axis xyz="0 1 0"/>
		<origin xyz="-0.405 0.0 0.005"/>
		<limit effort="100" lower="-100" upper="100" velocity="100"/>
	</joint>
	<link name="cylinder_left_16">
		<visual>
			<geometry>
				<cylinder length="0.05" radius="0.003"/>
			</geometry>
			<origin rpy="-1.57075 -1.57075 0"/>
			<material name="black"/>
		</visual>
		<collision>
			<geometry>
				<cylinder length="0.05" radius="0.003"/>
			</geometry>
			<origin rpy="-1.57075 -1.57075 0"/>
		</collision>
		<inertial>
			<origin rpy="-1.57075 -1.57075 0"/>
			<mass value="0.3"/>
			<inertia ixx="0.4" ixy="0" ixz="0" iyy="0.4" iyz="0.0" izz="0.2"/>
		</inertial>
	</link>
	<joint name="cylinder_left_16_to_belt" type="revolute">
		<parent link="conveyor_belt_left_foremost_link"/>
		<child link="cylinder_left_16"/>
		<axis xyz="0 1 0"/>
		<origin xyz="-0.38 0.0 0.005"/>
		<limit effort="100" lower="-100" upper="100" velocity="100"/>
	</joint>
	<link name="cylinder_left_17">
		<visual>
			<geometry>
				<cylinder length="0.05" radius="0.003"/>
			</geometry>
			<origin rpy="-1.57075 -1.57075 0"/>
			<material name="black"/>
		</visual>
		<collision>
			<geometry>
				<cylinder length="0.05" radius="0.003"/>
			</geometry>
			<origin rpy="-1.57075 -1.57075 0"/>
		</collision>
		<inertial>
			<origin rpy="-1.57075 -1.57075 0"/>
			<mass value="0.3"/>
			<inertia ixx="0.4" ixy="0" ixz="0" iyy="0.4" iyz="0.0" izz="0.2"/>
		</inertial>
	</link>
	<joint name="cylinder_left_17_to_belt" type="revolute">
		<parent link="conveyor_belt_left_foremost_link"/>
		<child link="cylinder_left_17"/>
		<axis xyz="0 1 0"/>
		<origin xyz="-0.355 0.0 0.005"/>
		<limit effort="100" lower="-100" upper="100" velocity="100"/>
	</joint>
	<link name="cylinder_left_18">
		<visual>
			<geometry>
				<cylinder length="0.05" radius="0.003"/>
			</geometry>
			<origin rpy="-1.57075 -1.57075 0"/>
			<material name="black"/>
		</visual>
		<collision>
			<geometry>
				<cylinder length="0.05" radius="0.003"/>
			</geometry>
			<origin rpy="-1.57075 -1.57075 0"/>
		</collision>
		<inertial>
			<origin rpy="-1.57075 -1.57075 0"/>
			<mass value="0.3"/>
			<inertia ixx="0.4" ixy="0" ixz="0" iyy="0.4" iyz="0.0" izz="0.2"/>
		</inertial>
	</link>
	<joint name="cylinder_left_18_to_belt" type="revolute">
		<parent link="conveyor_belt_left_foremost_link"/>
		<child link="cylinder_left_18"/>
		<axis xyz="0 1 0"/>
		<origin xyz="-0.33 0.0 0.005"/>
		<limit effort="100" lower="-100" upper="100" velocity="100"/>
	</joint>
	<link name="cylinder_left_19">
		<visual>
			<geometry>
				<cylinder length="0.05" radius="0.003"/>
			</geometry>
			<origin rpy="-1.57075 -1.57075 0"/>
			<material name="black"/>
		</visual>
		<collision>
			<geometry>
				<cylinder length="0.05" radius="0.003"/>
			</geometry>
			<origin rpy="-1.57075 -1.57075 0"/>
		</collision>
		<inertial>
			<origin rpy="-1.57075 -1.57075 0"/>
			<mass value="0.3"/>
			<inertia ixx="0.4" ixy="0" ixz="0" iyy="0.4" iyz="0.0" izz="0.2"/>
		</inertial>
	</link>
	<joint name="cylinder_left_19_to_belt" type="revolute">
		<parent link="conveyor_belt_left_foremost_link"/>
		<child link="cylinder_left_19"/>
		<axis xyz="0 1 0"/>
		<origin xyz="-0.305 0.0 0.005"/>
		<limit effort="100" lower="-100" upper="100" velocity="100"/>
	</joint>
	<link name="cylinder_left_20">
		<visual>
			<geometry>
				<cylinder length="0.05" radius="0.003"/>
			</geometry>
			<origin rpy="-1.57075 -1.57075 0"/>
			<material name="black"/>
		</visual>
		<collision>
			<geometry>
				<cylinder length="0.05" radius="0.003"/>
			</geometry>
			<origin rpy="-1.57075 -1.57075 0"/>
		</collision>
		<inertial>
			<origin rpy="-1.57075 -1.57075 0"/>
			<mass value="0.3"/>
			<inertia ixx="0.4" ixy="0" ixz="0" iyy="0.4" iyz="0.0" izz="0.2"/>
		</inertial>
	</link>
	<joint name="cylinder_left_20_to_belt" type="revolute">
		<parent link="conveyor_belt_left_foremost_link"/>
		<child link="cylinder_left_20"/>
		<axis xyz="0 1 0"/>
		<origin xyz="-0.28 0.0 0.005"/>
		<limit effort="100" lower="-100" upper="100" velocity="100"/>
	</joint>
	<link name="cylinder_left_21">
		<visual>
			<geometry>
				<cylinder length="0.05" radius="0.003"/>
			</geometry>
			<origin rpy="-1.57075 -1.57075 0"/>
			<material name="black"/>
		</visual>
		<collision>
			<geometry>
				<cylinder length="0.05" radius="0.003"/>
			</geometry>
			<origin rpy="-1.57075 -1.57075 0"/>
		</collision>
		<inertial>
			<origin rpy="-1.57075 -1.57075 0"/>
			<mass value="0.3"/>
			<inertia ixx="0.4" ixy="0" ixz="0" iyy="0.4" iyz="0.0" izz="0.2"/>
		</inertial>
	</link>
	<joint name="cylinder_left_21_to_belt" type="revolute">
		<parent link="conveyor_belt_left_foremost_link"/>
		<child link="cylinder_left_21"/>
		<axis xyz="0 1 0"/>
		<origin xyz="-0.255 0.0 0.005"/>
		<limit effort="100" lower="-100" upper="100" velocity="100"/>
	</joint>
	<link name="cylinder_left_22">
		<visual>
			<geometry>
				<cylinder length="0.05" radius="0.003"/>
			</geometry>
			<origin rpy="-1.57075 -1.57075 0"/>
			<material name="black"/>
		</visual>
		<collision>
			<geometry>
				<cylinder length="0.05" radius="0.003"/>
			</geometry>
			<origin rpy="-1.57075 -1.57075 0"/>
		</collision>
		<inertial>
			<origin rpy="-1.57075 -1.57075 0"/>
			<mass value="0.3"/>
			<inertia ixx="0.4" ixy="0" ixz="0" iyy="0.4" iyz="0.0" izz="0.2"/>
		</inertial>
	</link>
	<joint name="cylinder_left_22_to_belt" type="revolute">
		<parent link="conveyor_belt_left_foremost_link"/>
		<child link="cylinder_left_22"/>
		<axis xyz="0 1 0"/>
		<origin xyz="-0.22999999999999998 0.0 0.005"/>
		<limit effort="100" lower="-100" upper="100" velocity="100"/>
	</joint>
	<link name="cylinder_left_23">
		<visual>
			<geometry>
				<cylinder length="0.05" radius="0.003"/>
			</geometry>
			<origin rpy="-1.57075 -1.57075 0"/>
			<material name="black"/>
		</visual>
		<collision>
			<geometry>
				<cylinder length="0.05" radius="0.003"/>
			</geometry>
			<origin rpy="-1.57075 -1.57075 0"/>
		</collision>
		<inertial>
			<origin rpy="-1.57075 -1.57075 0"/>
			<mass value="0.3"/>
			<inertia ixx="0.4" ixy="0" ixz="0" iyy="0.4" iyz="0.0" izz="0.2"/>
		</inertial>
	</link>
	<joint name="cylinder_left_23_to_belt" type="revolute">
		<parent link="conveyor_belt_left_foremost_link"/>
		<child link="cylinder_left_23"/>
		<axis xyz="0 1 0"/>
		<origin xyz="-0.20499999999999996 0.0 0.005"/>
		<limit effort="100" lower="-100" upper="100" velocity="100"/>
	</joint>
	<link name="cylinder_left_24">
		<visual>
			<geometry>
				<cylinder length="0.05" radius="0.003"/>
			</geometry>
			<origin rpy="-1.57075 -1.57075 0"/>
			<material name="black"/>
		</visual>
		<collision>
			<geometry>
				<cylinder length="0.05" radius="0.003"/>
			</geometry>
			<origin rpy="-1.57075 -1.57075 0"/>
		</collision>
		<inertial>
			<origin rpy="-1.57075 -1.57075 0"/>
			<mass value="0.3"/>
			<inertia ixx="0.4" ixy="0" ixz="0" iyy="0.4" iyz="0.0" izz="0.2"/>
		</inertial>
	</link>
	<joint name="cylinder_left_24_to_belt" type="revolute">
		<parent link="conveyor_belt_left_foremost_link"/>
		<child link="cylinder_left_24"/>
		<axis xyz="0 1 0"/>
		<origin xyz="-0.17999999999999994 0.0 0.005"/>
		<limit effort="100" lower="-100" upper="100" velocity="100"/>
	</joint>
	<link name="cylinder_left_25">
		<visual>
			<geometry>
				<cylinder length="0.05" radius="0.003"/>
			</geometry>
			<origin rpy="-1.57075 -1.57075 0"/>
			<material name="black"/>
		</visual>
		<collision>
			<geometry>
				<cylinder length="0.05" radius="0.003"/>
			</geometry>
			<origin rpy="-1.57075 -1.57075 0"/>
		</collision>
		<inertial>
			<origin rpy="-1.57075 -1.57075 0"/>
			<mass value="0.3"/>
			<inertia ixx="0.4" ixy="0" ixz="0" iyy="0.4" iyz="0.0" izz="0.2"/>
		</inertial>
	</link>
	<joint name="cylinder_left_25_to_belt" type="revolute">
		<parent link="conveyor_belt_left_foremost_link"/>
		<child link="cylinder_left_25"/>
		<axis xyz="0 1 0"/>
		<origin xyz="-0.15500000000000003 0.0 0.005"/>
		<limit effort="100" lower="-100" upper="100" velocity="100"/>
	</joint>
	<link name="cylinder_left_26">
		<visual>
			<geometry>
				<cylinder length="0.05" radius="0.003"/>
			</geometry>
			<origin rpy="-1.57075 -1.57075 0"/>
			<material name="black"/>
		</visual>
		<collision>
			<geometry>
				<cylinder length="0.05" radius="0.003"/>
			</geometry>
			<origin rpy="-1.57075 -1.57075 0"/>
		</collision>
		<inertial>
			<origin rpy="-1.57075 -1.57075 0"/>
			<mass value="0.3"/>
			<inertia ixx="0.4" ixy="0" ixz="0" iyy="0.4" iyz="0.0" izz="0.2"/>
		</inertial>
	</link>
	<joint name="cylinder_left_26_to_belt" type="revolute">
		<parent link="conveyor_belt_left_foremost_link"/>
		<child link="cylinder_left_26"/>
		<axis xyz="0 1 0"/>
		<origin xyz="-0.13 0.0 0.005"/>
		<limit effort="100" lower="-100" upper="100" velocity="100"/>
	</joint>
	<link name="cylinder_left_27">
		<visual>
			<geometry>
				<cylinder length="0.05" radius="0.003"/>
			</geometry>
			<origin rpy="-1.57075 -1.57075 0"/>
			<material name="black"/>
		</visual>
		<collision>
			<geometry>
				<cylinder length="0.05" radius="0.003"/>
			</geometry>
			<origin rpy="-1.57075 -1.57075 0"/>
		</collision>
		<inertial>
			<origin rpy="-1.57075 -1.57075 0"/>
			<mass value="0.3"/>
			<inertia ixx="0.4" ixy="0" ixz="0" iyy="0.4" iyz="0.0" izz="0.2"/>
		</inertial>
	</link>
	<joint name="cylinder_left_27_to_belt" type="revolute">
		<parent link="conveyor_belt_left_foremost_link"/>
		<child link="cylinder_left_27"/>
		<axis xyz="0 1 0"/>
		<origin xyz="-0.10499999999999998 0.0 0.005"/>
		<limit effort="100" lower="-100" upper="100" velocity="100"/>
	</joint>
	<link name="cylinder_left_28">
		<visual>
			<geometry>
				<cylinder length="0.05" radius="0.003"/>
			</geometry>
			<origin rpy="-1.57075 -1.57075 0"/>
			<material name="black"/>
		</visual>
		<collision>
			<geometry>
				<cylinder length="0.05" radius="0.003"/>
			</geometry>
			<origin rpy="-1.57075 -1.57075 0"/>
		</collision>
		<inertial>
			<origin rpy="-1.57075 -1.57075 0"/>
			<mass value="0.3"/>
			<inertia ixx="0.4" ixy="0" ixz="0" iyy="0.4" iyz="0.0" izz="0.2"/>
		</inertial>
	</link>
	<joint name="cylinder_left_28_to_belt" type="revolute">
		<parent link="conveyor_belt_left_foremost_link"/>
		<child link="cylinder_left_28"/>
		<axis xyz="0 1 0"/>
		<origin xyz="-0.07999999999999996 0.0 0.005"/>
		<limit effort="100" lower="-100" upper="100" velocity="100"/>
	</joint>
	<link name="cylinder_left_29">
		<visual>
			<geometry>
				<cylinder length="0.05" radius="0.003"/>
			</geometry>
			<origin rpy="-1.57075 -1.57075 0"/>
			<material name="black"/>
		</visual>
		<collision>
			<geometry>
				<cylinder length="0.05" radius="0.003"/>
			</geometry>
			<origin rpy="-1.57075 -1.57075 0"/>
		</collision>
		<inertial>
			<origin rpy="-1.57075 -1.57075 0"/>
			<mass value="0.3"/>
			<inertia ixx="0.4" ixy="0" ixz="0" iyy="0.4" iyz="0.0" izz="0.2"/>
		</inertial>
	</link>
	<joint name="cylinder_left_29_to_belt" type="revolute">
		<parent link="conveyor_belt_left_foremost_link"/>
		<child link="cylinder_left_29"/>
		<axis xyz="0 1 0"/>
		<origin xyz="-0.05499999999999994 0.0 0.005"/>
		<limit effort="100" lower="-100" upper="100" velocity="100"/>
	</joint>
	<link name="cylinder_left_30">
		<visual>
			<geometry>
				<cylinder length="0.05" radius="0.003"/>
			</geometry>
			<origin rpy="-1.57075 -1.57075 0"/>
			<material name="black"/>
		</visual>
		<collision>
			<geometry>
				<cylinder length="0.05" radius="0.003"/>
			</geometry>
			<origin rpy="-1.57075 -1.57075 0"/>
		</collision>
		<inertial>
			<origin rpy="-1.57075 -1.57075 0"/>
			<mass value="0.3"/>
			<inertia ixx="0.4" ixy="0" ixz="0" iyy="0.4" iyz="0.0" izz="0.2"/>
		</inertial>
	</link>
	<joint name="cylinder_left_30_to_belt" type="revolute">
		<parent link="conveyor_belt_left_foremost_link"/>
		<child link="cylinder_left_30"/>
		<axis xyz="0 1 0"/>
		<origin xyz="-0.030000000000000027 0.0 0.005"/>
		<limit effort="100" lower="-100" upper="100" velocity="100"/>
	</joint>
	<link name="cylinder_left_31">
		<visual>
			<geometry>
				<cylinder length="0.05" radius="0.003"/>
			</geometry>
			<origin rpy="-1.57075 -1.57075 0"/>
			<material name="black"/>
		</visual>
		<collision>
			<geometry>
				<cylinder length="0.05" radius="0.003"/>
			</geometry>
			<origin rpy="-1.57075 -1.57075 0"/>
		</collision>
		<inertial>
			<origin rpy="-1.57075 -1.57075 0"/>
			<mass value="0.3"/>
			<inertia ixx="0.4" ixy="0" ixz="0" iyy="0.4" iyz="0.0" izz="0.2"/>
		</inertial>
	</link>
	<joint name="cylinder_left_31_to_belt" type="revolute">
		<parent link="conveyor_belt_left_foremost_link"/>
		<child link="cylinder_left_31"/>
		<axis xyz="0 1 0"/>
		<origin xyz="-0.0043 0.0 -0.00"/>
		<limit effort="100" lower="-100" upper="100" velocity="100"/>
	</joint>




  <link name="cylinder_right_4">
		<visual>
			<geometry>
				<cylinder length="0.05" radius="0.003"/>
			</geometry>
			<origin rpy="-1.57075 -1.57075 0"/>
			<material name="black"/>
		</visual>
		<collision>
			<geometry>
				<cylinder length="0.05" radius="0.003"/>
			</geometry>
			<origin rpy="-1.57075 -1.57075 0"/>
		</collision>
		<inertial>
			<origin rpy="-1.57075 -1.57075 0"/>
			<mass value="0.3"/>
			<inertia ixx="0.4" ixy="0" ixz="0" iyy="0.4" iyz="0.0" izz="0.2"/>
		</inertial>
	</link>
	<joint name="cylinder_right_4_to_belt" type="revolute">
		<parent link="conveyor_belt_right_foremost_link"/>
		<child link="cylinder_right_4"/>
		<axis xyz="0 1 0"/>
		<origin xyz="-0.68 0.0 0.005"/>
		<limit effort="100" lower="-100" upper="100" velocity="100"/>
	</joint>

	<link name="cylinder_right_5">
		<visual>
			<geometry>
				<cylinder length="0.05" radius="0.003"/>
			</geometry>
			<origin rpy="-1.57075 -1.57075 0"/>
			<material name="black"/>
		</visual>
		<collision>
			<geometry>
				<cylinder length="0.05" radius="0.003"/>
			</geometry>
			<origin rpy="-1.57075 -1.57075 0"/>
		</collision>
		<inertial>
			<origin rpy="-1.57075 -1.57075 0"/>
			<mass value="0.3"/>
			<inertia ixx="0.4" ixy="0" ixz="0" iyy="0.4" iyz="0.0" izz="0.2"/>
		</inertial>
	</link>
	<joint name="cylinder_right_5_to_belt" type="revolute">
		<parent link="conveyor_belt_right_foremost_link"/>
		<child link="cylinder_right_5"/>
		<axis xyz="0 1 0"/>
		<origin xyz="-0.655 0.0 0.005"/>
		<limit effort="100" lower="-100" upper="100" velocity="100"/>
	</joint>
	<link name="cylinder_right_6">
		<visual>
			<geometry>
				<cylinder length="0.05" radius="0.003"/>
			</geometry>
			<origin rpy="-1.57075 -1.57075 0"/>
			<material name="black"/>
		</visual>
		<collision>
			<geometry>
				<cylinder length="0.05" radius="0.003"/>
			</geometry>
			<origin rpy="-1.57075 -1.57075 0"/>
		</collision>
		<inertial>
			<origin rpy="-1.57075 -1.57075 0"/>
			<mass value="0.3"/>
			<inertia ixx="0.4" ixy="0" ixz="0" iyy="0.4" iyz="0.0" izz="0.2"/>
		</inertial>
	</link>
	<joint name="cylinder_right_6_to_belt" type="revolute">
		<parent link="conveyor_belt_right_foremost_link"/>
		<child link="cylinder_right_6"/>
		<axis xyz="0 1 0"/>
		<origin xyz="-0.63 0.0 0.005"/>
		<limit effort="100" lower="-100" upper="100" velocity="100"/>
	</joint>
	<link name="cylinder_right_7">
		<visual>
			<geometry>
				<cylinder length="0.05" radius="0.003"/>
			</geometry>
			<origin rpy="-1.57075 -1.57075 0"/>
			<material name="black"/>
		</visual>
		<collision>
			<geometry>
				<cylinder length="0.05" radius="0.003"/>
			</geometry>
			<origin rpy="-1.57075 -1.57075 0"/>
		</collision>
		<inertial>
			<origin rpy="-1.57075 -1.57075 0"/>
			<mass value="0.3"/>
			<inertia ixx="0.4" ixy="0" ixz="0" iyy="0.4" iyz="0.0" izz="0.2"/>
		</inertial>
	</link>
	<joint name="cylinder_right_7_to_belt" type="revolute">
		<parent link="conveyor_belt_right_foremost_link"/>
		<child link="cylinder_right_7"/>
		<axis xyz="0 1 0"/>
		<origin xyz="-0.605 0.0 0.005"/>
		<limit effort="100" lower="-100" upper="100" velocity="100"/>
	</joint>
	<link name="cylinder_right_8">
		<visual>
			<geometry>
				<cylinder length="0.05" radius="0.003"/>
			</geometry>
			<origin rpy="-1.57075 -1.57075 0"/>
			<material name="black"/>
		</visual>
		<collision>
			<geometry>
				<cylinder length="0.05" radius="0.003"/>
			</geometry>
			<origin rpy="-1.57075 -1.57075 0"/>
		</collision>
		<inertial>
			<origin rpy="-1.57075 -1.57075 0"/>
			<mass value="0.3"/>
			<inertia ixx="0.4" ixy="0" ixz="0" iyy="0.4" iyz="0.0" izz="0.2"/>
		</inertial>
	</link>
	<joint name="cylinder_right_8_to_belt" type="revolute">
		<parent link="conveyor_belt_right_foremost_link"/>
		<child link="cylinder_right_8"/>
		<axis xyz="0 1 0"/>
		<origin xyz="-0.5800000000000001 0.0 0.005"/>
		<limit effort="100" lower="-100" upper="100" velocity="100"/>
	</joint>
	<link name="cylinder_right_9">
		<visual>
			<geometry>
				<cylinder length="0.05" radius="0.003"/>
			</geometry>
			<origin rpy="-1.57075 -1.57075 0"/>
			<material name="black"/>
		</visual>
		<collision>
			<geometry>
				<cylinder length="0.05" radius="0.003"/>
			</geometry>
			<origin rpy="-1.57075 -1.57075 0"/>
		</collision>
		<inertial>
			<origin rpy="-1.57075 -1.57075 0"/>
			<mass value="0.3"/>
			<inertia ixx="0.4" ixy="0" ixz="0" iyy="0.4" iyz="0.0" izz="0.2"/>
		</inertial>
	</link>
	<joint name="cylinder_right_9_to_belt" type="revolute">
		<parent link="conveyor_belt_right_foremost_link"/>
		<child link="cylinder_right_9"/>
		<axis xyz="0 1 0"/>
		<origin xyz="-0.555 0.0 0.005"/>
		<limit effort="100" lower="-100" upper="100" velocity="100"/>
	</joint>
	<link name="cylinder_right_10">
		<visual>
			<geometry>
				<cylinder length="0.05" radius="0.003"/>
			</geometry>
			<origin rpy="-1.57075 -1.57075 0"/>
			<material name="black"/>
		</visual>
		<collision>
			<geometry>
				<cylinder length="0.05" radius="0.003"/>
			</geometry>
			<origin rpy="-1.57075 -1.57075 0"/>
		</collision>
		<inertial>
			<origin rpy="-1.57075 -1.57075 0"/>
			<mass value="0.3"/>
			<inertia ixx="0.4" ixy="0" ixz="0" iyy="0.4" iyz="0.0" izz="0.2"/>
		</inertial>
	</link>
	<joint name="cylinder_right_10_to_belt" type="revolute">
		<parent link="conveyor_belt_right_foremost_link"/>
		<child link="cylinder_right_10"/>
		<axis xyz="0 1 0"/>
		<origin xyz="-0.53 0.0 0.005"/>
		<limit effort="100" lower="-100" upper="100" velocity="100"/>
	</joint>
	<link name="cylinder_right_11">
		<visual>
			<geometry>
				<cylinder length="0.05" radius="0.003"/>
			</geometry>
			<origin rpy="-1.57075 -1.57075 0"/>
			<material name="black"/>
		</visual>
		<collision>
			<geometry>
				<cylinder length="0.05" radius="0.003"/>
			</geometry>
			<origin rpy="-1.57075 -1.57075 0"/>
		</collision>
		<inertial>
			<origin rpy="-1.57075 -1.57075 0"/>
			<mass value="0.3"/>
			<inertia ixx="0.4" ixy="0" ixz="0" iyy="0.4" iyz="0.0" izz="0.2"/>
		</inertial>
	</link>
	<joint name="cylinder_right_11_to_belt" type="revolute">
		<parent link="conveyor_belt_right_foremost_link"/>
		<child link="cylinder_right_11"/>
		<axis xyz="0 1 0"/>
		<origin xyz="-0.505 0.0 0.005"/>
		<limit effort="100" lower="-100" upper="100" velocity="100"/>
	</joint>
	<link name="cylinder_right_12">
		<visual>
			<geometry>
				<cylinder length="0.05" radius="0.003"/>
			</geometry>
			<origin rpy="-1.57075 -1.57075 0"/>
			<material name="black"/>
		</visual>
		<collision>
			<geometry>
				<cylinder length="0.05" radius="0.003"/>
			</geometry>
			<origin rpy="-1.57075 -1.57075 0"/>
		</collision>
		<inertial>
			<origin rpy="-1.57075 -1.57075 0"/>
			<mass value="0.3"/>
			<inertia ixx="0.4" ixy="0" ixz="0" iyy="0.4" iyz="0.0" izz="0.2"/>
		</inertial>
	</link>
	<joint name="cylinder_right_12_to_belt" type="revolute">
		<parent link="conveyor_belt_right_foremost_link"/>
		<child link="cylinder_right_12"/>
		<axis xyz="0 1 0"/>
		<origin xyz="-0.48 0.0 0.005"/>
		<limit effort="100" lower="-100" upper="100" velocity="100"/>
	</joint>
	<link name="cylinder_right_13">
		<visual>
			<geometry>
				<cylinder length="0.05" radius="0.003"/>
			</geometry>
			<origin rpy="-1.57075 -1.57075 0"/>
			<material name="black"/>
		</visual>
		<collision>
			<geometry>
				<cylinder length="0.05" radius="0.003"/>
			</geometry>
			<origin rpy="-1.57075 -1.57075 0"/>
		</collision>
		<inertial>
			<origin rpy="-1.57075 -1.57075 0"/>
			<mass value="0.3"/>
			<inertia ixx="0.4" ixy="0" ixz="0" iyy="0.4" iyz="0.0" izz="0.2"/>
		</inertial>
	</link>
	<joint name="cylinder_right_13_to_belt" type="revolute">
		<parent link="conveyor_belt_right_foremost_link"/>
		<child link="cylinder_right_13"/>
		<axis xyz="0 1 0"/>
		<origin xyz="-0.455 0.0 0.005"/>
		<limit effort="100" lower="-100" upper="100" velocity="100"/>
	</joint>
	<link name="cylinder_right_14">
		<visual>
			<geometry>
				<cylinder length="0.05" radius="0.003"/>
			</geometry>
			<origin rpy="-1.57075 -1.57075 0"/>
			<material name="black"/>
		</visual>
		<collision>
			<geometry>
				<cylinder length="0.05" radius="0.003"/>
			</geometry>
			<origin rpy="-1.57075 -1.57075 0"/>
		</collision>
		<inertial>
			<origin rpy="-1.57075 -1.57075 0"/>
			<mass value="0.3"/>
			<inertia ixx="0.4" ixy="0" ixz="0" iyy="0.4" iyz="0.0" izz="0.2"/>
		</inertial>
	</link>
	<joint name="cylinder_right_14_to_belt" type="revolute">
		<parent link="conveyor_belt_right_foremost_link"/>
		<child link="cylinder_right_14"/>
		<axis xyz="0 1 0"/>
		<origin xyz="-0.43 0.0 0.005"/>
		<limit effort="100" lower="-100" upper="100" velocity="100"/>
	</joint>
	<link name="cylinder_right_15">
		<visual>
			<geometry>
				<cylinder length="0.05" radius="0.003"/>
			</geometry>
			<origin rpy="-1.57075 -1.57075 0"/>
			<material name="black"/>
		</visual>
		<collision>
			<geometry>
				<cylinder length="0.05" radius="0.003"/>
			</geometry>
			<origin rpy="-1.57075 -1.57075 0"/>
		</collision>
		<inertial>
			<origin rpy="-1.57075 -1.57075 0"/>
			<mass value="0.3"/>
			<inertia ixx="0.4" ixy="0" ixz="0" iyy="0.4" iyz="0.0" izz="0.2"/>
		</inertial>
	</link>
	<joint name="cylinder_right_15_to_belt" type="revolute">
		<parent link="conveyor_belt_right_foremost_link"/>
		<child link="cylinder_right_15"/>
		<axis xyz="0 1 0"/>
		<origin xyz="-0.405 0.0 0.005"/>
		<limit effort="100" lower="-100" upper="100" velocity="100"/>
	</joint>
	<link name="cylinder_right_16">
		<visual>
			<geometry>
				<cylinder length="0.05" radius="0.003"/>
			</geometry>
			<origin rpy="-1.57075 -1.57075 0"/>
			<material name="black"/>
		</visual>
		<collision>
			<geometry>
				<cylinder length="0.05" radius="0.003"/>
			</geometry>
			<origin rpy="-1.57075 -1.57075 0"/>
		</collision>
		<inertial>
			<origin rpy="-1.57075 -1.57075 0"/>
			<mass value="0.3"/>
			<inertia ixx="0.4" ixy="0" ixz="0" iyy="0.4" iyz="0.0" izz="0.2"/>
		</inertial>
	</link>
	<joint name="cylinder_right_16_to_belt" type="revolute">
		<parent link="conveyor_belt_right_foremost_link"/>
		<child link="cylinder_right_16"/>
		<axis xyz="0 1 0"/>
		<origin xyz="-0.38 0.0 0.005"/>
		<limit effort="100" lower="-100" upper="100" velocity="100"/>
	</joint>
	<link name="cylinder_right_17">
		<visual>
			<geometry>
				<cylinder length="0.05" radius="0.003"/>
			</geometry>
			<origin rpy="-1.57075 -1.57075 0"/>
			<material name="black"/>
		</visual>
		<collision>
			<geometry>
				<cylinder length="0.05" radius="0.003"/>
			</geometry>
			<origin rpy="-1.57075 -1.57075 0"/>
		</collision>
		<inertial>
			<origin rpy="-1.57075 -1.57075 0"/>
			<mass value="0.3"/>
			<inertia ixx="0.4" ixy="0" ixz="0" iyy="0.4" iyz="0.0" izz="0.2"/>
		</inertial>
	</link>
	<joint name="cylinder_right_17_to_belt" type="revolute">
		<parent link="conveyor_belt_right_foremost_link"/>
		<child link="cylinder_right_17"/>
		<axis xyz="0 1 0"/>
		<origin xyz="-0.355 0.0 0.005"/>
		<limit effort="100" lower="-100" upper="100" velocity="100"/>
	</joint>
	<link name="cylinder_right_18">
		<visual>
			<geometry>
				<cylinder length="0.05" radius="0.003"/>
			</geometry>
			<origin rpy="-1.57075 -1.57075 0"/>
			<material name="black"/>
		</visual>
		<collision>
			<geometry>
				<cylinder length="0.05" radius="0.003"/>
			</geometry>
			<origin rpy="-1.57075 -1.57075 0"/>
		</collision>
		<inertial>
			<origin rpy="-1.57075 -1.57075 0"/>
			<mass value="0.3"/>
			<inertia ixx="0.4" ixy="0" ixz="0" iyy="0.4" iyz="0.0" izz="0.2"/>
		</inertial>
	</link>
	<joint name="cylinder_right_18_to_belt" type="revolute">
		<parent link="conveyor_belt_right_foremost_link"/>
		<child link="cylinder_right_18"/>
		<axis xyz="0 1 0"/>
		<origin xyz="-0.33 0.0 0.005"/>
		<limit effort="100" lower="-100" upper="100" velocity="100"/>
	</joint>
	<link name="cylinder_right_19">
		<visual>
			<geometry>
				<cylinder length="0.05" radius="0.003"/>
			</geometry>
			<origin rpy="-1.57075 -1.57075 0"/>
			<material name="black"/>
		</visual>
		<collision>
			<geometry>
				<cylinder length="0.05" radius="0.003"/>
			</geometry>
			<origin rpy="-1.57075 -1.57075 0"/>
		</collision>
		<inertial>
			<origin rpy="-1.57075 -1.57075 0"/>
			<mass value="0.3"/>
			<inertia ixx="0.4" ixy="0" ixz="0" iyy="0.4" iyz="0.0" izz="0.2"/>
		</inertial>
	</link>
	<joint name="cylinder_right_19_to_belt" type="revolute">
		<parent link="conveyor_belt_right_foremost_link"/>
		<child link="cylinder_right_19"/>
		<axis xyz="0 1 0"/>
		<origin xyz="-0.305 0.0 0.005"/>
		<limit effort="100" lower="-100" upper="100" velocity="100"/>
	</joint>
	<link name="cylinder_right_20">
		<visual>
			<geometry>
				<cylinder length="0.05" radius="0.003"/>
			</geometry>
			<origin rpy="-1.57075 -1.57075 0"/>
			<material name="black"/>
		</visual>
		<collision>
			<geometry>
				<cylinder length="0.05" radius="0.003"/>
			</geometry>
			<origin rpy="-1.57075 -1.57075 0"/>
		</collision>
		<inertial>
			<origin rpy="-1.57075 -1.57075 0"/>
			<mass value="0.3"/>
			<inertia ixx="0.4" ixy="0" ixz="0" iyy="0.4" iyz="0.0" izz="0.2"/>
		</inertial>
	</link>
	<joint name="cylinder_right_20_to_belt" type="revolute">
		<parent link="conveyor_belt_right_foremost_link"/>
		<child link="cylinder_right_20"/>
		<axis xyz="0 1 0"/>
		<origin xyz="-0.28 0.0 0.005"/>
		<limit effort="100" lower="-100" upper="100" velocity="100"/>
	</joint>
	<link name="cylinder_right_21">
		<visual>
			<geometry>
				<cylinder length="0.05" radius="0.003"/>
			</geometry>
			<origin rpy="-1.57075 -1.57075 0"/>
			<material name="black"/>
		</visual>
		<collision>
			<geometry>
				<cylinder length="0.05" radius="0.003"/>
			</geometry>
			<origin rpy="-1.57075 -1.57075 0"/>
		</collision>
		<inertial>
			<origin rpy="-1.57075 -1.57075 0"/>
			<mass value="0.3"/>
			<inertia ixx="0.4" ixy="0" ixz="0" iyy="0.4" iyz="0.0" izz="0.2"/>
		</inertial>
	</link>
	<joint name="cylinder_right_21_to_belt" type="revolute">
		<parent link="conveyor_belt_right_foremost_link"/>
		<child link="cylinder_right_21"/>
		<axis xyz="0 1 0"/>
		<origin xyz="-0.255 0.0 0.005"/>
		<limit effort="100" lower="-100" upper="100" velocity="100"/>
	</joint>
	<link name="cylinder_right_22">
		<visual>
			<geometry>
				<cylinder length="0.05" radius="0.003"/>
			</geometry>
			<origin rpy="-1.57075 -1.57075 0"/>
			<material name="black"/>
		</visual>
		<collision>
			<geometry>
				<cylinder length="0.05" radius="0.003"/>
			</geometry>
			<origin rpy="-1.57075 -1.57075 0"/>
		</collision>
		<inertial>
			<origin rpy="-1.57075 -1.57075 0"/>
			<mass value="0.3"/>
			<inertia ixx="0.4" ixy="0" ixz="0" iyy="0.4" iyz="0.0" izz="0.2"/>
		</inertial>
	</link>
	<joint name="cylinder_right_22_to_belt" type="revolute">
		<parent link="conveyor_belt_right_foremost_link"/>
		<child link="cylinder_right_22"/>
		<axis xyz="0 1 0"/>
		<origin xyz="-0.22999999999999998 0.0 0.005"/>
		<limit effort="100" lower="-100" upper="100" velocity="100"/>
	</joint>
	<link name="cylinder_right_23">
		<visual>
			<geometry>
				<cylinder length="0.05" radius="0.003"/>
			</geometry>
			<origin rpy="-1.57075 -1.57075 0"/>
			<material name="black"/>
		</visual>
		<collision>
			<geometry>
				<cylinder length="0.05" radius="0.003"/>
			</geometry>
			<origin rpy="-1.57075 -1.57075 0"/>
		</collision>
		<inertial>
			<origin rpy="-1.57075 -1.57075 0"/>
			<mass value="0.3"/>
			<inertia ixx="0.4" ixy="0" ixz="0" iyy="0.4" iyz="0.0" izz="0.2"/>
		</inertial>
	</link>
	<joint name="cylinder_right_23_to_belt" type="revolute">
		<parent link="conveyor_belt_right_foremost_link"/>
		<child link="cylinder_right_23"/>
		<axis xyz="0 1 0"/>
		<origin xyz="-0.20499999999999996 0.0 0.005"/>
		<limit effort="100" lower="-100" upper="100" velocity="100"/>
	</joint>
	<link name="cylinder_right_24">
		<visual>
			<geometry>
				<cylinder length="0.05" radius="0.003"/>
			</geometry>
			<origin rpy="-1.57075 -1.57075 0"/>
			<material name="black"/>
		</visual>
		<collision>
			<geometry>
				<cylinder length="0.05" radius="0.003"/>
			</geometry>
			<origin rpy="-1.57075 -1.57075 0"/>
		</collision>
		<inertial>
			<origin rpy="-1.57075 -1.57075 0"/>
			<mass value="0.3"/>
			<inertia ixx="0.4" ixy="0" ixz="0" iyy="0.4" iyz="0.0" izz="0.2"/>
		</inertial>
	</link>
	<joint name="cylinder_right_24_to_belt" type="revolute">
		<parent link="conveyor_belt_right_foremost_link"/>
		<child link="cylinder_right_24"/>
		<axis xyz="0 1 0"/>
		<origin xyz="-0.17999999999999994 0.0 0.005"/>
		<limit effort="100" lower="-100" upper="100" velocity="100"/>
	</joint>
	<link name="cylinder_right_25">
		<visual>
			<geometry>
				<cylinder length="0.05" radius="0.003"/>
			</geometry>
			<origin rpy="-1.57075 -1.57075 0"/>
			<material name="black"/>
		</visual>
		<collision>
			<geometry>
				<cylinder length="0.05" radius="0.003"/>
			</geometry>
			<origin rpy="-1.57075 -1.57075 0"/>
		</collision>
		<inertial>
			<origin rpy="-1.57075 -1.57075 0"/>
			<mass value="0.3"/>
			<inertia ixx="0.4" ixy="0" ixz="0" iyy="0.4" iyz="0.0" izz="0.2"/>
		</inertial>
	</link>
	<joint name="cylinder_right_25_to_belt" type="revolute">
		<parent link="conveyor_belt_right_foremost_link"/>
		<child link="cylinder_right_25"/>
		<axis xyz="0 1 0"/>
		<origin xyz="-0.15500000000000003 0.0 0.005"/>
		<limit effort="100" lower="-100" upper="100" velocity="100"/>
	</joint>
	<link name="cylinder_right_26">
		<visual>
			<geometry>
				<cylinder length="0.05" radius="0.003"/>
			</geometry>
			<origin rpy="-1.57075 -1.57075 0"/>
			<material name="black"/>
		</visual>
		<collision>
			<geometry>
				<cylinder length="0.05" radius="0.003"/>
			</geometry>
			<origin rpy="-1.57075 -1.57075 0"/>
		</collision>
		<inertial>
			<origin rpy="-1.57075 -1.57075 0"/>
			<mass value="0.3"/>
			<inertia ixx="0.4" ixy="0" ixz="0" iyy="0.4" iyz="0.0" izz="0.2"/>
		</inertial>
	</link>
	<joint name="cylinder_right_26_to_belt" type="revolute">
		<parent link="conveyor_belt_right_foremost_link"/>
		<child link="cylinder_right_26"/>
		<axis xyz="0 1 0"/>
		<origin xyz="-0.13 0.0 0.005"/>
		<limit effort="100" lower="-100" upper="100" velocity="100"/>
	</joint>
	<link name="cylinder_right_27">
		<visual>
			<geometry>
				<cylinder length="0.05" radius="0.003"/>
			</geometry>
			<origin rpy="-1.57075 -1.57075 0"/>
			<material name="black"/>
		</visual>
		<collision>
			<geometry>
				<cylinder length="0.05" radius="0.003"/>
			</geometry>
			<origin rpy="-1.57075 -1.57075 0"/>
		</collision>
		<inertial>
			<origin rpy="-1.57075 -1.57075 0"/>
			<mass value="0.3"/>
			<inertia ixx="0.4" ixy="0" ixz="0" iyy="0.4" iyz="0.0" izz="0.2"/>
		</inertial>
	</link>
	<joint name="cylinder_right_27_to_belt" type="revolute">
		<parent link="conveyor_belt_right_foremost_link"/>
		<child link="cylinder_right_27"/>
		<axis xyz="0 1 0"/>
		<origin xyz="-0.10499999999999998 0.0 0.005"/>
		<limit effort="100" lower="-100" upper="100" velocity="100"/>
	</joint>
	<link name="cylinder_right_28">
		<visual>
			<geometry>
				<cylinder length="0.05" radius="0.003"/>
			</geometry>
			<origin rpy="-1.57075 -1.57075 0"/>
			<material name="black"/>
		</visual>
		<collision>
			<geometry>
				<cylinder length="0.05" radius="0.003"/>
			</geometry>
			<origin rpy="-1.57075 -1.57075 0"/>
		</collision>
		<inertial>
			<origin rpy="-1.57075 -1.57075 0"/>
			<mass value="0.3"/>
			<inertia ixx="0.4" ixy="0" ixz="0" iyy="0.4" iyz="0.0" izz="0.2"/>
		</inertial>
	</link>
	<joint name="cylinder_right_28_to_belt" type="revolute">
		<parent link="conveyor_belt_right_foremost_link"/>
		<child link="cylinder_right_28"/>
		<axis xyz="0 1 0"/>
		<origin xyz="-0.07999999999999996 0.0 0.005"/>
		<limit effort="100" lower="-100" upper="100" velocity="100"/>
	</joint>
	<link name="cylinder_right_29">
		<visual>
			<geometry>
				<cylinder length="0.05" radius="0.003"/>
			</geometry>
			<origin rpy="-1.57075 -1.57075 0"/>
			<material name="black"/>
		</visual>
		<collision>
			<geometry>
				<cylinder length="0.05" radius="0.003"/>
			</geometry>
			<origin rpy="-1.57075 -1.57075 0"/>
		</collision>
		<inertial>
			<origin rpy="-1.57075 -1.57075 0"/>
			<mass value="0.3"/>
			<inertia ixx="0.4" ixy="0" ixz="0" iyy="0.4" iyz="0.0" izz="0.2"/>
		</inertial>
	</link>
	<joint name="cylinder_right_29_to_belt" type="revolute">
		<parent link="conveyor_belt_right_foremost_link"/>
		<child link="cylinder_right_29"/>
		<axis xyz="0 1 0"/>
		<origin xyz="-0.05499999999999994 0.0 0.005"/>
		<limit effort="100" lower="-100" upper="100" velocity="100"/>
	</joint>
	<link name="cylinder_right_30">
		<visual>
			<geometry>
				<cylinder length="0.05" radius="0.003"/>
			</geometry>
			<origin rpy="-1.57075 -1.57075 0"/>
			<material name="black"/>
		</visual>
		<collision>
			<geometry>
				<cylinder length="0.05" radius="0.003"/>
			</geometry>
			<origin rpy="-1.57075 -1.57075 0"/>
		</collision>
		<inertial>
			<origin rpy="-1.57075 -1.57075 0"/>
			<mass value="0.3"/>
			<inertia ixx="0.4" ixy="0" ixz="0" iyy="0.4" iyz="0.0" izz="0.2"/>
		</inertial>
	</link>
	<joint name="cylinder_right_30_to_belt" type="revolute">
		<parent link="conveyor_belt_right_foremost_link"/>
		<child link="cylinder_right_30"/>
		<axis xyz="0 1 0"/>
		<origin xyz="-0.030000000000000027 0.0 0.005"/>
		<limit effort="100" lower="-100" upper="100" velocity="100"/>
	</joint>
	<link name="cylinder_right_31">
		<visual>
			<geometry>
				<cylinder length="0.05" radius="0.003"/>
			</geometry>
			<origin rpy="-1.57075 -1.57075 0"/>
			<material name="black"/>
		</visual>
		<collision>
			<geometry>
				<cylinder length="0.05" radius="0.003"/>
			</geometry>
			<origin rpy="-1.57075 -1.57075 0"/>
		</collision>
		<inertial>
			<origin rpy="-1.57075 -1.57075 0"/>
			<mass value="0.3"/>
			<inertia ixx="0.4" ixy="0" ixz="0" iyy="0.4" iyz="0.0" izz="0.2"/>
		</inertial>
	</link>
	<joint name="cylinder_right_31_to_belt" type="revolute">
		<parent link="conveyor_belt_right_foremost_link"/>
		<child link="cylinder_right_31"/>
		<axis xyz="0 1 0"/>
		<origin xyz="-0.0043 0.0 -0.00"/>
		<limit effort="100" lower="-100" upper="100" velocity="100"/>
	</joint>

</robot>

