<?xml version="1.0" encoding="utf-8"?>
<!-- =================================================================================== -->
<!-- |    This document was autogenerated by xacro from ../robots/v0variants/xacros/v0_4l_20.xacro | -->
<!-- |    EDITING THIS FILE BY HAND IS NOT RECOMMENDED                                 | -->
<!-- =================================================================================== -->
<robot name="v0">
  <material name="grey">
    <color rgba="0.5 0.5 0.5 1"/>
  </material>
  <material name="white">
    <color rgba="1 1 1 1"/>
  </material>
  <material name="yellow">
    <color rgba="0.91 0.7 0.14 1"/>
  </material>
  <material name="red">
    <color rgba="0.71 0.14 0.14 1"/>
  </material>
  <link name="body">
    <visual>
      <geometry>
        <box size="1.3 0.3 0.1"/>
      </geometry>
      <material name="grey"/>
      <origin rpy="0 0 0" xyz="0 0 0.7"/>
    </visual>
    <collision>
      <geometry>
        <box size="1.3 0.3 0.1"/>
      </geometry>
      <origin rpy="0 0 0" xyz="0 0 0.7"/>
    </collision>
    <inertial>
      <mass value="99.84"/>
      <inertia ixx="0.832" ixy="0.0" ixz="0.0" iyy="14.144" iyz="0.0" izz="14.8096"/>
    </inertial>
  </link>
  <link name="l1_segment_1">
    <visual>
      <geometry>
        <box size="0.1 0.1 0.2"/>
      </geometry>
      <material name="white"/>
      <origin rpy="0 0 0" xyz="0 0 0.1"/>
    </visual>
    <collision>
      <geometry>
        <box size="0.1 0.1 0.2"/>
      </geometry>
      <origin rpy="0 0 0" xyz="0 0 0.1"/>
    </collision>
    <inertial>
      <mass value="5.12"/>
      <inertia ixx="0.0213333333333" ixy="0.0" ixz="0.0" iyy="0.0213333333333" iyz="0.0" izz="0.00853333333333"/>
    </inertial>
  </link>
  <joint name="l1_base_to_joint_1" type="fixed">
    <parent link="body"/>
    <child link="l1_segment_1"/>
    <origin rpy="0 0 0" xyz="-0.5251355048699647 0.1 0.75"/>
  </joint>
  <link name="l1_segment_2_HIP">
    <visual>
      <geometry>
        <box size="0.1 0.6 0.1"/>
      </geometry>
      <material name="yellow"/>
      <origin rpy="0 0 0" xyz="0 0.25 0"/>
    </visual>
    <collision>
      <geometry>
        <box size="0.1 0.6 0.1"/>
      </geometry>
      <origin rpy="0 0 0" xyz="0 0.25 0"/>
    </collision>
    <inertial>
      <mass value="15.36"/>
      <inertia ixx="0.4736" ixy="0.0" ixz="0.0" iyy="0.0256" iyz="0.0" izz="0.4736"/>
    </inertial>
  </link>
  <joint name="l1_joint_1_to_2" type="revolute">
    <parent link="l1_segment_1"/>
    <child link="l1_segment_2_HIP"/>
    <origin rpy="0 0 0" xyz="0 0 0.25"/>
    <axis xyz="0.0 0.0 1.0"/>
    <limit effort="2048" lower="-1.2" upper="1.2" velocity="20"/>
  </joint>
  <link name="l1_segment_3_THIGH">
    <visual>
      <geometry>
        <box size="0.1 0.1 0.7"/>
      </geometry>
      <material name="red"/>
      <origin rpy="0 0 0" xyz="0 0 -0.3"/>
    </visual>
    <collision>
      <geometry>
        <box size="0.1 0.1 0.7"/>
      </geometry>
      <origin rpy="0 0 0" xyz="0 0 -0.3"/>
    </collision>
    <inertial>
      <mass value="17.92"/>
      <inertia ixx="0.746666666667" ixy="0.0" ixz="0.0" iyy="0.746666666667" iyz="0.0" izz="0.0298666666667"/>
    </inertial>
  </link>
  <joint name="l1_joint_2_to_3" type="revolute">
    <parent link="l1_segment_2_HIP"/>
    <child link="l1_segment_3_THIGH"/>
    <origin rpy="0 0 0" xyz="-0.1 0.5 0"/>
    <axis xyz="1.0 0.0 0.0"/>
    <limit effort="2048" lower="-0.2" upper="0.75" velocity="20"/>
  </joint>
  <link name="l1_segment_4_FOOT">
    <visual>
      <geometry>
        <box size="0.1 0.1 0.4"/>
      </geometry>
      <material name="yellow"/>
      <origin rpy="0 0 0" xyz="0 0 -0.2"/>
    </visual>
    <collision>
      <geometry>
        <box size="0.1 0.1 0.4"/>
      </geometry>
      <origin rpy="0 0 0" xyz="0 0 -0.2"/>
    </collision>
    <inertial>
      <mass value="10.24"/>
      <inertia ixx="0.145066666667" ixy="0.0" ixz="0.0" iyy="0.145066666667" iyz="0.0" izz="0.0170666666667"/>
    </inertial>
  </link>
  <joint name="l1_joint_3_to_4_FOOT" type="revolute">
    <parent link="l1_segment_3_THIGH"/>
    <child link="l1_segment_4_FOOT"/>
    <origin rpy="0 0 0" xyz="0.1 0 -0.55"/>
    <axis xyz="1.0 0.0 0.0"/>
    <limit effort="2048" lower="-0.2" upper="0.5" velocity="20"/>
  </joint>
  <link name="r2_segment_1">
    <visual>
      <geometry>
        <box size="0.1 0.1 0.2"/>
      </geometry>
      <material name="white"/>
      <origin rpy="0 0 0" xyz="0 0 0.1"/>
    </visual>
    <collision>
      <geometry>
        <box size="0.1 0.1 0.2"/>
      </geometry>
      <origin rpy="0 0 0" xyz="0 0 0.1"/>
    </collision>
    <inertial>
      <mass value="5.12"/>
      <inertia ixx="0.0213333333333" ixy="0.0" ixz="0.0" iyy="0.0213333333333" iyz="0.0" izz="0.00853333333333"/>
    </inertial>
  </link>
  <joint name="r2_base_to_joint_1" type="fixed">
    <parent link="body"/>
    <child link="r2_segment_1"/>
    <origin rpy="0 0 0" xyz="-0.24617366687046574 0.1 0.75"/>
  </joint>
  <link name="r2_segment_2_HIP">
    <visual>
      <geometry>
        <box size="0.1 0.6 0.1"/>
      </geometry>
      <material name="yellow"/>
      <origin rpy="0 0 0" xyz="0 -0.25 0"/>
    </visual>
    <collision>
      <geometry>
        <box size="0.1 0.6 0.1"/>
      </geometry>
      <origin rpy="0 0 0" xyz="0 -0.25 0"/>
    </collision>
    <inertial>
      <mass value="15.36"/>
      <inertia ixx="0.4736" ixy="0.0" ixz="0.0" iyy="0.0256" iyz="0.0" izz="0.4736"/>
    </inertial>
  </link>
  <joint name="r2_joint_1_to_2" type="revolute">
    <parent link="r2_segment_1"/>
    <child link="r2_segment_2_HIP"/>
    <origin rpy="0 0 0" xyz="0 0 0.25"/>
    <axis xyz="0.0 0.0 1.0"/>
    <limit effort="2048" lower="-1.2" upper="1.2" velocity="20"/>
  </joint>
  <link name="r2_segment_3_THIGH">
    <visual>
      <geometry>
        <box size="0.1 0.1 0.7"/>
      </geometry>
      <material name="red"/>
      <origin rpy="0 0 0" xyz="0 0 -0.3"/>
    </visual>
    <collision>
      <geometry>
        <box size="0.1 0.1 0.7"/>
      </geometry>
      <origin rpy="0 0 0" xyz="0 0 -0.3"/>
    </collision>
    <inertial>
      <mass value="17.92"/>
      <inertia ixx="0.746666666667" ixy="0.0" ixz="0.0" iyy="0.746666666667" iyz="0.0" izz="0.0298666666667"/>
    </inertial>
  </link>
  <joint name="r2_joint_2_to_3" type="revolute">
    <parent link="r2_segment_2_HIP"/>
    <child link="r2_segment_3_THIGH"/>
    <origin rpy="0 0 0" xyz="-0.1 -0.5 0"/>
    <axis xyz="1.0 0.0 0.0"/>
    <limit effort="2048" lower="-0.75" upper="0.2" velocity="20"/>
  </joint>
  <link name="r2_segment_4_FOOT">
    <visual>
      <geometry>
        <box size="0.1 0.1 0.4"/>
      </geometry>
      <material name="yellow"/>
      <origin rpy="0 0 0" xyz="0 0 -0.2"/>
    </visual>
    <collision>
      <geometry>
        <box size="0.1 0.1 0.4"/>
      </geometry>
      <origin rpy="0 0 0" xyz="0 0 -0.2"/>
    </collision>
    <inertial>
      <mass value="10.24"/>
      <inertia ixx="0.145066666667" ixy="0.0" ixz="0.0" iyy="0.145066666667" iyz="0.0" izz="0.0170666666667"/>
    </inertial>
  </link>
  <joint name="r2_joint_3_to_4_FOOT" type="revolute">
    <parent link="r2_segment_3_THIGH"/>
    <child link="r2_segment_4_FOOT"/>
    <origin rpy="0 0 0" xyz="0.1 0 -0.55"/>
    <axis xyz="1.0 0.0 0.0"/>
    <limit effort="2048" lower="-0.5" upper="0.2" velocity="20"/>
  </joint>
  <link name="l3_segment_1">
    <visual>
      <geometry>
        <box size="0.1 0.1 0.2"/>
      </geometry>
      <material name="white"/>
      <origin rpy="0 0 0" xyz="0 0 0.1"/>
    </visual>
    <collision>
      <geometry>
        <box size="0.1 0.1 0.2"/>
      </geometry>
      <origin rpy="0 0 0" xyz="0 0 0.1"/>
    </collision>
    <inertial>
      <mass value="5.12"/>
      <inertia ixx="0.0213333333333" ixy="0.0" ixz="0.0" iyy="0.0213333333333" iyz="0.0" izz="0.00853333333333"/>
    </inertial>
  </link>
  <joint name="l3_base_to_joint_1" type="fixed">
    <parent link="body"/>
    <child link="l3_segment_1"/>
    <origin rpy="0 0 0" xyz="0.015030651274069662 0.1 0.75"/>
  </joint>
  <link name="l3_segment_2_HIP">
    <visual>
      <geometry>
        <box size="0.1 0.6 0.1"/>
      </geometry>
      <material name="yellow"/>
      <origin rpy="0 0 0" xyz="0 0.25 0"/>
    </visual>
    <collision>
      <geometry>
        <box size="0.1 0.6 0.1"/>
      </geometry>
      <origin rpy="0 0 0" xyz="0 0.25 0"/>
    </collision>
    <inertial>
      <mass value="15.36"/>
      <inertia ixx="0.4736" ixy="0.0" ixz="0.0" iyy="0.0256" iyz="0.0" izz="0.4736"/>
    </inertial>
  </link>
  <joint name="l3_joint_1_to_2" type="revolute">
    <parent link="l3_segment_1"/>
    <child link="l3_segment_2_HIP"/>
    <origin rpy="0 0 0" xyz="0 0 0.25"/>
    <axis xyz="0.0 0.0 1.0"/>
    <limit effort="2048" lower="-1.2" upper="1.2" velocity="20"/>
  </joint>
  <link name="l3_segment_3_THIGH">
    <visual>
      <geometry>
        <box size="0.1 0.1 0.7"/>
      </geometry>
      <material name="red"/>
      <origin rpy="0 0 0" xyz="0 0 -0.3"/>
    </visual>
    <collision>
      <geometry>
        <box size="0.1 0.1 0.7"/>
      </geometry>
      <origin rpy="0 0 0" xyz="0 0 -0.3"/>
    </collision>
    <inertial>
      <mass value="17.92"/>
      <inertia ixx="0.746666666667" ixy="0.0" ixz="0.0" iyy="0.746666666667" iyz="0.0" izz="0.0298666666667"/>
    </inertial>
  </link>
  <joint name="l3_joint_2_to_3" type="revolute">
    <parent link="l3_segment_2_HIP"/>
    <child link="l3_segment_3_THIGH"/>
    <origin rpy="0 0 0" xyz="-0.1 0.5 0"/>
    <axis xyz="1.0 0.0 0.0"/>
    <limit effort="2048" lower="-0.2" upper="0.75" velocity="20"/>
  </joint>
  <link name="l3_segment_4_FOOT">
    <visual>
      <geometry>
        <box size="0.1 0.1 0.4"/>
      </geometry>
      <material name="yellow"/>
      <origin rpy="0 0 0" xyz="0 0 -0.2"/>
    </visual>
    <collision>
      <geometry>
        <box size="0.1 0.1 0.4"/>
      </geometry>
      <origin rpy="0 0 0" xyz="0 0 -0.2"/>
    </collision>
    <inertial>
      <mass value="10.24"/>
      <inertia ixx="0.145066666667" ixy="0.0" ixz="0.0" iyy="0.145066666667" iyz="0.0" izz="0.0170666666667"/>
    </inertial>
  </link>
  <joint name="l3_joint_3_to_4_FOOT" type="revolute">
    <parent link="l3_segment_3_THIGH"/>
    <child link="l3_segment_4_FOOT"/>
    <origin rpy="0 0 0" xyz="0.1 0 -0.55"/>
    <axis xyz="1.0 0.0 0.0"/>
    <limit effort="2048" lower="-0.2" upper="0.5" velocity="20"/>
  </joint>
  <link name="r4_segment_1">
    <visual>
      <geometry>
        <box size="0.1 0.1 0.2"/>
      </geometry>
      <material name="white"/>
      <origin rpy="0 0 0" xyz="0 0 0.1"/>
    </visual>
    <collision>
      <geometry>
        <box size="0.1 0.1 0.2"/>
      </geometry>
      <origin rpy="0 0 0" xyz="0 0 0.1"/>
    </collision>
    <inertial>
      <mass value="5.12"/>
      <inertia ixx="0.0213333333333" ixy="0.0" ixz="0.0" iyy="0.0213333333333" iyz="0.0" izz="0.00853333333333"/>
    </inertial>
  </link>
  <joint name="r4_base_to_joint_1" type="fixed">
    <parent link="body"/>
    <child link="r4_segment_1"/>
    <origin rpy="0 0 0" xyz="0.18615929074399076 0.1 0.75"/>
  </joint>
  <link name="r4_segment_2_HIP">
    <visual>
      <geometry>
        <box size="0.1 0.6 0.1"/>
      </geometry>
      <material name="yellow"/>
      <origin rpy="0 0 0" xyz="0 -0.25 0"/>
    </visual>
    <collision>
      <geometry>
        <box size="0.1 0.6 0.1"/>
      </geometry>
      <origin rpy="0 0 0" xyz="0 -0.25 0"/>
    </collision>
    <inertial>
      <mass value="15.36"/>
      <inertia ixx="0.4736" ixy="0.0" ixz="0.0" iyy="0.0256" iyz="0.0" izz="0.4736"/>
    </inertial>
  </link>
  <joint name="r4_joint_1_to_2" type="revolute">
    <parent link="r4_segment_1"/>
    <child link="r4_segment_2_HIP"/>
    <origin rpy="0 0 0" xyz="0 0 0.25"/>
    <axis xyz="0.0 0.0 1.0"/>
    <limit effort="2048" lower="-1.2" upper="1.2" velocity="20"/>
  </joint>
  <link name="r4_segment_3_THIGH">
    <visual>
      <geometry>
        <box size="0.1 0.1 0.7"/>
      </geometry>
      <material name="red"/>
      <origin rpy="0 0 0" xyz="0 0 -0.3"/>
    </visual>
    <collision>
      <geometry>
        <box size="0.1 0.1 0.7"/>
      </geometry>
      <origin rpy="0 0 0" xyz="0 0 -0.3"/>
    </collision>
    <inertial>
      <mass value="17.92"/>
      <inertia ixx="0.746666666667" ixy="0.0" ixz="0.0" iyy="0.746666666667" iyz="0.0" izz="0.0298666666667"/>
    </inertial>
  </link>
  <joint name="r4_joint_2_to_3" type="revolute">
    <parent link="r4_segment_2_HIP"/>
    <child link="r4_segment_3_THIGH"/>
    <origin rpy="0 0 0" xyz="-0.1 -0.5 0"/>
    <axis xyz="1.0 0.0 0.0"/>
    <limit effort="2048" lower="-0.75" upper="0.2" velocity="20"/>
  </joint>
  <link name="r4_segment_4_FOOT">
    <visual>
      <geometry>
        <box size="0.1 0.1 0.4"/>
      </geometry>
      <material name="yellow"/>
      <origin rpy="0 0 0" xyz="0 0 -0.2"/>
    </visual>
    <collision>
      <geometry>
        <box size="0.1 0.1 0.4"/>
      </geometry>
      <origin rpy="0 0 0" xyz="0 0 -0.2"/>
    </collision>
    <inertial>
      <mass value="10.24"/>
      <inertia ixx="0.145066666667" ixy="0.0" ixz="0.0" iyy="0.145066666667" iyz="0.0" izz="0.0170666666667"/>
    </inertial>
  </link>
  <joint name="r4_joint_3_to_4_FOOT" type="revolute">
    <parent link="r4_segment_3_THIGH"/>
    <child link="r4_segment_4_FOOT"/>
    <origin rpy="0 0 0" xyz="0.1 0 -0.55"/>
    <axis xyz="1.0 0.0 0.0"/>
    <limit effort="2048" lower="-0.5" upper="0.2" velocity="20"/>
  </joint>
</robot>

