<robot
  name="gripper_rotate"
  xmlns:xacro="http://ros.org/wiki/xacro">

  <!-- extend xacro functionality with macros of urdf_utils -->
  <xacro:include filename="$(find urdf_utils)/urdf/properties/defaults.xacro" />
  <xacro:include filename="$(find urdf_utils)/urdf/origin.xacro" />
  <xacro:include filename="$(find urdf_utils)/urdf/limit.xacro" />
  <xacro:include filename="$(find urdf_utils)/urdf/parent.xacro" />

  <!-- Load default joint data from yaml files in config directory. -->
  <!-- If additional data is present in cman, use it to overwrite the default one. -->
  <xacro:property
      name="cman_joints"
      value="${load_cman('conveyor_gripper_1_0_description', 'conveyor_gripper_1_0_description.yaml', '')}" />


  <xacro:if value="${standalone}">
    <link
      name="gripper_carrier_frame_link"/>
  </xacro:if>

  <joint
    name="gripper_rotate"
    type="revolute">
    <origin
      xyz="0.42 -0.378 -0.1425"
      rpy="0 0 ${pi}" />
    <parent
      link="gripper_carrier_frame_link" />
    <child
      link="gripper_base_link" />
    <axis
      xyz="0 0 1" />
    <xacro:limit_from_config config="${cman_joints}" joint_name="gripper_rotate" />
  </joint>

</robot>