<?xml version="1.0" ?>
<!-- =================================================================================== -->
<!-- |    This document was autogenerated by xacro from v0.urdf.xacro                  | -->
<!-- |    EDITING THIS FILE BY HAND IS NOT RECOMMENDED                                 | -->
<!-- =================================================================================== -->
<robot name="v0">
  <material name="grey">
    <color rgba="0.5 0.5 0.5 1"/>
  </material>
  <material name="white">
    <color rgba="1 1 1 1"/>
  </material>
  <material name="yellow">
    <color rgba="0.91 0.7 0.14 1"/>
  </material>
  <material name="red">
    <color rgba="0.71 0.14 0.14 1"/>
  </material>
  <link name="body">
    <visual>
      <geometry>
        <box size="1.3 0.3 0.1"/>
      </geometry>
      <material name="grey"/>
      <origin rpy="0 0 0" xyz="0 0 0.7"/>
    </visual>
    <collision>
      <geometry>
        <box size="1.3 0.3 0.1"/>
      </geometry>
      <origin rpy="0 0 0" xyz="0 0 0.7"/>
    </collision>
    <inertial>
      <mass value="99.84000000000002"/>
      <inertia ixx="0.8320000000000001" ixy="0.0" ixz="0.0" iyy="14.144000000000002" iyz="0.0" izz="14.809600000000003"/>
    </inertial>
  </link>
  <link name="l1_segment_1">
    <visual>
      <geometry>
        <box size="0.1 0.1 0.2"/>
      </geometry>
      <material name="white"/>
      <origin rpy="0 0 0" xyz="0 0 0.1"/>
    </visual>
    <collision>
      <geometry>
        <box size="0.1 0.1 0.2"/>
      </geometry>
      <origin rpy="0 0 0" xyz="0 0 0.1"/>
    </collision>
    <inertial>
      <mass value="5.120000000000001"/>
      <inertia ixx="0.021333333333333343" ixy="0.0" ixz="0.0" iyy="0.021333333333333343" iyz="0.0" izz="0.008533333333333337"/>
    </inertial>
  </link>
  <joint name="l1_base_to_joint_1" type="fixed">
    <parent link="body"/>
    <child link="l1_segment_1"/>
    <origin rpy="0 0 0" xyz="0.5 0.1 .75"/>
  </joint>
  <link name="l1_segment_2_HIP">
    <visual>
      <geometry>
        <box size="0.1 0.6 0.1"/>
      </geometry>
      <material name="yellow"/>
      <origin rpy="0 0 0" xyz="0 0.25 0"/>
    </visual>
    <collision>
      <geometry>
        <box size="0.1 0.6 0.1"/>
      </geometry>
      <origin rpy="0 0 0" xyz="0 0.25 0"/>
    </collision>
    <inertial>
      <mass value="15.36"/>
      <inertia ixx="0.4735999999999999" ixy="0.0" ixz="0.0" iyy="0.0256" iyz="0.0" izz="0.4735999999999999"/>
    </inertial>
  </link>
  <joint name="l1_joint_1_to_2" type="revolute">
    <parent link="l1_segment_1"/>
    <child link="l1_segment_2_HIP"/>
    <origin rpy="0 0 0" xyz="0 0 0.25"/>
    <axis xyz="0.0 0.0 1.0"/>
    <limit effort="2048" lower="-1.2" upper="1.2" velocity="15"/>
  </joint>
  <link name="l1_segment_3_THIGH">
    <visual>
      <geometry>
        <box size="0.1 0.1 0.7"/>
      </geometry>
      <material name="red"/>
      <origin rpy="0 0 0" xyz="0 0 -0.3"/>
    </visual>
    <collision>
      <geometry>
        <box size="0.1 0.1 0.7"/>
      </geometry>
      <origin rpy="0 0 0" xyz="0 0 -0.3"/>
    </collision>
    <inertial>
      <mass value="17.92"/>
      <inertia ixx="0.7466666666666666" ixy="0.0" ixz="0.0" iyy="0.7466666666666666" iyz="0.0" izz="0.029866666666666673"/>
    </inertial>
  </link>
  <joint name="l1_joint_2_to_3" type="revolute">
    <parent link="l1_segment_2_HIP"/>
    <child link="l1_segment_3_THIGH"/>
    <origin rpy="0 0 0" xyz="-0.1 0.5 0"/>
    <axis xyz="1.0 0.0 0.0"/>
    <limit effort="2048" lower="-0.2" upper="0.75" velocity="15"/>
  </joint>
  <link name="l1_segment_4_FOOT">
    <visual>
      <geometry>
        <box size="0.1 0.1 0.4"/>
      </geometry>
      <material name="yellow"/>
      <origin rpy="0 0 0" xyz="0 0 -0.2"/>
    </visual>
    <collision>
      <geometry>
        <box size="0.1 0.1 0.4"/>
      </geometry>
      <origin rpy="0 0 0" xyz="0 0 -0.2"/>
    </collision>
    <inertial>
      <mass value="10.240000000000002"/>
      <inertia ixx="0.14506666666666673" ixy="0.0" ixz="0.0" iyy="0.14506666666666673" iyz="0.0" izz="0.017066666666666674"/>
    </inertial>
  </link>
  <joint name="l1_joint_3_to_4_FOOT" type="revolute">
    <parent link="l1_segment_3_THIGH"/>
    <child link="l1_segment_4_FOOT"/>
    <origin rpy="0 0 0" xyz="0.1 0 -0.55"/>
    <axis xyz="1.0 0.0 0.0"/>
    <limit effort="2048" lower="-0.2" upper="0.5" velocity="9"/>
  </joint>
  <!-- <xacro:leg name="l2" reflect="1">
		<origin xyz="0 0.1 1.05" rpy="0 0 0" />
	</xacro:leg> -->
  <link name="l3_segment_1">
    <visual>
      <geometry>
        <box size="0.1 0.1 0.2"/>
      </geometry>
      <material name="white"/>
      <origin rpy="0 0 0" xyz="0 0 0.1"/>
    </visual>
    <collision>
      <geometry>
        <box size="0.1 0.1 0.2"/>
      </geometry>
      <origin rpy="0 0 0" xyz="0 0 0.1"/>
    </collision>
    <inertial>
      <mass value="5.120000000000001"/>
      <inertia ixx="0.021333333333333343" ixy="0.0" ixz="0.0" iyy="0.021333333333333343" iyz="0.0" izz="0.008533333333333337"/>
    </inertial>
  </link>
  <joint name="l3_base_to_joint_1" type="fixed">
    <parent link="body"/>
    <child link="l3_segment_1"/>
    <origin rpy="0 0 0" xyz="-0.5 0.1 .75"/>
  </joint>
  <link name="l3_segment_2_HIP">
    <visual>
      <geometry>
        <box size="0.1 0.6 0.1"/>
      </geometry>
      <material name="yellow"/>
      <origin rpy="0 0 0" xyz="0 0.25 0"/>
    </visual>
    <collision>
      <geometry>
        <box size="0.1 0.6 0.1"/>
      </geometry>
      <origin rpy="0 0 0" xyz="0 0.25 0"/>
    </collision>
    <inertial>
      <mass value="15.36"/>
      <inertia ixx="0.4735999999999999" ixy="0.0" ixz="0.0" iyy="0.0256" iyz="0.0" izz="0.4735999999999999"/>
    </inertial>
  </link>
  <joint name="l3_joint_1_to_2" type="revolute">
    <parent link="l3_segment_1"/>
    <child link="l3_segment_2_HIP"/>
    <origin rpy="0 0 0" xyz="0 0 0.25"/>
    <axis xyz="0.0 0.0 1.0"/>
    <limit effort="2048" lower="-1.2" upper="1.2" velocity="15"/>
  </joint>
  <link name="l3_segment_3_THIGH">
    <visual>
      <geometry>
        <box size="0.1 0.1 0.7"/>
      </geometry>
      <material name="red"/>
      <origin rpy="0 0 0" xyz="0 0 -0.3"/>
    </visual>
    <collision>
      <geometry>
        <box size="0.1 0.1 0.7"/>
      </geometry>
      <origin rpy="0 0 0" xyz="0 0 -0.3"/>
    </collision>
    <inertial>
      <mass value="17.92"/>
      <inertia ixx="0.7466666666666666" ixy="0.0" ixz="0.0" iyy="0.7466666666666666" iyz="0.0" izz="0.029866666666666673"/>
    </inertial>
  </link>
  <joint name="l3_joint_2_to_3" type="revolute">
    <parent link="l3_segment_2_HIP"/>
    <child link="l3_segment_3_THIGH"/>
    <origin rpy="0 0 0" xyz="-0.1 0.5 0"/>
    <axis xyz="1.0 0.0 0.0"/>
    <limit effort="2048" lower="-0.2" upper="0.75" velocity="15"/>
  </joint>
  <link name="l3_segment_4_FOOT">
    <visual>
      <geometry>
        <box size="0.1 0.1 0.4"/>
      </geometry>
      <material name="yellow"/>
      <origin rpy="0 0 0" xyz="0 0 -0.2"/>
    </visual>
    <collision>
      <geometry>
        <box size="0.1 0.1 0.4"/>
      </geometry>
      <origin rpy="0 0 0" xyz="0 0 -0.2"/>
    </collision>
    <inertial>
      <mass value="10.240000000000002"/>
      <inertia ixx="0.14506666666666673" ixy="0.0" ixz="0.0" iyy="0.14506666666666673" iyz="0.0" izz="0.017066666666666674"/>
    </inertial>
  </link>
  <joint name="l3_joint_3_to_4_FOOT" type="revolute">
    <parent link="l3_segment_3_THIGH"/>
    <child link="l3_segment_4_FOOT"/>
    <origin rpy="0 0 0" xyz="0.1 0 -0.55"/>
    <axis xyz="1.0 0.0 0.0"/>
    <limit effort="2048" lower="-0.2" upper="0.5" velocity="9"/>
  </joint>
  <link name="r1_segment_1">
    <visual>
      <geometry>
        <box size="0.1 0.1 0.2"/>
      </geometry>
      <material name="white"/>
      <origin rpy="0 0 0" xyz="0 0 0.1"/>
    </visual>
    <collision>
      <geometry>
        <box size="0.1 0.1 0.2"/>
      </geometry>
      <origin rpy="0 0 0" xyz="0 0 0.1"/>
    </collision>
    <inertial>
      <mass value="5.120000000000001"/>
      <inertia ixx="0.021333333333333343" ixy="0.0" ixz="0.0" iyy="0.021333333333333343" iyz="0.0" izz="0.008533333333333337"/>
    </inertial>
  </link>
  <joint name="r1_base_to_joint_1" type="fixed">
    <parent link="body"/>
    <child link="r1_segment_1"/>
    <origin rpy="0 0 0" xyz="0.5 -0.1 .75"/>
  </joint>
  <link name="r1_segment_2_HIP">
    <visual>
      <geometry>
        <box size="0.1 0.6 0.1"/>
      </geometry>
      <material name="yellow"/>
      <origin rpy="0 0 0" xyz="0 -0.25 0"/>
    </visual>
    <collision>
      <geometry>
        <box size="0.1 0.6 0.1"/>
      </geometry>
      <origin rpy="0 0 0" xyz="0 -0.25 0"/>
    </collision>
    <inertial>
      <mass value="15.36"/>
      <inertia ixx="0.4735999999999999" ixy="0.0" ixz="0.0" iyy="0.0256" iyz="0.0" izz="0.4735999999999999"/>
    </inertial>
  </link>
  <joint name="r1_joint_1_to_2" type="revolute">
    <parent link="r1_segment_1"/>
    <child link="r1_segment_2_HIP"/>
    <origin rpy="0 0 0" xyz="0 0 0.25"/>
    <axis xyz="0.0 0.0 1.0"/>
    <limit effort="2048" lower="-1.2" upper="1.2" velocity="15"/>
  </joint>
  <link name="r1_segment_3_THIGH">
    <visual>
      <geometry>
        <box size="0.1 0.1 0.7"/>
      </geometry>
      <material name="red"/>
      <origin rpy="0 0 0" xyz="0 0 -0.3"/>
    </visual>
    <collision>
      <geometry>
        <box size="0.1 0.1 0.7"/>
      </geometry>
      <origin rpy="0 0 0" xyz="0 0 -0.3"/>
    </collision>
    <inertial>
      <mass value="17.92"/>
      <inertia ixx="0.7466666666666666" ixy="0.0" ixz="0.0" iyy="0.7466666666666666" iyz="0.0" izz="0.029866666666666673"/>
    </inertial>
  </link>
  <joint name="r1_joint_2_to_3" type="revolute">
    <parent link="r1_segment_2_HIP"/>
    <child link="r1_segment_3_THIGH"/>
    <origin rpy="0 0 0" xyz="-0.1 -0.5 0"/>
    <axis xyz="1.0 0.0 0.0"/>
    <limit effort="2048" lower="-0.75" upper="0.2" velocity="15"/>
  </joint>
  <link name="r1_segment_4_FOOT">
    <visual>
      <geometry>
        <box size="0.1 0.1 0.4"/>
      </geometry>
      <material name="yellow"/>
      <origin rpy="0 0 0" xyz="0 0 -0.2"/>
    </visual>
    <collision>
      <geometry>
        <box size="0.1 0.1 0.4"/>
      </geometry>
      <origin rpy="0 0 0" xyz="0 0 -0.2"/>
    </collision>
    <inertial>
      <mass value="10.240000000000002"/>
      <inertia ixx="0.14506666666666673" ixy="0.0" ixz="0.0" iyy="0.14506666666666673" iyz="0.0" izz="0.017066666666666674"/>
    </inertial>
  </link>
  <joint name="r1_joint_3_to_4_FOOT" type="revolute">
    <parent link="r1_segment_3_THIGH"/>
    <child link="r1_segment_4_FOOT"/>
    <origin rpy="0 0 0" xyz="0.1 0 -0.55"/>
    <axis xyz="1.0 0.0 0.0"/>
    <limit effort="2048" lower="-0.5" upper="0.2" velocity="9"/>
  </joint>
  <!-- <xacro:leg name="r2" reflect="-1">
		<origin xyz="0 -0.1 1.05" rpy="0 0 0" />
	</xacro:leg> -->
  <link name="r3_segment_1">
    <visual>
      <geometry>
        <box size="0.1 0.1 0.2"/>
      </geometry>
      <material name="white"/>
      <origin rpy="0 0 0" xyz="0 0 0.1"/>
    </visual>
    <collision>
      <geometry>
        <box size="0.1 0.1 0.2"/>
      </geometry>
      <origin rpy="0 0 0" xyz="0 0 0.1"/>
    </collision>
    <inertial>
      <mass value="5.120000000000001"/>
      <inertia ixx="0.021333333333333343" ixy="0.0" ixz="0.0" iyy="0.021333333333333343" iyz="0.0" izz="0.008533333333333337"/>
    </inertial>
  </link>
  <joint name="r3_base_to_joint_1" type="fixed">
    <parent link="body"/>
    <child link="r3_segment_1"/>
    <origin rpy="0 0 0" xyz="-0.5 -0.1 .75"/>
  </joint>
  <link name="r3_segment_2_HIP">
    <visual>
      <geometry>
        <box size="0.1 0.6 0.1"/>
      </geometry>
      <material name="yellow"/>
      <origin rpy="0 0 0" xyz="0 -0.25 0"/>
    </visual>
    <collision>
      <geometry>
        <box size="0.1 0.6 0.1"/>
      </geometry>
      <origin rpy="0 0 0" xyz="0 -0.25 0"/>
    </collision>
    <inertial>
      <mass value="15.36"/>
      <inertia ixx="0.4735999999999999" ixy="0.0" ixz="0.0" iyy="0.0256" iyz="0.0" izz="0.4735999999999999"/>
    </inertial>
  </link>
  <joint name="r3_joint_1_to_2" type="revolute">
    <parent link="r3_segment_1"/>
    <child link="r3_segment_2_HIP"/>
    <origin rpy="0 0 0" xyz="0 0 0.25"/>
    <axis xyz="0.0 0.0 1.0"/>
    <limit effort="2048" lower="-1.2" upper="1.2" velocity="15"/>
  </joint>
  <link name="r3_segment_3_THIGH">
    <visual>
      <geometry>
        <box size="0.1 0.1 0.7"/>
      </geometry>
      <material name="red"/>
      <origin rpy="0 0 0" xyz="0 0 -0.3"/>
    </visual>
    <collision>
      <geometry>
        <box size="0.1 0.1 0.7"/>
      </geometry>
      <origin rpy="0 0 0" xyz="0 0 -0.3"/>
    </collision>
    <inertial>
      <mass value="17.92"/>
      <inertia ixx="0.7466666666666666" ixy="0.0" ixz="0.0" iyy="0.7466666666666666" iyz="0.0" izz="0.029866666666666673"/>
    </inertial>
  </link>
  <joint name="r3_joint_2_to_3" type="revolute">
    <parent link="r3_segment_2_HIP"/>
    <child link="r3_segment_3_THIGH"/>
    <origin rpy="0 0 0" xyz="-0.1 -0.5 0"/>
    <axis xyz="1.0 0.0 0.0"/>
    <limit effort="2048" lower="-0.75" upper="0.2" velocity="15"/>
  </joint>
  <link name="r3_segment_4_FOOT">
    <visual>
      <geometry>
        <box size="0.1 0.1 0.4"/>
      </geometry>
      <material name="yellow"/>
      <origin rpy="0 0 0" xyz="0 0 -0.2"/>
    </visual>
    <collision>
      <geometry>
        <box size="0.1 0.1 0.4"/>
      </geometry>
      <origin rpy="0 0 0" xyz="0 0 -0.2"/>
    </collision>
    <inertial>
      <mass value="10.240000000000002"/>
      <inertia ixx="0.14506666666666673" ixy="0.0" ixz="0.0" iyy="0.14506666666666673" iyz="0.0" izz="0.017066666666666674"/>
    </inertial>
  </link>
  <joint name="r3_joint_3_to_4_FOOT" type="revolute">
    <parent link="r3_segment_3_THIGH"/>
    <child link="r3_segment_4_FOOT"/>
    <origin rpy="0 0 0" xyz="0.1 0 -0.55"/>
    <axis xyz="1.0 0.0 0.0"/>
    <limit effort="2048" lower="-0.5" upper="0.2" velocity="9"/>
  </joint>
</robot>
