<?xml version="1.0" ?>
<!-- =================================================================================== -->
<!-- |    This document was autogenerated by xacro from v0.urdf.xacro                  | -->
<!-- |    EDITING THIS FILE BY HAND IS NOT RECOMMENDED                                 | -->
<!-- =================================================================================== -->
<robot name="v0">
  <material name="grey">
    <color rgba="0.5 0.5 0.5 1"/>
  </material>
  <material name="white">
    <color rgba="1 1 1 1"/>
  </material>
  <material name="yellow">
    <color rgba="0.91 0.7 0.14 1"/>
  </material>
  <material name="red">
    <color rgba="0.71 0.14 0.14 1"/>
  </material>
  <link name="body">
    <visual>
      <geometry>
        <box size="1.3 0.3 0.1"/>
      </geometry>
      <material name="grey"/>
      <origin rpy="0 0 0" xyz="0 0 0.7"/>
    </visual>
    <collision>
      <geometry>
        <box size="1.3 0.3 0.1"/>
      </geometry>
      <origin rpy="0 0 0" xyz="0 0 0.7"/>
    </collision>
    <inertial>
      <mass value="1.9500000000000004"/>
      <inertia ixx="0.01625" ixy="0.0" ixz="0.0" iyy="0.27625000000000005" iyz="0.0" izz="0.28925000000000006"/>
    </inertial>
  </link>
  <link name="l1_segment_1">
    <visual>
      <geometry>
        <box size="0.1 0.1 0.2"/>
      </geometry>
      <material name="white"/>
      <origin rpy="0 0 0" xyz="0 0 0.1"/>
    </visual>
    <collision>
      <geometry>
        <box size="0.1 0.1 0.2"/>
      </geometry>
      <origin rpy="0 0 0" xyz="0 0 0.1"/>
    </collision>
    <inertial>
      <mass value="0.10000000000000002"/>
      <inertia ixx="0.0004166666666666668" ixy="0.0" ixz="0.0" iyy="0.0004166666666666668" iyz="0.0" izz="0.00016666666666666674"/>
    </inertial>
  </link>
  <joint name="l1_base_to_joint_1" type="fixed">
    <parent link="body"/>
    <child link="l1_segment_1"/>
    <origin rpy="0 0 0" xyz="0.5 0.1 .75"/>
  </joint>
  <link name="l1_segment_2_HIP">
    <visual>
      <geometry>
        <box size="0.1 0.6 0.1"/>
      </geometry>
      <material name="yellow"/>
      <origin rpy="0 0 0" xyz="0 0.25 0"/>
    </visual>
    <collision>
      <geometry>
        <box size="0.1 0.6 0.1"/>
      </geometry>
      <origin rpy="0 0 0" xyz="0 0.25 0"/>
    </collision>
    <inertial>
      <mass value="0.3"/>
      <inertia ixx="0.00925" ixy="0.0" ixz="0.0" iyy="0.0005000000000000001" iyz="0.0" izz="0.00925"/>
    </inertial>
  </link>
  <joint name="l1_joint_1_to_2" type="revolute">
    <parent link="l1_segment_1"/>
    <child link="l1_segment_2_HIP"/>
    <origin rpy="0 0 0" xyz="0 0 0.25"/>
    <axis xyz="0.0 0.0 1.0"/>
    <limit effort="55" lower="-1.2" upper="1.2" velocity="29"/>
  </joint>
  <link name="l1_segment_3_THIGH">
    <visual>
      <geometry>
        <box size="0.1 0.1 0.7"/>
      </geometry>
      <material name="red"/>
      <origin rpy="0 0 0" xyz="0 0 -0.3"/>
    </visual>
    <collision>
      <geometry>
        <box size="0.1 0.1 0.7"/>
      </geometry>
      <origin rpy="0 0 0" xyz="0 0 -0.3"/>
    </collision>
    <inertial>
      <mass value="0.35000000000000003"/>
      <inertia ixx="0.014583333333333334" ixy="0.0" ixz="0.0" iyy="0.014583333333333334" iyz="0.0" izz="0.0005833333333333335"/>
    </inertial>
  </link>
  <joint name="l1_joint_2_to_3" type="revolute">
    <parent link="l1_segment_2_HIP"/>
    <child link="l1_segment_3_THIGH"/>
    <origin rpy="0 0 0" xyz="-0.1 0.5 0"/>
    <axis xyz="1.0 0.0 0.0"/>
    <limit effort="55" lower="-0.2" upper="0.75" velocity="29"/>
  </joint>
  <link name="l1_segment_4_FOOT">
    <visual>
      <geometry>
        <box size="0.1 0.1 0.4"/>
      </geometry>
      <material name="yellow"/>
      <origin rpy="0 0 0" xyz="0 0 -0.2"/>
    </visual>
    <collision>
      <geometry>
        <box size="0.1 0.1 0.4"/>
      </geometry>
      <origin rpy="0 0 0" xyz="0 0 -0.2"/>
    </collision>
    <inertial>
      <mass value="0.20000000000000004"/>
      <inertia ixx="0.0028333333333333344" ixy="0.0" ixz="0.0" iyy="0.0028333333333333344" iyz="0.0" izz="0.0003333333333333335"/>
    </inertial>
  </link>
  <joint name="l1_joint_3_to_4_FOOT" type="revolute">
    <parent link="l1_segment_3_THIGH"/>
    <child link="l1_segment_4_FOOT"/>
    <origin rpy="0 0 0" xyz="0.1 0 -0.55"/>
    <axis xyz="1.0 0.0 0.0"/>
    <limit effort="55" lower="-0.2" upper="0.5" velocity="29"/>
  </joint>
  <!-- <xacro:leg name="l2" reflect="1">
		<origin xyz="0 0.1 1.05" rpy="0 0 0" />
	</xacro:leg> -->
  <link name="l3_segment_1">
    <visual>
      <geometry>
        <box size="0.1 0.1 0.2"/>
      </geometry>
      <material name="white"/>
      <origin rpy="0 0 0" xyz="0 0 0.1"/>
    </visual>
    <collision>
      <geometry>
        <box size="0.1 0.1 0.2"/>
      </geometry>
      <origin rpy="0 0 0" xyz="0 0 0.1"/>
    </collision>
    <inertial>
      <mass value="0.10000000000000002"/>
      <inertia ixx="0.0004166666666666668" ixy="0.0" ixz="0.0" iyy="0.0004166666666666668" iyz="0.0" izz="0.00016666666666666674"/>
    </inertial>
  </link>
  <joint name="l3_base_to_joint_1" type="fixed">
    <parent link="body"/>
    <child link="l3_segment_1"/>
    <origin rpy="0 0 0" xyz="-0.5 0.1 .75"/>
  </joint>
  <link name="l3_segment_2_HIP">
    <visual>
      <geometry>
        <box size="0.1 0.6 0.1"/>
      </geometry>
      <material name="yellow"/>
      <origin rpy="0 0 0" xyz="0 0.25 0"/>
    </visual>
    <collision>
      <geometry>
        <box size="0.1 0.6 0.1"/>
      </geometry>
      <origin rpy="0 0 0" xyz="0 0.25 0"/>
    </collision>
    <inertial>
      <mass value="0.3"/>
      <inertia ixx="0.00925" ixy="0.0" ixz="0.0" iyy="0.0005000000000000001" iyz="0.0" izz="0.00925"/>
    </inertial>
  </link>
  <joint name="l3_joint_1_to_2" type="revolute">
    <parent link="l3_segment_1"/>
    <child link="l3_segment_2_HIP"/>
    <origin rpy="0 0 0" xyz="0 0 0.25"/>
    <axis xyz="0.0 0.0 1.0"/>
    <limit effort="55" lower="-1.2" upper="1.2" velocity="29"/>
  </joint>
  <link name="l3_segment_3_THIGH">
    <visual>
      <geometry>
        <box size="0.1 0.1 0.7"/>
      </geometry>
      <material name="red"/>
      <origin rpy="0 0 0" xyz="0 0 -0.3"/>
    </visual>
    <collision>
      <geometry>
        <box size="0.1 0.1 0.7"/>
      </geometry>
      <origin rpy="0 0 0" xyz="0 0 -0.3"/>
    </collision>
    <inertial>
      <mass value="0.35000000000000003"/>
      <inertia ixx="0.014583333333333334" ixy="0.0" ixz="0.0" iyy="0.014583333333333334" iyz="0.0" izz="0.0005833333333333335"/>
    </inertial>
  </link>
  <joint name="l3_joint_2_to_3" type="revolute">
    <parent link="l3_segment_2_HIP"/>
    <child link="l3_segment_3_THIGH"/>
    <origin rpy="0 0 0" xyz="-0.1 0.5 0"/>
    <axis xyz="1.0 0.0 0.0"/>
    <limit effort="55" lower="-0.2" upper="0.75" velocity="29"/>
  </joint>
  <link name="l3_segment_4_FOOT">
    <visual>
      <geometry>
        <box size="0.1 0.1 0.4"/>
      </geometry>
      <material name="yellow"/>
      <origin rpy="0 0 0" xyz="0 0 -0.2"/>
    </visual>
    <collision>
      <geometry>
        <box size="0.1 0.1 0.4"/>
      </geometry>
      <origin rpy="0 0 0" xyz="0 0 -0.2"/>
    </collision>
    <inertial>
      <mass value="0.20000000000000004"/>
      <inertia ixx="0.0028333333333333344" ixy="0.0" ixz="0.0" iyy="0.0028333333333333344" iyz="0.0" izz="0.0003333333333333335"/>
    </inertial>
  </link>
  <joint name="l3_joint_3_to_4_FOOT" type="revolute">
    <parent link="l3_segment_3_THIGH"/>
    <child link="l3_segment_4_FOOT"/>
    <origin rpy="0 0 0" xyz="0.1 0 -0.55"/>
    <axis xyz="1.0 0.0 0.0"/>
    <limit effort="55" lower="-0.2" upper="0.5" velocity="29"/>
  </joint>
  <link name="r1_segment_1">
    <visual>
      <geometry>
        <box size="0.1 0.1 0.2"/>
      </geometry>
      <material name="white"/>
      <origin rpy="0 0 0" xyz="0 0 0.1"/>
    </visual>
    <collision>
      <geometry>
        <box size="0.1 0.1 0.2"/>
      </geometry>
      <origin rpy="0 0 0" xyz="0 0 0.1"/>
    </collision>
    <inertial>
      <mass value="0.10000000000000002"/>
      <inertia ixx="0.0004166666666666668" ixy="0.0" ixz="0.0" iyy="0.0004166666666666668" iyz="0.0" izz="0.00016666666666666674"/>
    </inertial>
  </link>
  <joint name="r1_base_to_joint_1" type="fixed">
    <parent link="body"/>
    <child link="r1_segment_1"/>
    <origin rpy="0 0 0" xyz="0.5 -0.1 .75"/>
  </joint>
  <link name="r1_segment_2_HIP">
    <visual>
      <geometry>
        <box size="0.1 0.6 0.1"/>
      </geometry>
      <material name="yellow"/>
      <origin rpy="0 0 0" xyz="0 -0.25 0"/>
    </visual>
    <collision>
      <geometry>
        <box size="0.1 0.6 0.1"/>
      </geometry>
      <origin rpy="0 0 0" xyz="0 -0.25 0"/>
    </collision>
    <inertial>
      <mass value="0.3"/>
      <inertia ixx="0.00925" ixy="0.0" ixz="0.0" iyy="0.0005000000000000001" iyz="0.0" izz="0.00925"/>
    </inertial>
  </link>
  <joint name="r1_joint_1_to_2" type="revolute">
    <parent link="r1_segment_1"/>
    <child link="r1_segment_2_HIP"/>
    <origin rpy="0 0 0" xyz="0 0 0.25"/>
    <axis xyz="0.0 0.0 1.0"/>
    <limit effort="55" lower="-1.2" upper="1.2" velocity="29"/>
  </joint>
  <link name="r1_segment_3_THIGH">
    <visual>
      <geometry>
        <box size="0.1 0.1 0.7"/>
      </geometry>
      <material name="red"/>
      <origin rpy="0 0 0" xyz="0 0 -0.3"/>
    </visual>
    <collision>
      <geometry>
        <box size="0.1 0.1 0.7"/>
      </geometry>
      <origin rpy="0 0 0" xyz="0 0 -0.3"/>
    </collision>
    <inertial>
      <mass value="0.35000000000000003"/>
      <inertia ixx="0.014583333333333334" ixy="0.0" ixz="0.0" iyy="0.014583333333333334" iyz="0.0" izz="0.0005833333333333335"/>
    </inertial>
  </link>
  <joint name="r1_joint_2_to_3" type="revolute">
    <parent link="r1_segment_2_HIP"/>
    <child link="r1_segment_3_THIGH"/>
    <origin rpy="0 0 0" xyz="-0.1 -0.5 0"/>
    <axis xyz="1.0 0.0 0.0"/>
    <limit effort="55" lower="-0.75" upper="0.2" velocity="29"/>
  </joint>
  <link name="r1_segment_4_FOOT">
    <visual>
      <geometry>
        <box size="0.1 0.1 0.4"/>
      </geometry>
      <material name="yellow"/>
      <origin rpy="0 0 0" xyz="0 0 -0.2"/>
    </visual>
    <collision>
      <geometry>
        <box size="0.1 0.1 0.4"/>
      </geometry>
      <origin rpy="0 0 0" xyz="0 0 -0.2"/>
    </collision>
    <inertial>
      <mass value="0.20000000000000004"/>
      <inertia ixx="0.0028333333333333344" ixy="0.0" ixz="0.0" iyy="0.0028333333333333344" iyz="0.0" izz="0.0003333333333333335"/>
    </inertial>
  </link>
  <joint name="r1_joint_3_to_4_FOOT" type="revolute">
    <parent link="r1_segment_3_THIGH"/>
    <child link="r1_segment_4_FOOT"/>
    <origin rpy="0 0 0" xyz="0.1 0 -0.55"/>
    <axis xyz="1.0 0.0 0.0"/>
    <limit effort="55" lower="-0.5" upper="0.2" velocity="29"/>
  </joint>
  <!-- <xacro:leg name="r2" reflect="-1">
		<origin xyz="0 -0.1 1.05" rpy="0 0 0" />
	</xacro:leg> -->
  <link name="r3_segment_1">
    <visual>
      <geometry>
        <box size="0.1 0.1 0.2"/>
      </geometry>
      <material name="white"/>
      <origin rpy="0 0 0" xyz="0 0 0.1"/>
    </visual>
    <collision>
      <geometry>
        <box size="0.1 0.1 0.2"/>
      </geometry>
      <origin rpy="0 0 0" xyz="0 0 0.1"/>
    </collision>
    <inertial>
      <mass value="0.10000000000000002"/>
      <inertia ixx="0.0004166666666666668" ixy="0.0" ixz="0.0" iyy="0.0004166666666666668" iyz="0.0" izz="0.00016666666666666674"/>
    </inertial>
  </link>
  <joint name="r3_base_to_joint_1" type="fixed">
    <parent link="body"/>
    <child link="r3_segment_1"/>
    <origin rpy="0 0 0" xyz="-0.5 -0.1 .75"/>
  </joint>
  <link name="r3_segment_2_HIP">
    <visual>
      <geometry>
        <box size="0.1 0.6 0.1"/>
      </geometry>
      <material name="yellow"/>
      <origin rpy="0 0 0" xyz="0 -0.25 0"/>
    </visual>
    <collision>
      <geometry>
        <box size="0.1 0.6 0.1"/>
      </geometry>
      <origin rpy="0 0 0" xyz="0 -0.25 0"/>
    </collision>
    <inertial>
      <mass value="0.3"/>
      <inertia ixx="0.00925" ixy="0.0" ixz="0.0" iyy="0.0005000000000000001" iyz="0.0" izz="0.00925"/>
    </inertial>
  </link>
  <joint name="r3_joint_1_to_2" type="revolute">
    <parent link="r3_segment_1"/>
    <child link="r3_segment_2_HIP"/>
    <origin rpy="0 0 0" xyz="0 0 0.25"/>
    <axis xyz="0.0 0.0 1.0"/>
    <limit effort="55" lower="-1.2" upper="1.2" velocity="29"/>
  </joint>
  <link name="r3_segment_3_THIGH">
    <visual>
      <geometry>
        <box size="0.1 0.1 0.7"/>
      </geometry>
      <material name="red"/>
      <origin rpy="0 0 0" xyz="0 0 -0.3"/>
    </visual>
    <collision>
      <geometry>
        <box size="0.1 0.1 0.7"/>
      </geometry>
      <origin rpy="0 0 0" xyz="0 0 -0.3"/>
    </collision>
    <inertial>
      <mass value="0.35000000000000003"/>
      <inertia ixx="0.014583333333333334" ixy="0.0" ixz="0.0" iyy="0.014583333333333334" iyz="0.0" izz="0.0005833333333333335"/>
    </inertial>
  </link>
  <joint name="r3_joint_2_to_3" type="revolute">
    <parent link="r3_segment_2_HIP"/>
    <child link="r3_segment_3_THIGH"/>
    <origin rpy="0 0 0" xyz="-0.1 -0.5 0"/>
    <axis xyz="1.0 0.0 0.0"/>
    <limit effort="55" lower="-0.75" upper="0.2" velocity="29"/>
  </joint>
  <link name="r3_segment_4_FOOT">
    <visual>
      <geometry>
        <box size="0.1 0.1 0.4"/>
      </geometry>
      <material name="yellow"/>
      <origin rpy="0 0 0" xyz="0 0 -0.2"/>
    </visual>
    <collision>
      <geometry>
        <box size="0.1 0.1 0.4"/>
      </geometry>
      <origin rpy="0 0 0" xyz="0 0 -0.2"/>
    </collision>
    <inertial>
      <mass value="0.20000000000000004"/>
      <inertia ixx="0.0028333333333333344" ixy="0.0" ixz="0.0" iyy="0.0028333333333333344" iyz="0.0" izz="0.0003333333333333335"/>
    </inertial>
  </link>
  <joint name="r3_joint_3_to_4_FOOT" type="revolute">
    <parent link="r3_segment_3_THIGH"/>
    <child link="r3_segment_4_FOOT"/>
    <origin rpy="0 0 0" xyz="0.1 0 -0.55"/>
    <axis xyz="1.0 0.0 0.0"/>
    <limit effort="55" lower="-0.5" upper="0.2" velocity="29"/>
  </joint>
</robot>
