<?xml version="1.0" encoding="utf-8"?>
<!-- =================================================================================== -->
<!-- |    This document was autogenerated by xacro from description.xacro              | -->
<!-- |    EDITING THIS FILE BY HAND IS NOT RECOMMENDED                                 | -->
<!-- =================================================================================== -->
<robot name="soto_2_0_description">
  <joint name="pcw_fl_virtual" type="fixed">
    <origin rpy="0 0 0" xyz="0 0 0"/>
    <parent link="pcw_fl"/>
    <child link="pcw_fl_base_link"/>
  </joint>
  <link name="pcw_fl_base_link">
    <inertial>
      <origin rpy="0 0 0" xyz="0.068676 0.000080 0.060449"/>
      <mass value="5"/>
      <inertia ixx="0.01386833" ixy="0" ixz="0" iyy="0.02433708" iyz="0" izz="0.02455208"/>
    </inertial>
    <visual>
      <origin rpy="0 0 0" xyz="0 0 0"/>
      <geometry>
        <mesh filename="package://neobotix_pcw_description/meshes/pcw_base_link.STL"/>
      </geometry>
      <material name="">
        <color rgba="1 1 1 1"/>
      </material>
    </visual>
    <collision>
      <origin rpy="0 0 0" xyz="0.0525 0 0.064"/>
      <geometry>
        <box size="0.20500 0.12000 0.12800"/>
      </geometry>
    </collision>
  </link>
  <link name="pcw_fl_rotate_link">
    <inertial>
      <origin rpy="0 0 0" xyz="0 -0.013786 -0.098176"/>
      <mass value="4"/>
      <inertia ixx="0.01374714" ixy="0" ixz="0" iyy="0.01447043" iyz="0" izz="0.00734337"/>
    </inertial>
    <visual>
      <origin rpy="0 0 0" xyz="0 0 0"/>
      <geometry>
        <mesh filename="package://neobotix_pcw_description/meshes/pcw_rotate_link.STL"/>
      </geometry>
      <material name="">
        <color rgba="1 1 1 1"/>
      </material>
    </visual>
    <collision>
      <origin rpy="0 0 0" xyz="0 -0.013025 -0.107975"/>
      <geometry>
        <box size="0.11000 0.08400 0.1388"/>
      </geometry>
    </collision>
  </link>
  <joint name="fl_caster_rotation_joint" type="continuous">
    <origin rpy="0 0 -3.14159265358979" xyz="0.095 0 0"/>
    <parent link="pcw_fl_base_link"/>
    <child link="pcw_fl_rotate_link"/>
    <axis xyz="0 0 1"/>
  </joint>
  <link name="pcw_fl_wheel_link">
    <inertial>
      <origin rpy="0 0 0" xyz="0 0 0"/>
      <mass value="1"/>
      <inertia ixx="0.00209476" ixy="0.0" ixz="0.0" iyy="0.00403952" iyz="0.0" izz="0.00209476"/>
    </inertial>
    <visual>
      <origin rpy="0 0 0" xyz="0 0 0"/>
      <geometry>
        <mesh filename="package://neobotix_pcw_description/meshes/pcw_wheel_link.STL"/>
      </geometry>
      <material name="">
        <color rgba="1 1 1 1"/>
      </material>
    </visual>
    <collision>
      <origin rpy="1.57079632679 0 0" xyz="0 0 0"/>
      <geometry>
        <cylinder length="0.03" radius="0.0898835"/>
      </geometry>
    </collision>
  </link>
  <joint name="fl_caster_r_wheel_joint" type="continuous">
    <origin rpy="-9.63831971360485E-17 -2.77555756156289E-17 -9.28601314642794E-17" xyz="0 0.044649999999999 -0.12195"/>
    <parent link="pcw_fl_rotate_link"/>
    <child link="pcw_fl_wheel_link"/>
    <axis xyz="0 1 0"/>
  </joint>
  <joint name="pcw_fr_virtual" type="fixed">
    <origin rpy="0 0 0" xyz="0 0 0"/>
    <parent link="pcw_fr"/>
    <child link="pcw_fr_base_link"/>
  </joint>
  <link name="pcw_fr_base_link">
    <inertial>
      <origin rpy="0 0 0" xyz="0.068676 0.000080 0.060449"/>
      <mass value="5"/>
      <inertia ixx="0.01386833" ixy="0" ixz="0" iyy="0.02433708" iyz="0" izz="0.02455208"/>
    </inertial>
    <visual>
      <origin rpy="0 0 0" xyz="0 0 0"/>
      <geometry>
        <mesh filename="package://neobotix_pcw_description/meshes/pcw_base_link.STL"/>
      </geometry>
      <material name="">
        <color rgba="1 1 1 1"/>
      </material>
    </visual>
    <collision>
      <origin rpy="0 0 0" xyz="0.0525 0 0.064"/>
      <geometry>
        <box size="0.20500 0.12000 0.12800"/>
      </geometry>
    </collision>
  </link>
  <link name="pcw_fr_rotate_link">
    <inertial>
      <origin rpy="0 0 0" xyz="0 -0.013786 -0.098176"/>
      <mass value="4"/>
      <inertia ixx="0.01374714" ixy="0" ixz="0" iyy="0.01447043" iyz="0" izz="0.00734337"/>
    </inertial>
    <visual>
      <origin rpy="0 0 0" xyz="0 0 0"/>
      <geometry>
        <mesh filename="package://neobotix_pcw_description/meshes/pcw_rotate_link.STL"/>
      </geometry>
      <material name="">
        <color rgba="1 1 1 1"/>
      </material>
    </visual>
    <collision>
      <origin rpy="0 0 0" xyz="0 -0.013025 -0.107975"/>
      <geometry>
        <box size="0.11000 0.08400 0.1388"/>
      </geometry>
    </collision>
  </link>
  <joint name="fr_caster_rotation_joint" type="continuous">
    <origin rpy="0 0 -3.14159265358979" xyz="0.095 0 0"/>
    <parent link="pcw_fr_base_link"/>
    <child link="pcw_fr_rotate_link"/>
    <axis xyz="0 0 1"/>
  </joint>
  <link name="pcw_fr_wheel_link">
    <inertial>
      <origin rpy="0 0 0" xyz="0 0 0"/>
      <mass value="1"/>
      <inertia ixx="0.00209476" ixy="0.0" ixz="0.0" iyy="0.00403952" iyz="0.0" izz="0.00209476"/>
    </inertial>
    <visual>
      <origin rpy="0 0 0" xyz="0 0 0"/>
      <geometry>
        <mesh filename="package://neobotix_pcw_description/meshes/pcw_wheel_link.STL"/>
      </geometry>
      <material name="">
        <color rgba="1 1 1 1"/>
      </material>
    </visual>
    <collision>
      <origin rpy="1.57079632679 0 0" xyz="0 0 0"/>
      <geometry>
        <cylinder length="0.03" radius="0.0898835"/>
      </geometry>
    </collision>
  </link>
  <joint name="fr_caster_r_wheel_joint" type="continuous">
    <origin rpy="-9.63831971360485E-17 -2.77555756156289E-17 -9.28601314642794E-17" xyz="0 0.044649999999999 -0.12195"/>
    <parent link="pcw_fr_rotate_link"/>
    <child link="pcw_fr_wheel_link"/>
    <axis xyz="0 1 0"/>
  </joint>
  <joint name="pcw_bl_virtual" type="fixed">
    <origin rpy="0 0 0" xyz="0 0 0"/>
    <parent link="pcw_bl"/>
    <child link="pcw_bl_base_link"/>
  </joint>
  <link name="pcw_bl_base_link">
    <inertial>
      <origin rpy="0 0 0" xyz="0.068676 0.000080 0.060449"/>
      <mass value="5"/>
      <inertia ixx="0.01386833" ixy="0" ixz="0" iyy="0.02433708" iyz="0" izz="0.02455208"/>
    </inertial>
    <visual>
      <origin rpy="0 0 0" xyz="0 0 0"/>
      <geometry>
        <mesh filename="package://neobotix_pcw_description/meshes/pcw_base_link.STL"/>
      </geometry>
      <material name="">
        <color rgba="1 1 1 1"/>
      </material>
    </visual>
    <collision>
      <origin rpy="0 0 0" xyz="0.0525 0 0.064"/>
      <geometry>
        <box size="0.20500 0.12000 0.12800"/>
      </geometry>
    </collision>
  </link>
  <link name="pcw_bl_rotate_link">
    <inertial>
      <origin rpy="0 0 0" xyz="0 -0.013786 -0.098176"/>
      <mass value="4"/>
      <inertia ixx="0.01374714" ixy="0" ixz="0" iyy="0.01447043" iyz="0" izz="0.00734337"/>
    </inertial>
    <visual>
      <origin rpy="0 0 0" xyz="0 0 0"/>
      <geometry>
        <mesh filename="package://neobotix_pcw_description/meshes/pcw_rotate_link.STL"/>
      </geometry>
      <material name="">
        <color rgba="1 1 1 1"/>
      </material>
    </visual>
    <collision>
      <origin rpy="0 0 0" xyz="0 -0.013025 -0.107975"/>
      <geometry>
        <box size="0.11000 0.08400 0.1388"/>
      </geometry>
    </collision>
  </link>
  <joint name="bl_caster_rotation_joint" type="continuous">
    <origin rpy="0 0 -3.14159265358979" xyz="0.095 0 0"/>
    <parent link="pcw_bl_base_link"/>
    <child link="pcw_bl_rotate_link"/>
    <axis xyz="0 0 1"/>
  </joint>
  <link name="pcw_bl_wheel_link">
    <inertial>
      <origin rpy="0 0 0" xyz="0 0 0"/>
      <mass value="1"/>
      <inertia ixx="0.00209476" ixy="0.0" ixz="0.0" iyy="0.00403952" iyz="0.0" izz="0.00209476"/>
    </inertial>
    <visual>
      <origin rpy="0 0 0" xyz="0 0 0"/>
      <geometry>
        <mesh filename="package://neobotix_pcw_description/meshes/pcw_wheel_link.STL"/>
      </geometry>
      <material name="">
        <color rgba="1 1 1 1"/>
      </material>
    </visual>
    <collision>
      <origin rpy="1.57079632679 0 0" xyz="0 0 0"/>
      <geometry>
        <cylinder length="0.03" radius="0.0898835"/>
      </geometry>
    </collision>
  </link>
  <joint name="bl_caster_r_wheel_joint" type="continuous">
    <origin rpy="-9.63831971360485E-17 -2.77555756156289E-17 -9.28601314642794E-17" xyz="0 0.044649999999999 -0.12195"/>
    <parent link="pcw_bl_rotate_link"/>
    <child link="pcw_bl_wheel_link"/>
    <axis xyz="0 -1 0"/>
  </joint>
  <joint name="pcw_br_virtual" type="fixed">
    <origin rpy="0 0 0" xyz="0 0 0"/>
    <parent link="pcw_br"/>
    <child link="pcw_br_base_link"/>
  </joint>
  <link name="pcw_br_base_link">
    <inertial>
      <origin rpy="0 0 0" xyz="0.068676 0.000080 0.060449"/>
      <mass value="5"/>
      <inertia ixx="0.01386833" ixy="0" ixz="0" iyy="0.02433708" iyz="0" izz="0.02455208"/>
    </inertial>
    <visual>
      <origin rpy="0 0 0" xyz="0 0 0"/>
      <geometry>
        <mesh filename="package://neobotix_pcw_description/meshes/pcw_base_link.STL"/>
      </geometry>
      <material name="">
        <color rgba="1 1 1 1"/>
      </material>
    </visual>
    <collision>
      <origin rpy="0 0 0" xyz="0.0525 0 0.064"/>
      <geometry>
        <box size="0.20500 0.12000 0.12800"/>
      </geometry>
    </collision>
  </link>
  <link name="pcw_br_rotate_link">
    <inertial>
      <origin rpy="0 0 0" xyz="0 -0.013786 -0.098176"/>
      <mass value="4"/>
      <inertia ixx="0.01374714" ixy="0" ixz="0" iyy="0.01447043" iyz="0" izz="0.00734337"/>
    </inertial>
    <visual>
      <origin rpy="0 0 0" xyz="0 0 0"/>
      <geometry>
        <mesh filename="package://neobotix_pcw_description/meshes/pcw_rotate_link.STL"/>
      </geometry>
      <material name="">
        <color rgba="1 1 1 1"/>
      </material>
    </visual>
    <collision>
      <origin rpy="0 0 0" xyz="0 -0.013025 -0.107975"/>
      <geometry>
        <box size="0.11000 0.08400 0.1388"/>
      </geometry>
    </collision>
  </link>
  <joint name="br_caster_rotation_joint" type="continuous">
    <origin rpy="0 0 -3.14159265358979" xyz="0.095 0 0"/>
    <parent link="pcw_br_base_link"/>
    <child link="pcw_br_rotate_link"/>
    <axis xyz="0 0 1"/>
  </joint>
  <link name="pcw_br_wheel_link">
    <inertial>
      <origin rpy="0 0 0" xyz="0 0 0"/>
      <mass value="1"/>
      <inertia ixx="0.00209476" ixy="0.0" ixz="0.0" iyy="0.00403952" iyz="0.0" izz="0.00209476"/>
    </inertial>
    <visual>
      <origin rpy="0 0 0" xyz="0 0 0"/>
      <geometry>
        <mesh filename="package://neobotix_pcw_description/meshes/pcw_wheel_link.STL"/>
      </geometry>
      <material name="">
        <color rgba="1 1 1 1"/>
      </material>
    </visual>
    <collision>
      <origin rpy="1.57079632679 0 0" xyz="0 0 0"/>
      <geometry>
        <cylinder length="0.03" radius="0.0898835"/>
      </geometry>
    </collision>
  </link>
  <joint name="br_caster_r_wheel_joint" type="continuous">
    <origin rpy="-9.63831971360485E-17 -2.77555756156289E-17 -9.28601314642794E-17" xyz="0 0.044649999999999 -0.12195"/>
    <parent link="pcw_br_rotate_link"/>
    <child link="pcw_br_wheel_link"/>
    <axis xyz="0 -1 0"/>
  </joint>
  <link name="base_footprint"/>
  <joint name="base_footprint_to_base" type="fixed">
    <!-- TODO: align base_footprint to ground plane in 1015001 -->
    <origin rpy="0 0 0" xyz="0 0 0.1815"/>
    <parent link="base_footprint"/>
    <child link="base_link"/>
  </joint>
  <!-- start of autogenerated component -->
  <link name="base_link">
    <inertial>
      <origin rpy="0 0 0" xyz="-0.030858267467835 0.000734792595130519 -0.0262663159827579"/>
      <mass value="63.5292905960047"/>
      <inertia ixx="3.63597230656031" ixy="0.026575132004481" ixz="0.167726202587328" iyy="26.1224110628601" iyz="6.86288099105268E-05" izz="29.4697351846051"/>
    </inertial>
    <visual>
      <origin rpy="0 0 0" xyz="0 0 0"/>
      <geometry>
        <mesh filename="package://drive_base_soto_2_0_description/meshes/base_link.STL"/>
      </geometry>
      <material name="">
        <color rgba="0.529411764705882 0.549019607843137 0.549019607843137 1"/>
      </material>
    </visual>
    <collision>
      <origin rpy="0 0 0" xyz="0 0 0"/>
      <geometry>
        <mesh filename="package://drive_base_soto_2_0_description/meshes/base_link.STL"/>
      </geometry>
    </collision>
  </link>
  <link name="base_front_laser_link">
    <inertial>
      <origin rpy="0 0 0" xyz="-0.00302048772057795 -5.96143926624228E-05 0.0421733483270551"/>
      <mass value="1.31397168795335"/>
      <inertia ixx="0.000305638553073255" ixy="-9.97956652050864E-07" ixz="0.000141592688769949" iyy="0.000380355250516333" iyz="2.14415572558052E-06" izz="7.51377511329644E-05"/>
    </inertial>
    <visual>
      <origin rpy="0 0 0" xyz="0 0 0"/>
      <geometry>
        <mesh filename="package://drive_base_soto_2_0_description/meshes/base_front_laser_link.STL"/>
      </geometry>
      <material name="">
        <color rgba="1 1 1 1"/>
      </material>
    </visual>
    <collision>
      <origin rpy="0 0 0" xyz="0 0 0.0353"/>
      <geometry>
        <cylinder length="0.150512" radius="0.05"/>
      </geometry>
    </collision>
  </link>
  <joint name="base_to_front_laser" type="fixed">
    <origin rpy="3.14159265359 0 0" xyz="0.861737079408169 0 -0.0615749999999948"/>
    <parent link="base_link"/>
    <child link="base_front_laser_link"/>
    <axis xyz="0 0 0"/>
  </joint>
  <link name="base_rear_laser_right_link">
    <inertial>
      <origin rpy="0 0 0" xyz="-0.00302055406980495 -5.95917334884066E-05 0.0421734134136776"/>
      <mass value="1.31397215019182"/>
      <inertia ixx="0.000305637939313287" ixy="-9.98004178283187E-07" ixz="0.0001415922231505" iyy="0.000380354330003911" iyz="2.14425615271607E-06" izz="7.51374470666478E-05"/>
    </inertial>
    <visual>
      <origin rpy="0 0 0" xyz="0 0 0"/>
      <geometry>
        <mesh filename="package://drive_base_soto_2_0_description/meshes/base_rear_laser_right_link.STL"/>
      </geometry>
      <material name="">
        <color rgba="1 1 1 1"/>
      </material>
    </visual>
    <collision>
      <origin rpy="0 0 0" xyz="0 0 0.0353"/>
      <geometry>
        <cylinder length="0.150512" radius="0.05"/>
      </geometry>
    </collision>
  </link>
  <joint name="base_to_rear_right_laser" type="fixed">
    <origin rpy="3.14159265359 0 -2.35619449019234" xyz="-0.958782741924265 -0.36988960664894 -0.0615658394487754"/>
    <parent link="base_link"/>
    <child link="base_rear_laser_right_link"/>
    <axis xyz="0 0 0"/>
  </joint>
  <link name="base_rear_laser_left_link">
    <inertial>
      <origin rpy="0 0 0" xyz="-0.0030205540702416 -5.95917329817564E-05 0.0421734134135134"/>
      <mass value="1.31397215017044"/>
      <inertia ixx="0.00030563793931515" ixy="-9.98004179429839E-07" ixz="0.000141592223148923" iyy="0.000380354330003797" iyz="2.14425615513367E-06" izz="7.51374470647395E-05"/>
    </inertial>
    <visual>
      <origin rpy="0 0 0" xyz="0 0 0"/>
      <geometry>
        <mesh filename="package://drive_base_soto_2_0_description/meshes/base_rear_laser_left_link.STL"/>
      </geometry>
      <material name="">
        <color rgba="1 1 1 1"/>
      </material>
    </visual>
    <collision>
      <origin rpy="0 0 0" xyz="0 0 0.0353"/>
      <geometry>
        <cylinder length="0.150512" radius="0.05"/>
      </geometry>
    </collision>
  </link>
  <joint name="base_to_rear_left_laser" type="fixed">
    <origin rpy="3.14159265359 0 2.35619449019234" xyz="-0.958782747939142 0.369889600634062 -0.0615658394487751"/>
    <parent link="base_link"/>
    <child link="base_rear_laser_left_link"/>
    <axis xyz="0 0 0"/>
  </joint>
  <link name="pcw_bl">
    <!-- Assumes a (size, size, size) cube link -->
    <inertial>
      <origin xyz="0 0 0"/>
      <mass value="1"/>
      <inertia ixx="0.00166666666667" ixy="0" ixz="0" iyy="0.00166666666667" iyz="0" izz="0.00166666666667"/>
    </inertial>
  </link>
  <joint name="base_to_pcw_bl" type="fixed">
    <origin rpy="0 0 0" xyz="-0.916499999999999 0.2125 0.0304250000000063"/>
    <parent link="base_link"/>
    <child link="pcw_bl"/>
    <axis xyz="0 0 0"/>
  </joint>
  <link name="pcw_br">
    <!-- Assumes a (size, size, size) cube link -->
    <inertial>
      <origin xyz="0 0 0"/>
      <mass value="1"/>
      <inertia ixx="0.00166666666667" ixy="0" ixz="0" iyy="0.00166666666667" iyz="0" izz="0.00166666666667"/>
    </inertial>
  </link>
  <joint name="base_to_pcw_br" type="fixed">
    <origin rpy="0 0 -2.52323414687536E-16" xyz="-0.916499999999999 -0.2125 0.0304250000000063"/>
    <parent link="base_link"/>
    <child link="pcw_br"/>
    <axis xyz="0 0 0"/>
  </joint>
  <link name="pcw_fr">
    <!-- Assumes a (size, size, size) cube link -->
    <inertial>
      <origin xyz="0 0 0"/>
      <mass value="1"/>
      <inertia ixx="0.00166666666667" ixy="0" ixz="0" iyy="0.00166666666667" iyz="0" izz="0.00166666666667"/>
    </inertial>
  </link>
  <joint name="base_to_pcw_fr" type="fixed">
    <origin rpy="0 0 3.14159265358979" xyz="0.916499999999998 -0.280000000000002 0.0304250000000052"/>
    <parent link="base_link"/>
    <child link="pcw_fr"/>
    <axis xyz="0 0 0"/>
  </joint>
  <link name="pcw_fl">
    <!-- Assumes a (size, size, size) cube link -->
    <inertial>
      <origin xyz="0 0 0"/>
      <mass value="1"/>
      <inertia ixx="0.00166666666667" ixy="0" ixz="0" iyy="0.00166666666667" iyz="0" izz="0.00166666666667"/>
    </inertial>
  </link>
  <joint name="base_to_pcw_fl" type="fixed">
    <origin rpy="0 0 3.14159265358979" xyz="0.916499999999998 0.279999999999998 0.0304250000000052"/>
    <parent link="base_link"/>
    <child link="pcw_fl"/>
    <axis xyz="0 0 0"/>
  </joint>
  <link name="laser_field_link">
    <!-- Assumes a (size, size, size) cube link -->
    <inertial>
      <origin xyz="0 0 0"/>
      <mass value="1"/>
      <inertia ixx="0.00166666666667" ixy="0" ixz="0" iyy="0.00166666666667" iyz="0" izz="0.00166666666667"/>
    </inertial>
    <visual>
      <origin rpy="0 0 0" xyz="0 0 0"/>
      <geometry>
        <mesh filename="package://drive_base_soto_2_0_description/meshes/laser_field_link.STL"/>
      </geometry>
      <material name="">
        <color rgba="1 0 0 0.5"/>
      </material>
    </visual>
    <collision>
      <origin rpy="0 0 0" xyz="0 0 0"/>
      <geometry>
        <mesh filename="package://drive_base_soto_2_0_description/meshes/laser_field_link.STL"/>
      </geometry>
    </collision>
  </link>
  <joint name="base_to_laser_field" type="fixed">
    <origin rpy="0 0 0" xyz="0 0 0"/>
    <parent link="base_link"/>
    <child link="laser_field_link"/>
    <axis xyz="0 0 0"/>
  </joint>
  <joint name="manipulator_base_to_base_link" type="fixed">
    <origin rpy="0 0 0" xyz="0.2365 0 -0.0385"/>
    <parent link="base_link"/>
    <child link="manipulator_base_link"/>
  </joint>
  <link name="gripper_carrier_frame_link">
    <inertial>
      <origin rpy="0 0 0" xyz="0.419871261985957 -0.378092873023538 -0.172763052387008"/>
      <mass value="22.6544046182285"/>
      <inertia ixx="0.000978681072360067" ixy="5.36158454747139E-06" ixz="5.72288391326164E-05" iyy="0.212674313369314" iyz="-4.50383372113037E-05" izz="0.211729185697808"/>
    </inertial>
    <visual>
      <origin rpy="0 0 0" xyz="0 0 0"/>
      <geometry>
        <mesh filename="package://vertical_axis_soto_2_0_description/meshes/gripper_carrier_frame_link.STL"/>
      </geometry>
      <material name="">
        <color rgba="0.752941176470588 0.752941176470588 0.752941176470588 1"/>
      </material>
    </visual>
    <collision>
      <origin rpy="0 0 0" xyz="0 0 0"/>
      <geometry>
        <mesh filename="package://vertical_axis_soto_2_0_description/meshes/gripper_carrier_frame_link.STL"/>
      </geometry>
    </collision>
  </link>
  <joint name="vertical_axis_to_carrier_frame" type="fixed">
    <origin rpy="0 0 0" xyz="0 0 0.2565"/>
    <parent link="vertical_axis_link"/>
    <child link="gripper_carrier_frame_link"/>
  </joint>
  <!-- start of Optical frames -->
  <link name="nav_3d_cam_front_depth_optical_frame"/>
  <joint name="nav_3d_cam_front_depth_optical" type="fixed">
    <origin rpy="0 0 0" xyz="0 0 0"/>
    <parent link="nav_3d_cam_front_link"/>
    <child link="nav_3d_cam_front_depth_optical_frame"/>
  </joint>
  <link name="nav_3d_cam_front_rgb_optical_frame"/>
  <joint name="nav_3d_cam_front_rgb_optical" type="fixed">
    <origin rpy="0 0 0" xyz="0.0145 0 0"/>
    <parent link="nav_3d_cam_front_link"/>
    <child link="nav_3d_cam_front_rgb_optical_frame"/>
  </joint>
  <!-- Start of autogenerated component -->
  <link name="manipulator_base_link">
    <inertial>
      <origin rpy="0 0 0" xyz="0.0140831490754253 -0.0103314828835449 1.03628074208567"/>
      <mass value="49.4957057836692"/>
      <inertia ixx="28.4337696303107" ixy="0.170730173040725" ixz="0.770352253194218" iyy="27.3913289655028" iyz="0.419406036104634" izz="15.9885561853555"/>
    </inertial>
    <visual>
      <origin rpy="0 0 0" xyz="0 0 0"/>
      <geometry>
        <mesh filename="package://vertical_axis_soto_2_0_description/meshes/manipulator_base_link.STL"/>
      </geometry>
      <material name="">
        <color rgba="0.529411764705882 0.549019607843137 0.549019607843137 1"/>
      </material>
    </visual>
    <collision>
      <origin rpy="0 0 0" xyz="0 0 0"/>
      <geometry>
        <mesh filename="package://vertical_axis_soto_2_0_description/meshes/manipulator_base_link.STL"/>
      </geometry>
    </collision>
  </link>
  <link name="vertical_axis_link">
    <inertial>
      <origin rpy="0 0 0" xyz="0.420000000000104 -0.147165343803046 0.0668738949005537"/>
      <mass value="4.67274949695533"/>
      <inertia ixx="0.605491366340649" ixy="-1.6991963391888E-13" ixz="2.22521653880925E-14" iyy="0.756041439643056" iyz="-0.0117324984712755" izz="1.35863466880556"/>
    </inertial>
    <visual>
      <origin rpy="0 0 0" xyz="0 0 0.2565"/>
      <geometry>
        <mesh filename="package://vertical_axis_soto_2_0_description/meshes/vertical_axis_link.STL"/>
      </geometry>
      <material name="">
        <color rgba="0.647058823529412 0.619607843137255 0.588235294117647 1"/>
      </material>
    </visual>
    <collision>
      <origin rpy="0 0 0" xyz="0 0 0.2565"/>
      <geometry>
        <mesh filename="package://vertical_axis_soto_2_0_description/meshes/vertical_axis_link.STL"/>
      </geometry>
    </collision>
  </link>
  <joint name="vertical_axis" type="prismatic">
    <origin rpy="0 0 0" xyz="-0.420000000000075 0.381609999999924 -0.488"/>
    <parent link="manipulator_base_link"/>
    <child link="vertical_axis_link"/>
    <axis xyz="0 0 1"/>
    <limit effort="1368.21" lower="0.355" upper="1.968" velocity="0.322917"/>
  </joint>
  <link name="nav_3d_cam_front_link">
    <!-- Assumes a (size, size, size) cube link -->
    <inertial>
      <origin xyz="0 0 0"/>
      <mass value="0.018"/>
      <inertia ixx="3e-05" ixy="0" ixz="0" iyy="3e-05" iyz="0" izz="3e-05"/>
    </inertial>
  </link>
  <joint name="nav_3d_cam_front" type="fixed">
    <origin rpy="-2.50454747661185 0 -1.57079632679489" xyz="0.673539512035944 0.00661000000000513 1.92628520157743"/>
    <parent link="manipulator_base_link"/>
    <child link="nav_3d_cam_front_link"/>
    <axis xyz="0 0 0"/>
  </joint>
  <link name="light_curtain_receiver_front_link">
    <inertial>
      <origin rpy="0 0 0" xyz="-0.0134506399940098 0.000460652545141254 1.37200510917923E-05"/>
      <mass value="0.639593835683051"/>
      <inertia ixx="0.03084176" ixy="0" ixz="0" iyy="0.00013446" iyz="0" izz="0.03082808"/>
    </inertial>
    <visual>
      <origin rpy="0 0 0" xyz="0 0 0"/>
      <geometry>
        <mesh filename="package://vertical_axis_soto_2_0_description/meshes/light_curtain_receiver_front_link.STL"/>
      </geometry>
      <material name="">
        <color rgba="1 1 1 1"/>
      </material>
    </visual>
    <collision>
      <origin rpy="0 0 0" xyz="0 0 0"/>
      <geometry>
        <mesh filename="package://vertical_axis_soto_2_0_description/meshes/light_curtain_receiver_front_link.STL"/>
      </geometry>
    </collision>
  </link>
  <joint name="manipulator_base_to_receiver_front" type="fixed">
    <origin rpy="3.14159265358979 -1.5707963267949 0" xyz="0.612816314445163 0.00230001773507929 0.247218554241161"/>
    <parent link="manipulator_base_link"/>
    <child link="light_curtain_receiver_front_link"/>
    <axis xyz="0 0 0"/>
  </joint>
  <link name="light_curtain_emitter_front_link">
    <inertial>
      <origin rpy="0 0 0" xyz="-0.0134507091493998 -5.86724921519569E-05 1.27766254944817E-05"/>
      <mass value="0.639590567420819"/>
      <inertia ixx="0.03084176" ixy="0" ixz="0" iyy="0.00013446" iyz="0" izz="0.03082808"/>
    </inertial>
    <visual>
      <origin rpy="0 0 0" xyz="0 0 0"/>
      <geometry>
        <mesh filename="package://vertical_axis_soto_2_0_description/meshes/light_curtain_emitter_front_link.STL"/>
      </geometry>
      <material name="">
        <color rgba="1 1 1 1"/>
      </material>
    </visual>
    <collision>
      <origin rpy="0 0 0" xyz="0 0 0"/>
      <geometry>
        <mesh filename="package://vertical_axis_soto_2_0_description/meshes/light_curtain_emitter_front_link.STL"/>
      </geometry>
    </collision>
  </link>
  <joint name="manipulator_base_to_emitter_front" type="fixed">
    <origin rpy="-0.0336671572796617 1.57079631189374 3.10792549631013" xyz="0.613000000420853 0.00399206214091707 1.92309999999978"/>
    <parent link="manipulator_base_link"/>
    <child link="light_curtain_emitter_front_link"/>
    <axis xyz="0 0 0"/>
  </joint>
  <link name="light_curtain_receiver_left_link">
    <inertial>
      <origin rpy="0 0 0" xyz="-0.0134506399940099 0.000460652545142018 1.37200510916813E-05"/>
      <mass value="0.639593835683055"/>
      <inertia ixx="0.03084176" ixy="0" ixz="0" iyy="0.00013446" iyz="0" izz="0.03082808"/>
    </inertial>
    <visual>
      <origin rpy="0 0 0" xyz="0 0 0"/>
      <geometry>
        <mesh filename="package://vertical_axis_soto_2_0_description/meshes/light_curtain_receiver_left_link.STL"/>
      </geometry>
      <material name="">
        <color rgba="1 1 1 1"/>
      </material>
    </visual>
    <collision>
      <origin rpy="0 0 0" xyz="0 0 0"/>
      <geometry>
        <mesh filename="package://vertical_axis_soto_2_0_description/meshes/light_curtain_receiver_left_link.STL"/>
      </geometry>
    </collision>
  </link>
  <joint name="manipulator_base_to_receiver_left" type="fixed">
    <origin rpy="1.57079632679501 -1.5707963267949 0" xyz="0.0013599822863284 0.507000941267109 0.0620098761376573"/>
    <parent link="manipulator_base_link"/>
    <child link="light_curtain_receiver_left_link"/>
    <axis xyz="0 0 0"/>
  </joint>
  <link name="light_curtain_emitter_left_link">
    <inertial>
      <origin rpy="0 0 0" xyz="-0.0134507091493994 -5.8672492154189E-05 1.27766254947037E-05"/>
      <mass value="0.639590567420818"/>
      <inertia ixx="0.03084176" ixy="0" ixz="0" iyy="0.00013446" iyz="0" izz="0.03082808"/>
    </inertial>
    <visual>
      <origin rpy="0 0 0" xyz="0 0 0"/>
      <geometry>
        <mesh filename="package://vertical_axis_soto_2_0_description/meshes/light_curtain_emitter_left_link.STL"/>
      </geometry>
      <material name="">
        <color rgba="1 1 1 1"/>
      </material>
    </visual>
    <collision>
      <origin rpy="0 0 0" xyz="0 0 0"/>
      <geometry>
        <mesh filename="package://vertical_axis_soto_2_0_description/meshes/light_curtain_emitter_left_link.STL"/>
      </geometry>
    </collision>
  </link>
  <joint name="manipulator_base_to_emitter_left" type="fixed">
    <origin rpy="1.5707963267949 1.5707963267949 0" xyz="0.000842062140590042 0.50701000012157 1.92299012386215"/>
    <parent link="manipulator_base_link"/>
    <child link="light_curtain_emitter_left_link"/>
    <axis xyz="0 0 0"/>
  </joint>
  <link name="light_curtain_receiver_right_link">
    <inertial>
      <origin rpy="0 0 0" xyz="-0.0134506399940099 0.000460652545141308 1.37200510919033E-05"/>
      <mass value="0.639593835683049"/>
      <inertia ixx="0.03084176" ixy="0" ixz="0" iyy="0.00013446" iyz="0" izz="0.03082808"/>
    </inertial>
    <visual>
      <origin rpy="0 0 0" xyz="0 0 0"/>
      <geometry>
        <mesh filename="package://vertical_axis_soto_2_0_description/meshes/light_curtain_receiver_right_link.STL"/>
      </geometry>
      <material name="">
        <color rgba="1 1 1 1"/>
      </material>
    </visual>
    <collision>
      <origin rpy="0 0 0" xyz="0 0 0"/>
      <geometry>
        <mesh filename="package://vertical_axis_soto_2_0_description/meshes/light_curtain_receiver_right_link.STL"/>
      </geometry>
    </collision>
  </link>
  <joint name="manipulator_base_to_receiver_right" type="fixed">
    <origin rpy="0.032557324725479 -1.57079630572147 1.53823900206941" xyz="0.00125998228584711 -0.49899905903031 0.0620098761378208"/>
    <parent link="manipulator_base_link"/>
    <child link="light_curtain_receiver_right_link"/>
    <axis xyz="0 0 0"/>
  </joint>
  <link name="light_curtain_emitter_right_link">
    <inertial>
      <origin rpy="0 0 0" xyz="-0.0134507091493998 -5.86724921541233E-05 1.27766254945927E-05"/>
      <mass value="0.639590567420825"/>
      <inertia ixx="0.03084176" ixy="0" ixz="0" iyy="0.00013446" iyz="0" izz="0.03082808"/>
    </inertial>
    <visual>
      <origin rpy="0 0 0" xyz="0 0 0"/>
      <geometry>
        <mesh filename="package://vertical_axis_soto_2_0_description/meshes/light_curtain_emitter_right_link.STL"/>
      </geometry>
      <material name="">
        <color rgba="1 1 1 1"/>
      </material>
    </visual>
    <collision>
      <origin rpy="0 0 0" xyz="0 0 0"/>
      <geometry>
        <mesh filename="package://vertical_axis_soto_2_0_description/meshes/light_curtain_emitter_right_link.STL"/>
      </geometry>
    </collision>
  </link>
  <joint name="manipulator_base_to_emitter_right" type="fixed">
    <origin rpy="1.5707963267949 1.5707963267949 0" xyz="0.00074206213964603 -0.499000000420611 1.92299012386212"/>
    <parent link="manipulator_base_link"/>
    <child link="light_curtain_emitter_right_link"/>
    <axis xyz="0 0 0"/>
  </joint>
  <joint name="backpack_base_to_base_link" type="fixed">
    <origin rpy="0 0 0" xyz="-0.294 0 0.0885"/>
    <parent link="base_link"/>
    <child link="backpack_base_link"/>
  </joint>
  <!-- use index to uniquely identify all joints and links  -->
  <link name="backpack_layer_0_base_link">
    <inertial>
      <origin rpy="0 0 0" xyz="-0.288351 0 -0.056443"/>
      <mass value="5"/>
      <inertia ixx="0.25636833" ixy="0" ixz="0" iyy="0.30238167" iyz="0" izz="0.55041667"/>
    </inertial>
    <visual>
      <origin rpy="0 0 0" xyz="0 0 0"/>
      <geometry>
        <mesh filename="package://backpack_soto_4_0_description/meshes/layer_base_link.STL"/>
      </geometry>
      <material name="">
        <color rgba="0.752941176470588 0.752941176470588 0.752941176470588 1"/>
      </material>
    </visual>
    <collision>
      <origin rpy="0 0 0" xyz="0 0 0"/>
      <geometry>
        <mesh filename="package://backpack_soto_4_0_description/meshes/layer_base_link.STL"/>
      </geometry>
    </collision>
  </link>
  <!-- left reference exists for both single and double compartments -->
  <link name="backpack_layer_0_left_reference_link"/>
  <joint name="backpack_layer_0_base_to_left_reference" type="fixed">
    <origin rpy="0 0 0" xyz="0.1286 -0.185 -0.0236"/>
    <parent link="backpack_layer_0_base_link"/>
    <child link="backpack_layer_0_left_reference_link"/>
    <axis xyz="0 0 0"/>
  </joint>
  <!-- create right reference-->
  <link name="backpack_layer_0_right_reference_link"/>
  <joint name="backpack_layer_0_base_to_right_reference" type="fixed">
    <origin rpy="0 0 0" xyz="0.1286 0.185 -0.0236"/>
    <parent link="backpack_layer_0_base_link"/>
    <child link="backpack_layer_0_right_reference_link"/>
    <axis xyz="0 0 0"/>
  </joint>
  <link name="backpack_layer_0_compartment_0_link">
    <inertial>
      <origin rpy="0 0 0" xyz="-0.1675 0 0.0675"/>
      <mass value="5"/>
      <inertia ixx="0.0476354166667" ixy="0" ixz="0" iyy="0.0543541666667" iyz="0" izz="0.0868020833333"/>
    </inertial>
    <collision>
      <!-- Bottom -->
      <origin rpy="0 0 0" xyz="-0.1675 0 -0.0025"/>
      <geometry>
        <box size="0.335 0.31 0.005"/>
      </geometry>
    </collision>
    <collision>
      <!-- Back wall -->
      <origin rpy="0 0 0" xyz="-0.3375 0 0.025"/>
      <geometry>
        <box size="0.005 0.31 0.05"/>
      </geometry>
    </collision>
    <collision>
      <!-- Right wall -->
      <origin rpy="0 0 0" xyz="-0.2015 -0.1575 0.025"/>
      <geometry>
        <box size="0.267 0.005 0.05"/>
      </geometry>
    </collision>
    <collision>
      <!-- Left wall -->
      <origin rpy="0 0 0" xyz="-0.2015 0.1575 0.025"/>
      <geometry>
        <box size="0.267 0.005 0.05"/>
      </geometry>
    </collision>
    <collision>
      <!-- Left stopper bottom -->
      <origin rpy="0 0 0" xyz="0.05 0 -0.0025"/>
      <geometry>
        <box size="0.1 0.03 0.005"/>
      </geometry>
    </collision>
    <collision>
      <!-- Left stopper wall -->
      <origin rpy="0 0 0" xyz="0.1025 0 0.0095"/>
      <geometry>
        <box size="0.005 0.03 0.019"/>
      </geometry>
    </collision>
    <collision>
      <!-- Right funnel -->
      <origin rpy="0 0 -0.335" xyz="-0.0356438458494 -0.16853917755 0.0675"/>
      <geometry>
        <box size="0.068 0.005 0.135"/>
      </geometry>
    </collision>
    <collision>
      <!-- Left funnel -->
      <origin rpy="0 0 0.335" xyz="-0.0356438458494 0.16853917755 0.0675"/>
      <geometry>
        <box size="0.068 0.005 0.135"/>
      </geometry>
    </collision>
  </link>
  <joint name="backpack_layer_0_compartment_0" type="fixed">
    <origin rpy="0 0 0" xyz="-0.1055 0 -0.004"/>
    <parent link="backpack_layer_0_left_reference_link"/>
    <child link="backpack_layer_0_compartment_0_link"/>
  </joint>
  <link name="backpack_layer_0_compartment_1_link">
    <inertial>
      <origin rpy="0 0 0" xyz="-0.3675 0 0.0675"/>
      <mass value="5"/>
      <inertia ixx="0.0476354166667" ixy="0" ixz="0" iyy="0.2326875" iyz="0" izz="0.265135416667"/>
    </inertial>
    <collision>
      <!-- Bottom -->
      <origin rpy="0 0 0" xyz="-0.3675 0 -0.0025"/>
      <geometry>
        <box size="0.735 0.31 0.005"/>
      </geometry>
    </collision>
    <collision>
      <!-- Back wall -->
      <origin rpy="0 0 0" xyz="-0.7375 0 0.025"/>
      <geometry>
        <box size="0.005 0.31 0.05"/>
      </geometry>
    </collision>
    <collision>
      <!-- Right wall -->
      <origin rpy="0 0 0" xyz="-0.4015 -0.1575 0.025"/>
      <geometry>
        <box size="0.667 0.005 0.05"/>
      </geometry>
    </collision>
    <collision>
      <!-- Left wall -->
      <origin rpy="0 0 0" xyz="-0.4015 0.1575 0.025"/>
      <geometry>
        <box size="0.667 0.005 0.05"/>
      </geometry>
    </collision>
    <collision>
      <!-- Left stopper bottom -->
      <origin rpy="0 0 0" xyz="0.05 0 -0.0025"/>
      <geometry>
        <box size="0.1 0.03 0.005"/>
      </geometry>
    </collision>
    <collision>
      <!-- Left stopper wall -->
      <origin rpy="0 0 0" xyz="0.1025 0 0.0095"/>
      <geometry>
        <box size="0.005 0.03 0.019"/>
      </geometry>
    </collision>
    <collision>
      <!-- Right funnel -->
      <origin rpy="0 0 -0.335" xyz="-0.0356438458494 -0.16853917755 0.0675"/>
      <geometry>
        <box size="0.068 0.005 0.135"/>
      </geometry>
    </collision>
    <collision>
      <!-- Left funnel -->
      <origin rpy="0 0 0.335" xyz="-0.0356438458494 0.16853917755 0.0675"/>
      <geometry>
        <box size="0.068 0.005 0.135"/>
      </geometry>
    </collision>
  </link>
  <joint name="backpack_layer_0_compartment_1" type="fixed">
    <origin rpy="0 0 0" xyz="-0.1055 0 -0.004"/>
    <parent link="backpack_layer_0_right_reference_link"/>
    <child link="backpack_layer_0_compartment_1_link"/>
  </joint>
  <!-- Connection between layer and pivot bar -->
  <joint name="backpack_layer_0_base_pivot" type="continuous">
    <parent link="backpack_layer_0_link"/>
    <child link="backpack_layer_0_base_link"/>
    <axis xyz="0 1 0"/>
    <mimic joint="backpack_tilt" multiplier="1.0"/>
  </joint>
  <!-- use index to uniquely identify all joints and links  -->
  <link name="backpack_layer_1_base_link">
    <inertial>
      <origin rpy="0 0 0" xyz="-0.288351 0 -0.056443"/>
      <mass value="5"/>
      <inertia ixx="0.25636833" ixy="0" ixz="0" iyy="0.30238167" iyz="0" izz="0.55041667"/>
    </inertial>
    <visual>
      <origin rpy="0 0 0" xyz="0 0 0"/>
      <geometry>
        <mesh filename="package://backpack_soto_4_0_description/meshes/layer_base_link.STL"/>
      </geometry>
      <material name="">
        <color rgba="0.752941176470588 0.752941176470588 0.752941176470588 1"/>
      </material>
    </visual>
    <collision>
      <origin rpy="0 0 0" xyz="0 0 0"/>
      <geometry>
        <mesh filename="package://backpack_soto_4_0_description/meshes/layer_base_link.STL"/>
      </geometry>
    </collision>
  </link>
  <!-- left reference exists for both single and double compartments -->
  <link name="backpack_layer_1_left_reference_link"/>
  <joint name="backpack_layer_1_base_to_left_reference" type="fixed">
    <origin rpy="0 0 0" xyz="0.1286 -0.185 -0.0236"/>
    <parent link="backpack_layer_1_base_link"/>
    <child link="backpack_layer_1_left_reference_link"/>
    <axis xyz="0 0 0"/>
  </joint>
  <!-- create right reference-->
  <link name="backpack_layer_1_right_reference_link"/>
  <joint name="backpack_layer_1_base_to_right_reference" type="fixed">
    <origin rpy="0 0 0" xyz="0.1286 0.185 -0.0236"/>
    <parent link="backpack_layer_1_base_link"/>
    <child link="backpack_layer_1_right_reference_link"/>
    <axis xyz="0 0 0"/>
  </joint>
  <link name="backpack_layer_1_compartment_0_link">
    <inertial>
      <origin rpy="0 0 0" xyz="-0.3675 0 0.0675"/>
      <mass value="5"/>
      <inertia ixx="0.0476354166667" ixy="0" ixz="0" iyy="0.2326875" iyz="0" izz="0.265135416667"/>
    </inertial>
    <collision>
      <!-- Bottom -->
      <origin rpy="0 0 0" xyz="-0.3675 0 -0.0025"/>
      <geometry>
        <box size="0.735 0.31 0.005"/>
      </geometry>
    </collision>
    <collision>
      <!-- Back wall -->
      <origin rpy="0 0 0" xyz="-0.7375 0 0.025"/>
      <geometry>
        <box size="0.005 0.31 0.05"/>
      </geometry>
    </collision>
    <collision>
      <!-- Right wall -->
      <origin rpy="0 0 0" xyz="-0.4015 -0.1575 0.025"/>
      <geometry>
        <box size="0.667 0.005 0.05"/>
      </geometry>
    </collision>
    <collision>
      <!-- Left wall -->
      <origin rpy="0 0 0" xyz="-0.4015 0.1575 0.025"/>
      <geometry>
        <box size="0.667 0.005 0.05"/>
      </geometry>
    </collision>
    <collision>
      <!-- Left stopper bottom -->
      <origin rpy="0 0 0" xyz="0.05 0 -0.0025"/>
      <geometry>
        <box size="0.1 0.03 0.005"/>
      </geometry>
    </collision>
    <collision>
      <!-- Left stopper wall -->
      <origin rpy="0 0 0" xyz="0.1025 0 0.0095"/>
      <geometry>
        <box size="0.005 0.03 0.019"/>
      </geometry>
    </collision>
    <collision>
      <!-- Right funnel -->
      <origin rpy="0 0 -0.335" xyz="-0.0356438458494 -0.16853917755 0.0675"/>
      <geometry>
        <box size="0.068 0.005 0.135"/>
      </geometry>
    </collision>
    <collision>
      <!-- Left funnel -->
      <origin rpy="0 0 0.335" xyz="-0.0356438458494 0.16853917755 0.0675"/>
      <geometry>
        <box size="0.068 0.005 0.135"/>
      </geometry>
    </collision>
  </link>
  <joint name="backpack_layer_1_compartment_0" type="fixed">
    <origin rpy="0 0 0" xyz="-0.1055 0 -0.004"/>
    <parent link="backpack_layer_1_left_reference_link"/>
    <child link="backpack_layer_1_compartment_0_link"/>
  </joint>
  <link name="backpack_layer_1_compartment_1_link">
    <inertial>
      <origin rpy="0 0 0" xyz="-0.3675 0 0.0675"/>
      <mass value="5"/>
      <inertia ixx="0.0476354166667" ixy="0" ixz="0" iyy="0.2326875" iyz="0" izz="0.265135416667"/>
    </inertial>
    <collision>
      <!-- Bottom -->
      <origin rpy="0 0 0" xyz="-0.3675 0 -0.0025"/>
      <geometry>
        <box size="0.735 0.31 0.005"/>
      </geometry>
    </collision>
    <collision>
      <!-- Back wall -->
      <origin rpy="0 0 0" xyz="-0.7375 0 0.025"/>
      <geometry>
        <box size="0.005 0.31 0.05"/>
      </geometry>
    </collision>
    <collision>
      <!-- Right wall -->
      <origin rpy="0 0 0" xyz="-0.4015 -0.1575 0.025"/>
      <geometry>
        <box size="0.667 0.005 0.05"/>
      </geometry>
    </collision>
    <collision>
      <!-- Left wall -->
      <origin rpy="0 0 0" xyz="-0.4015 0.1575 0.025"/>
      <geometry>
        <box size="0.667 0.005 0.05"/>
      </geometry>
    </collision>
    <collision>
      <!-- Left stopper bottom -->
      <origin rpy="0 0 0" xyz="0.05 0 -0.0025"/>
      <geometry>
        <box size="0.1 0.03 0.005"/>
      </geometry>
    </collision>
    <collision>
      <!-- Left stopper wall -->
      <origin rpy="0 0 0" xyz="0.1025 0 0.0095"/>
      <geometry>
        <box size="0.005 0.03 0.019"/>
      </geometry>
    </collision>
    <collision>
      <!-- Right funnel -->
      <origin rpy="0 0 -0.335" xyz="-0.0356438458494 -0.16853917755 0.0675"/>
      <geometry>
        <box size="0.068 0.005 0.135"/>
      </geometry>
    </collision>
    <collision>
      <!-- Left funnel -->
      <origin rpy="0 0 0.335" xyz="-0.0356438458494 0.16853917755 0.0675"/>
      <geometry>
        <box size="0.068 0.005 0.135"/>
      </geometry>
    </collision>
  </link>
  <joint name="backpack_layer_1_compartment_1" type="fixed">
    <origin rpy="0 0 0" xyz="-0.1055 0 -0.004"/>
    <parent link="backpack_layer_1_right_reference_link"/>
    <child link="backpack_layer_1_compartment_1_link"/>
  </joint>
  <!-- Connection between layer and pivot bar -->
  <joint name="backpack_layer_1_base_pivot" type="continuous">
    <parent link="backpack_layer_1_link"/>
    <child link="backpack_layer_1_base_link"/>
    <axis xyz="0 1 0"/>
    <mimic joint="backpack_tilt" multiplier="1.0"/>
  </joint>
  <!-- use index to uniquely identify all joints and links  -->
  <link name="backpack_layer_2_base_link">
    <inertial>
      <origin rpy="0 0 0" xyz="-0.288351 0 -0.056443"/>
      <mass value="5"/>
      <inertia ixx="0.25636833" ixy="0" ixz="0" iyy="0.30238167" iyz="0" izz="0.55041667"/>
    </inertial>
    <visual>
      <origin rpy="0 0 0" xyz="0 0 0"/>
      <geometry>
        <mesh filename="package://backpack_soto_4_0_description/meshes/layer_base_link.STL"/>
      </geometry>
      <material name="">
        <color rgba="0.752941176470588 0.752941176470588 0.752941176470588 1"/>
      </material>
    </visual>
    <collision>
      <origin rpy="0 0 0" xyz="0 0 0"/>
      <geometry>
        <mesh filename="package://backpack_soto_4_0_description/meshes/layer_base_link.STL"/>
      </geometry>
    </collision>
  </link>
  <!-- left reference exists for both single and double compartments -->
  <link name="backpack_layer_2_left_reference_link"/>
  <joint name="backpack_layer_2_base_to_left_reference" type="fixed">
    <origin rpy="0 0 0" xyz="0.1286 -0.185 -0.0236"/>
    <parent link="backpack_layer_2_base_link"/>
    <child link="backpack_layer_2_left_reference_link"/>
    <axis xyz="0 0 0"/>
  </joint>
  <link name="backpack_layer_2_compartment_0_link">
    <inertial>
      <origin rpy="0 0 0" xyz="-0.3675 0 0.0675"/>
      <mass value="5"/>
      <inertia ixx="0.162635416667" ixy="0" ixz="0" iyy="0.2326875" iyz="0" izz="0.380135416667"/>
    </inertial>
    <collision>
      <!-- Bottom -->
      <origin rpy="0 0 0" xyz="-0.3675 0 -0.0025"/>
      <geometry>
        <box size="0.735 0.61 0.005"/>
      </geometry>
    </collision>
    <collision>
      <!-- Back wall -->
      <origin rpy="0 0 0" xyz="-0.7375 0 0.025"/>
      <geometry>
        <box size="0.005 0.61 0.05"/>
      </geometry>
    </collision>
    <collision>
      <!-- Right wall -->
      <origin rpy="0 0 0" xyz="-0.4015 -0.3075 0.025"/>
      <geometry>
        <box size="0.667 0.005 0.05"/>
      </geometry>
    </collision>
    <collision>
      <!-- Left wall -->
      <origin rpy="0 0 0" xyz="-0.4015 0.3075 0.025"/>
      <geometry>
        <box size="0.667 0.005 0.05"/>
      </geometry>
    </collision>
    <collision>
      <!-- Left stopper bottom -->
      <origin rpy="0 0 0" xyz="0.05 0.185 -0.0025"/>
      <geometry>
        <box size="0.1 0.03 0.005"/>
      </geometry>
    </collision>
    <collision>
      <!-- Left stopper wall -->
      <origin rpy="0 0 0" xyz="0.1025 0.185 0.0095"/>
      <geometry>
        <box size="0.005 0.03 0.019"/>
      </geometry>
    </collision>
    <collision>
      <!-- Right stopper bottom -->
      <origin rpy="0 0 0" xyz="0.05 -0.185 -0.0025"/>
      <geometry>
        <box size="0.1 0.03 0.005"/>
      </geometry>
    </collision>
    <collision>
      <!-- Right stopper wall -->
      <origin rpy="0 0 0" xyz="0.1025 -0.185 0.0095"/>
      <geometry>
        <box size="0.005 0.03 0.019"/>
      </geometry>
    </collision>
    <collision>
      <!-- Right funnel -->
      <origin rpy="0 0 -0.335" xyz="-0.0356438458494 -0.31853917755 0.0675"/>
      <geometry>
        <box size="0.068 0.005 0.135"/>
      </geometry>
    </collision>
    <collision>
      <!-- Left funnel -->
      <origin rpy="0 0 0.335" xyz="-0.0356438458494 0.31853917755 0.0675"/>
      <geometry>
        <box size="0.068 0.005 0.135"/>
      </geometry>
    </collision>
  </link>
  <joint name="backpack_layer_2_compartment_0" type="fixed">
    <origin rpy="0 0 0" xyz="-0.1055 0.185 -0.004"/>
    <parent link="backpack_layer_2_left_reference_link"/>
    <child link="backpack_layer_2_compartment_0_link"/>
  </joint>
  <!-- Connection between layer and pivot bar -->
  <joint name="backpack_layer_2_base_pivot" type="continuous">
    <parent link="backpack_layer_2_link"/>
    <child link="backpack_layer_2_base_link"/>
    <axis xyz="0 1 0"/>
    <mimic joint="backpack_tilt" multiplier="1.0"/>
  </joint>
  <!-- use index to uniquely identify all joints and links  -->
  <link name="backpack_layer_3_base_link">
    <inertial>
      <origin rpy="0 0 0" xyz="-0.288351 0 -0.056443"/>
      <mass value="5"/>
      <inertia ixx="0.25636833" ixy="0" ixz="0" iyy="0.30238167" iyz="0" izz="0.55041667"/>
    </inertial>
    <visual>
      <origin rpy="0 0 0" xyz="0 0 0"/>
      <geometry>
        <mesh filename="package://backpack_soto_4_0_description/meshes/layer_base_link.STL"/>
      </geometry>
      <material name="">
        <color rgba="0.752941176470588 0.752941176470588 0.752941176470588 1"/>
      </material>
    </visual>
    <collision>
      <origin rpy="0 0 0" xyz="0 0 0"/>
      <geometry>
        <mesh filename="package://backpack_soto_4_0_description/meshes/layer_base_link.STL"/>
      </geometry>
    </collision>
  </link>
  <!-- left reference exists for both single and double compartments -->
  <link name="backpack_layer_3_left_reference_link"/>
  <joint name="backpack_layer_3_base_to_left_reference" type="fixed">
    <origin rpy="0 0 0" xyz="0.1286 -0.185 -0.0236"/>
    <parent link="backpack_layer_3_base_link"/>
    <child link="backpack_layer_3_left_reference_link"/>
    <axis xyz="0 0 0"/>
  </joint>
  <link name="backpack_layer_3_compartment_0_link">
    <inertial>
      <origin rpy="0 0 0" xyz="-0.3675 0 0.0675"/>
      <mass value="5"/>
      <inertia ixx="0.162635416667" ixy="0" ixz="0" iyy="0.2326875" iyz="0" izz="0.380135416667"/>
    </inertial>
    <collision>
      <!-- Bottom -->
      <origin rpy="0 0 0" xyz="-0.3675 0 -0.0025"/>
      <geometry>
        <box size="0.735 0.61 0.005"/>
      </geometry>
    </collision>
    <collision>
      <!-- Back wall -->
      <origin rpy="0 0 0" xyz="-0.7375 0 0.025"/>
      <geometry>
        <box size="0.005 0.61 0.05"/>
      </geometry>
    </collision>
    <collision>
      <!-- Right wall -->
      <origin rpy="0 0 0" xyz="-0.4015 -0.3075 0.025"/>
      <geometry>
        <box size="0.667 0.005 0.05"/>
      </geometry>
    </collision>
    <collision>
      <!-- Left wall -->
      <origin rpy="0 0 0" xyz="-0.4015 0.3075 0.025"/>
      <geometry>
        <box size="0.667 0.005 0.05"/>
      </geometry>
    </collision>
    <collision>
      <!-- Left stopper bottom -->
      <origin rpy="0 0 0" xyz="0.05 0.185 -0.0025"/>
      <geometry>
        <box size="0.1 0.03 0.005"/>
      </geometry>
    </collision>
    <collision>
      <!-- Left stopper wall -->
      <origin rpy="0 0 0" xyz="0.1025 0.185 0.0095"/>
      <geometry>
        <box size="0.005 0.03 0.019"/>
      </geometry>
    </collision>
    <collision>
      <!-- Right stopper bottom -->
      <origin rpy="0 0 0" xyz="0.05 -0.185 -0.0025"/>
      <geometry>
        <box size="0.1 0.03 0.005"/>
      </geometry>
    </collision>
    <collision>
      <!-- Right stopper wall -->
      <origin rpy="0 0 0" xyz="0.1025 -0.185 0.0095"/>
      <geometry>
        <box size="0.005 0.03 0.019"/>
      </geometry>
    </collision>
    <collision>
      <!-- Right funnel -->
      <origin rpy="0 0 -0.335" xyz="-0.0356438458494 -0.31853917755 0.0675"/>
      <geometry>
        <box size="0.068 0.005 0.135"/>
      </geometry>
    </collision>
    <collision>
      <!-- Left funnel -->
      <origin rpy="0 0 0.335" xyz="-0.0356438458494 0.31853917755 0.0675"/>
      <geometry>
        <box size="0.068 0.005 0.135"/>
      </geometry>
    </collision>
  </link>
  <joint name="backpack_layer_3_compartment_0" type="fixed">
    <origin rpy="0 0 0" xyz="-0.1055 0.185 -0.004"/>
    <parent link="backpack_layer_3_left_reference_link"/>
    <child link="backpack_layer_3_compartment_0_link"/>
  </joint>
  <!-- Connection between layer and pivot bar -->
  <joint name="backpack_layer_3_base_pivot" type="continuous">
    <parent link="backpack_layer_3_link"/>
    <child link="backpack_layer_3_base_link"/>
    <axis xyz="0 1 0"/>
    <mimic joint="backpack_tilt" multiplier="1.0"/>
  </joint>
  <!-- Add nav_3d_cam_rear -->
  <link name="nav_3d_cam_rear_link">
    <!-- Assumes a (size, size, size) cube link -->
    <inertial>
      <origin xyz="0 0 0"/>
      <mass value="0.018"/>
      <inertia ixx="3e-05" ixy="0" ixz="0" iyy="3e-05" iyz="0" izz="3e-05"/>
    </inertial>
  </link>
  <joint name="nav_3d_cam_rear" type="fixed">
    <origin rpy="-2.50454747661185 5.81433671204338E-13 1.57079632679411" xyz="-0.9042660093438 -0.00299999999998613 1.81374525650981"/>
    <parent link="backpack_base_link"/>
    <child link="nav_3d_cam_rear_link"/>
    <axis xyz="0 0 0"/>
  </joint>
  <!-- start of Optical frames -->
  <link name="nav_3d_cam_rear_depth_optical_frame"/>
  <joint name="nav_3d_cam_rear_depth_optical" type="fixed">
    <origin rpy="0 0 0" xyz="0 0 0"/>
    <parent link="nav_3d_cam_rear_link"/>
    <child link="nav_3d_cam_rear_depth_optical_frame"/>
  </joint>
  <link name="nav_3d_cam_rear_rgb_optical_frame"/>
  <joint name="nav_3d_cam_rear_rgb_optical" type="fixed">
    <origin rpy="0 0 0" xyz="0.0145 0 0"/>
    <parent link="nav_3d_cam_rear_link"/>
    <child link="nav_3d_cam_rear_rgb_optical_frame"/>
  </joint>
  <!-- start of autogenerated component -->
  <link name="backpack_base_link">
    <inertial>
      <origin rpy="0 0 0" xyz="-0.455821265232892 -0.00577757365877395 0.78583802712244"/>
      <mass value="51.1974466568688"/>
      <inertia ixx="18.9816299358231" ixy="-0.0352688472475744" ixz="1.4784509395309" iyy="15.0741956264721" iyz="-0.279200068260086" izz="10.2614463851292"/>
    </inertial>
    <visual>
      <origin rpy="0 0 0" xyz="0 0 0"/>
      <geometry>
        <mesh filename="package://backpack_soto_4_0_description/meshes/backpack_base_link.STL"/>
      </geometry>
      <material name="">
        <color rgba="0.752941176470588 0.752941176470588 0.752941176470588 1"/>
      </material>
    </visual>
    <collision>
      <origin rpy="0 0 0" xyz="0 0 0"/>
      <geometry>
        <mesh filename="package://backpack_soto_4_0_description/meshes/backpack_base_link.STL"/>
      </geometry>
    </collision>
  </link>
  <link name="backpack_tilt_link">
    <!-- Assumes a (size, size, size) cube link -->
    <inertial>
      <origin xyz="0 0 0"/>
      <mass value="1"/>
      <inertia ixx="0.00166666666667" ixy="0" ixz="0" iyy="0.00166666666667" iyz="0" izz="0.00166666666667"/>
    </inertial>
  </link>
  <joint name="backpack_tilt" type="revolute">
    <origin rpy="0 0 0" xyz="0 0 0"/>
    <parent link="backpack_base_link"/>
    <child link="backpack_tilt_link"/>
    <axis xyz="0 1 0"/>
    <limit effort="524.003" lower="-0.15" upper="0.15" velocity="0.750142"/>
  </joint>
  <link name="pivot_bar_link">
    <inertial>
      <origin rpy="0 0 0" xyz="-1.00259564539407E-10 9.6129575046171E-16 0.710864961391751"/>
      <mass value="11.549234708381"/>
      <inertia ixx="2.02376780598256" ixy="-3.76524551976487E-14" ixz="3.06379251428533E-13" iyy="0.166328170735414" iyz="-2.72698530423554E-15" izz="1.85743963524715"/>
    </inertial>
    <visual>
      <origin rpy="0 0 0" xyz="0 0 0"/>
      <geometry>
        <mesh filename="package://backpack_soto_4_0_description/meshes/pivot_bar_link.STL"/>
      </geometry>
      <material name="">
        <color rgba="0.698039215686274 0.698039215686274 0.698039215686274 1"/>
      </material>
    </visual>
    <collision>
      <origin rpy="0 0 0" xyz="0 0 0"/>
      <geometry>
        <mesh filename="package://backpack_soto_4_0_description/meshes/pivot_bar_link.STL"/>
      </geometry>
    </collision>
  </link>
  <joint name="pivot_bar" type="prismatic">
    <origin rpy="0 0 0" xyz="-0.0887264972016103 0 0.147199999999999"/>
    <parent link="backpack_base_link"/>
    <child link="pivot_bar_link"/>
    <axis xyz="0 0 1"/>
    <limit effort="524.003" lower="-0.15" upper="0.15" velocity="0.750142"/>
    <!-- multiplier based off of small angle approximation using 0.38 m axis offset -->
    <mimic joint="backpack_tilt" multiplier="-0.38023"/>
  </joint>
  <link name="backpack_layer_0_link">
    <!-- Assumes a (size, size, size) cube link -->
    <inertial>
      <origin xyz="0 0 0"/>
      <mass value="1"/>
      <inertia ixx="0.00166666666667" ixy="0" ixz="0" iyy="0.00166666666667" iyz="0" izz="0.00166666666667"/>
    </inertial>
  </link>
  <joint name="pivot_bar_to_layer_0" type="fixed">
    <origin rpy="0 0 0" xyz="0 0 0.1545"/>
    <parent link="pivot_bar_link"/>
    <child link="backpack_layer_0_link"/>
    <axis xyz="0 0 0"/>
  </joint>
  <link name="backpack_layer_1_link">
    <!-- Assumes a (size, size, size) cube link -->
    <inertial>
      <origin xyz="0 0 0"/>
      <mass value="1"/>
      <inertia ixx="0.00166666666667" ixy="0" ixz="0" iyy="0.00166666666667" iyz="0" izz="0.00166666666667"/>
    </inertial>
  </link>
  <joint name="pivot_bar_to_layer_1" type="fixed">
    <origin rpy="0 0 0" xyz="0 0 0.5395"/>
    <parent link="pivot_bar_link"/>
    <child link="backpack_layer_1_link"/>
    <axis xyz="0 0 0"/>
  </joint>
  <link name="backpack_layer_2_link">
    <!-- Assumes a (size, size, size) cube link -->
    <inertial>
      <origin xyz="0 0 0"/>
      <mass value="1"/>
      <inertia ixx="0.00166666666667" ixy="0" ixz="0" iyy="0.00166666666667" iyz="0" izz="0.00166666666667"/>
    </inertial>
  </link>
  <joint name="pivot_bar_to_layer_2" type="fixed">
    <origin rpy="0 0 0" xyz="0 0 0.9245"/>
    <parent link="pivot_bar_link"/>
    <child link="backpack_layer_2_link"/>
    <axis xyz="0 0 0"/>
  </joint>
  <link name="backpack_layer_3_link">
    <!-- Assumes a (size, size, size) cube link -->
    <inertial>
      <origin xyz="0 0 0"/>
      <mass value="1"/>
      <inertia ixx="0.00166666666667" ixy="0" ixz="0" iyy="0.00166666666667" iyz="0" izz="0.00166666666667"/>
    </inertial>
  </link>
  <joint name="pivot_bar_to_layer_3" type="fixed">
    <origin rpy="0 0 0" xyz="0 0 1.3095"/>
    <parent link="pivot_bar_link"/>
    <child link="backpack_layer_3_link"/>
    <axis xyz="0 0 0"/>
  </joint>
  <link name="backpack_light_curtain_emitter_link">
    <inertial>
      <origin rpy="0 0 0" xyz="-0.0134507091493996 -5.86724921532477E-05 1.27766254949258E-05"/>
      <mass value="0.639590567420823"/>
      <inertia ixx="0.03084176" ixy="0" ixz="0" iyy="0.00013446" iyz="0" izz="0.03082808"/>
    </inertial>
    <visual>
      <origin rpy="0 0 0" xyz="0 0 0"/>
      <geometry>
        <mesh filename="package://backpack_soto_4_0_description/meshes/backpack_light_curtain_emitter_link.STL"/>
      </geometry>
      <material name="">
        <color rgba="0.792156862745098 0.819607843137255 0.933333333333333 1"/>
      </material>
    </visual>
    <collision>
      <origin rpy="0 0 0" xyz="0 0 0"/>
      <geometry>
        <mesh filename="package://backpack_soto_4_0_description/meshes/backpack_light_curtain_emitter_link.STL"/>
      </geometry>
    </collision>
  </link>
  <joint name="backpack_base_to_light_curtain_emitter" type="fixed">
    <origin rpy="3.14159265358979 1.5707963267949 0" xyz="-0.843726497429714 0.000292062117629333 1.81058017879448"/>
    <parent link="backpack_base_link"/>
    <child link="backpack_light_curtain_emitter_link"/>
    <axis xyz="0 0 0"/>
  </joint>
  <link name="backpack_light_curtain_receiver_link">
    <inertial>
      <origin rpy="0 0 0" xyz="-0.0134506399940098 0.000460652545142309 1.37200510917923E-05"/>
      <mass value="0.639593835683053"/>
      <inertia ixx="0.03084176" ixy="0" ixz="0" iyy="0.00013446" iyz="0" izz="0.03082808"/>
    </inertial>
    <visual>
      <origin rpy="0 0 0" xyz="0 0 0"/>
      <geometry>
        <mesh filename="package://backpack_soto_4_0_description/meshes/backpack_light_curtain_receiver_link.STL"/>
      </geometry>
      <material name="">
        <color rgba="0.792156862745098 0.819607843137255 0.933333333333333 1"/>
      </material>
    </visual>
    <collision>
      <origin rpy="0 0 0" xyz="0 0 0"/>
      <geometry>
        <mesh filename="package://backpack_soto_4_0_description/meshes/backpack_light_curtain_receiver_link.STL"/>
      </geometry>
    </collision>
  </link>
  <joint name="backpack_base_to_light_curtain_receiver" type="fixed">
    <origin rpy="0 -1.5707963267949 0" xyz="-0.84372743857346 0.00130998226353682 0.0849999310700815"/>
    <parent link="backpack_base_link"/>
    <child link="backpack_light_curtain_receiver_link"/>
    <axis xyz="0 0 0"/>
  </joint>
  <link name="charger_connector">
    <inertial>
      <origin rpy="0 0 0" xyz="0 0 0"/>
      <mass value="5"/>
      <inertia ixx="0.05208333" ixy="0" ixz="0" iyy="0.0262001" iyz="0" izz="0.0262001"/>
    </inertial>
    <visual>
      <origin rpy="0 0 0" xyz="0 0 0"/>
      <geometry>
        <mesh filename="package://backpack_soto_4_0_description/meshes/charger_connector.STL"/>
      </geometry>
      <material name="">
        <color rgba="1 1 1 1"/>
      </material>
    </visual>
    <collision>
      <origin rpy="0 0 0" xyz="0 0 0"/>
      <geometry>
        <mesh filename="package://backpack_soto_4_0_description/meshes/charger_connector.STL"/>
      </geometry>
    </collision>
  </link>
  <joint name="backpack_base_to_charger_connector" type="fixed">
    <origin rpy="-1.5707963267949 5.14278077834825E-16 1.5707963267949" xyz="-0.359627649604358 0.5109 0.279949443858408"/>
    <parent link="backpack_base_link"/>
    <child link="charger_connector"/>
    <axis xyz="0 0 0"/>
  </joint>
  <joint name="gripper_rotate" type="revolute">
    <origin rpy="0 0 0" xyz="0.42 -0.378 -0.1425"/>
    <parent link="gripper_carrier_frame_link"/>
    <child link="gripper_base_link"/>
    <axis xyz="0 0 1"/>
    <limit effort="18.0" lower="-1.62316" upper="3.19395" velocity="1.84078"/>
  </joint>
  <!-- start of manually added component -->
  <link name="gripper_casing_link">
    <inertial>
      <origin rpy="0 0 0" xyz="0.0566248951556863 -2.00332299900564E-06 0.0887482618543158"/>
      <mass value="1.89695657621472"/>
      <inertia ixx="0.161916446032723" ixy="-1.36885644157184E-06" ixz="-0.00162211448512088" iyy="0.0361164097412647" iyz="2.44138906904143E-07" izz="0.19593677406372"/>
    </inertial>
    <visual>
      <origin rpy="0 0 0" xyz="0 0 0"/>
      <geometry>
        <mesh filename="package://conveyor_gripper_1_0_description/meshes/gripper_casing_link.STL"/>
      </geometry>
      <material name="">
        <color rgba="0.698039215686274 0.698039215686274 0.698039215686274 1"/>
      </material>
    </visual>
    <collision>
      <origin rpy="0 0 0" xyz="0 0 0"/>
      <geometry>
        <mesh filename="package://conveyor_gripper_1_0_description/meshes/gripper_casing_link.STL"/>
      </geometry>
    </collision>
  </link>
  <joint name="gripper_base_to_casing" type="fixed">
    <!-- TODO: fix gripper_base_duplicate in 1015005 -->
    <origin rpy="0 0 0" xyz="-0.3105 0 0.0335"/>
    <parent link="gripper_base_link"/>
    <child link="gripper_casing_link"/>
  </joint>
  <!-- start of Optical frames -->
  <link name="gripper_depth_camera_link">
    <!-- Assumes a (size, size, size) cube link -->
    <inertial>
      <origin xyz="0 0 0"/>
      <mass value="0.1"/>
      <inertia ixx="0.000166666666667" ixy="0" ixz="0" iyy="0.000166666666667" iyz="0" izz="0.000166666666667"/>
    </inertial>
    <visual>
      <origin rpy="0 0 0" xyz="0 0 0"/>
      <geometry>
        <mesh filename="package://conveyor_gripper_1_0_description/meshes/gripper_depth_camera_link.STL"/>
      </geometry>
      <material name="">
        <color rgba="1 1 1 1"/>
      </material>
    </visual>
  </link>
  <joint name="gripper_base_to_depth_camera" type="fixed">
    <origin rpy="1.22173047639602 -1.14748667623603E-15 1.57079632679489" xyz="-0.44287 0.0055 0.23766"/>
    <parent link="gripper_base_link"/>
    <child link="gripper_depth_camera_link"/>
  </joint>
  <link name="gripper_depth_camera_depth_optical_frame"/>
  <joint name="gripper_depth_camera_depth_optical" type="fixed">
    <origin rpy="0 0 0" xyz="0 0 0"/>
    <parent link="gripper_depth_camera_link"/>
    <child link="gripper_depth_camera_depth_optical_frame"/>
  </joint>
  <link name="gripper_depth_camera_rgb_optical_frame"/>
  <joint name="gripper_depth_camera_rgb_optical" type="fixed">
    <origin rpy="0 0 0" xyz="0.0145 0 0"/>
    <parent link="gripper_depth_camera_link"/>
    <child link="gripper_depth_camera_rgb_optical_frame"/>
  </joint>
  <!-- start of autogenerated component -->
  <link name="gripper_base_link">
    <inertial>
      <origin rpy="0 0 0" xyz="-0.0291964947014054 0.00185928064465478 0.0571112330957645"/>
      <mass value="4.43604003962018"/>
      <inertia ixx="0.00848228102782677" ixy="-0.00397948149068779" ixz="-0.000197943829855595" iyy="0.0294439378703873" iyz="-4.43345350995509E-05" izz="0.0375329931767107"/>
    </inertial>
    <visual>
      <origin rpy="0 0 0" xyz="0 0 0"/>
      <geometry>
        <mesh filename="package://conveyor_gripper_1_0_description/meshes/gripper_base_link.STL"/>
      </geometry>
      <material name="">
        <color rgba="1 1 1 1"/>
      </material>
    </visual>
    <collision>
      <origin rpy="0 0 0" xyz="0 0 0"/>
      <geometry>
        <mesh filename="package://conveyor_gripper_1_0_description/meshes/gripper_base_link.STL"/>
      </geometry>
    </collision>
  </link>
  <link name="gripper_base_x_link">
    <!-- Assumes a (size, size, size) cube link -->
    <inertial>
      <origin xyz="0 0 0"/>
      <mass value="1.0"/>
      <inertia ixx="0.00166666666667" ixy="0" ixz="0" iyy="0.00166666666667" iyz="0" izz="0.00166666666667"/>
    </inertial>
    <visual>
      <origin rpy="0 0 0" xyz="0 0 0"/>
      <geometry>
        <mesh filename="package://conveyor_gripper_1_0_description/meshes/gripper_base_x_link.STL"/>
      </geometry>
      <material name="">
        <color rgba="0.752941176470588 0.752941176470588 0.752941176470588 1"/>
      </material>
    </visual>
    <collision>
      <origin rpy="0 0 0" xyz="0 0 0"/>
      <geometry>
        <mesh filename="package://conveyor_gripper_1_0_description/meshes/gripper_base_x_link.STL"/>
      </geometry>
    </collision>
  </link>
  <joint name="gripper_base_x" type="prismatic">
    <origin rpy="0 0 0" xyz="-0.3105 0 0.0334999999999999"/>
    <parent link="gripper_base_link"/>
    <child link="gripper_base_x_link"/>
    <axis xyz="1 0 0"/>
    <limit effort="149.65" lower="0.002" upper="0.359" velocity="0.296"/>
  </joint>
  <!-- start of manually added component -->
  <joint name="gripper_base_x_to_lateral_frame" type="fixed">
    <origin rpy="0 0 0" xyz="0.16682 0.00254 0.09900"/>
    <parent link="gripper_base_x_link"/>
    <child link="gripper_lateral_frame_link"/>
    <axis xyz="0 0 0"/>
  </joint>
  <!-- intersection between left/right foremost point axis and gripper_y XY plane -->
  <link name="gripper_surface_tip_link"/>
  <joint name="gripper_lateral_base_to_surface_tip" type="fixed">
    <origin rpy="0 0 0" xyz="0.5286 0 0.09824"/>
    <parent link="gripper_lateral_frame_link"/>
    <child link="gripper_surface_tip_link"/>
  </joint>
  <!-- start of autogenerated component -->
  <link name="gripper_lateral_frame_link">
    <inertial>
      <origin rpy="0 0 0" xyz="0.0109523584667708 -0.00213924832383244 -0.0127104571800313"/>
      <mass value="9.06374767181828"/>
      <inertia ixx="0.152907857864764" ixy="-0.000359950628530387" ixz="-0.00123889187432906" iyy="0.0557080358972366" iyz="-0.000575501671994657" izz="0.206424853480047"/>
    </inertial>
    <visual>
      <origin rpy="0 0 0" xyz="0 0 0"/>
      <geometry>
        <mesh filename="package://conveyor_gripper_1_0_description/meshes/gripper_lateral_frame_link.STL"/>
      </geometry>
      <material name="">
        <color rgba="0.752941176470588 0.752941176470588 0.752941176470588 1"/>
      </material>
    </visual>
    <collision>
      <origin rpy="0 0 0" xyz="0 0 0"/>
      <geometry>
        <mesh filename="package://conveyor_gripper_1_0_description/meshes/gripper_lateral_frame_link.STL"/>
      </geometry>
    </collision>
  </link>
  <link name="gripper_y_right_link">
    <inertial>
      <origin rpy="0 0 0" xyz="0.00354228739566675 -0.0287875724844683 -0.0242552174069289"/>
      <mass value="0.327260297311246"/>
      <inertia ixx="0.000196526493426853" ixy="-2.29379028088093E-05" ixz="7.56584769951965E-05" iyy="0.000210428427291072" iyz="4.8646299306573E-05" izz="5.22867445641922E-05"/>
    </inertial>
    <visual>
      <origin rpy="0 0 0" xyz="0 0 0"/>
      <geometry>
        <mesh filename="package://conveyor_gripper_1_0_description/meshes/gripper_y_right_link.STL"/>
      </geometry>
      <material name="">
        <color rgba="0.698039215686274 0.698039215686274 0.698039215686274 1"/>
      </material>
    </visual>
    <collision>
      <origin rpy="0 0 0" xyz="0 0 0"/>
      <geometry>
        <mesh filename="package://conveyor_gripper_1_0_description/meshes/gripper_y_right_link.STL"/>
      </geometry>
    </collision>
  </link>
  <joint name="gripper_y_right" type="prismatic">
    <origin rpy="0 0 0" xyz="-0.1895 -0.291 0.0768"/>
    <parent link="gripper_lateral_frame_link"/>
    <child link="gripper_y_right_link"/>
    <axis xyz="0 1 0"/>
    <limit effort="36.9721" lower="0.002" upper="0.498" velocity="0.414175"/>
  </joint>
  <link name="gripper_y_right_dist_x_sensor">
    <!-- Assumes a (size, size, size) cube link -->
    <inertial>
      <origin xyz="0 0 0"/>
      <mass value="0.206"/>
      <inertia ixx="0.000343333333333" ixy="0" ixz="0" iyy="0.000343333333333" iyz="0" izz="0.000343333333333"/>
    </inertial>
    <visual>
      <origin rpy="0 0 0" xyz="0 0 0"/>
      <geometry>
        <mesh filename="package://conveyor_gripper_1_0_description/meshes/gripper_y_right_dist_x_sensor.STL"/>
      </geometry>
      <material name="">
        <color rgba="1 1 1 1"/>
      </material>
    </visual>
  </link>
  <joint name="gripper_y_right_to_dist_x_sensor" type="fixed">
    <origin rpy="1.5707963267949 8.45933770995668E-16 1.72247079380644E-16" xyz="-0.000773072340143593 -0.0340048054495324 0.0292"/>
    <parent link="gripper_y_right_link"/>
    <child link="gripper_y_right_dist_x_sensor"/>
    <axis xyz="0 0 0"/>
  </joint>
  <link name="gripper_y_left_link">
    <inertial>
      <origin rpy="0 0 0" xyz="0.00355881845944125 -0.0392124275155317 -0.0242552174069289"/>
      <mass value="0.327260297311246"/>
      <inertia ixx="0.000196526493426853" ixy="2.2946784360994E-05" ixz="7.58716206094717E-05" iyy="0.000210573949255188" iyz="-4.86462993065728E-05" izz="5.24322665283085E-05"/>
    </inertial>
    <visual>
      <origin rpy="0 0 0" xyz="0 0 0"/>
      <geometry>
        <mesh filename="package://conveyor_gripper_1_0_description/meshes/gripper_y_left_link.STL"/>
      </geometry>
      <material name="">
        <color rgba="1 1 1 1"/>
      </material>
    </visual>
    <collision>
      <origin rpy="0 0 0" xyz="0 0 0"/>
      <geometry>
        <mesh filename="package://conveyor_gripper_1_0_description/meshes/gripper_y_left_link.STL"/>
      </geometry>
    </collision>
  </link>
  <joint name="gripper_y_left" type="prismatic">
    <origin rpy="0 0 0" xyz="-0.1895 0.359 0.0768"/>
    <parent link="gripper_lateral_frame_link"/>
    <child link="gripper_y_left_link"/>
    <axis xyz="0 -1 0"/>
    <limit effort="36.9721" lower="0.002" upper="0.498" velocity="0.414175"/>
  </joint>
  <link name="gripper_y_left_dist_x_sensor">
    <!-- Assumes a (size, size, size) cube link -->
    <inertial>
      <origin xyz="0 0 0"/>
      <mass value="0.206"/>
      <inertia ixx="0.000343333333333" ixy="0" ixz="0" iyy="0.000343333333333" iyz="0" izz="0.000343333333333"/>
    </inertial>
    <visual>
      <origin rpy="0 0 0" xyz="0 0 0"/>
      <geometry>
        <mesh filename="package://conveyor_gripper_1_0_description/meshes/gripper_y_left_dist_x_sensor.STL"/>
      </geometry>
      <material name="">
        <color rgba="1 1 1 1"/>
      </material>
    </visual>
  </link>
  <joint name="gripper_y_left_to_dist_x_sensor" type="fixed">
    <origin rpy="-1.5707963267949 2.6257874588619E-16 4.90441639395184E-17" xyz="-0.00077307234014351 -0.0339951945504676 0.0292"/>
    <parent link="gripper_y_left_link"/>
    <child link="gripper_y_left_dist_x_sensor"/>
    <axis xyz="0 0 0"/>
  </joint>
  <!-- start of manually added component -->
  <joint name="gripper_y_right_to_belt_right" type="fixed">
    <parent link="gripper_y_right_link"/>
    <child link="conveyor_belt_right_base_link"/>
  </joint>
  <!-- prismatic joint travelling along conveyor belt plane -->
  <link name="conveyor_belt_right_link">
    <!-- Assumes a (size, size, size) cube link -->
    <inertial>
      <origin xyz="0 0 0"/>
      <mass value="0.5"/>
      <inertia ixx="0.000833333333333" ixy="0" ixz="0" iyy="0.000833333333333" iyz="0" izz="0.000833333333333"/>
    </inertial>
  </link>
  <joint name="conveyor_belt_right" type="prismatic">
    <origin rpy="0 0 0" xyz="0 0 0"/>
    <parent link="conveyor_belt_right_surface_foremost_link"/>
    <child link="conveyor_belt_right_link"/>
    <axis xyz="-1 0 0"/>
    <!-- TODO: swap limit out for macro from dimensioning notebook -->
    <limit effort="30" lower="0" upper="0.60" velocity="1"/>
  </joint>
  <!-- start of autogenerated component -->
  <link name="conveyor_belt_right_base_link">
    <inertial>
      <origin rpy="0 0 0" xyz="0.353839700449319 -0.0342492002501805 -0.0100000000278072"/>
      <mass value="1.75237629293966"/>
      <inertia ixx="0.00106107197657959" ixy="3.25747306440015E-06" ixz="3.63423703976073E-13" iyy="0.0518565044065418" iyz="-3.83928274166947E-14" izz="0.0519817058628901"/>
    </inertial>
    <visual>
      <origin rpy="0 0 0" xyz="0 0 0"/>
      <geometry>
        <mesh filename="package://conveyor_gripper_1_0_description/meshes/conveyor_belt_right_base_link.STL"/>
      </geometry>
      <material name="">
        <color rgba="0.698039215686274 0.698039215686274 0.698039215686274 1"/>
      </material>
    </visual>
    <collision>
      <origin rpy="0 0 0" xyz="0 0 0"/>
      <geometry>
        <mesh filename="package://conveyor_gripper_1_0_description/meshes/conveyor_belt_right_base_link.STL"/>
      </geometry>
    </collision>
  </link>
  <link name="conveyor_belt_right_foremost_link"/>
  <joint name="belt_right_base_to_foremost" type="fixed">
    <origin rpy="0 0 0" xyz="0.718038238155445 -0.0339999999950005 0.02174"/>
    <parent link="conveyor_belt_right_base_link"/>
    <child link="conveyor_belt_right_foremost_link"/>
    <axis xyz="0 0 0"/>
  </joint>
  <link name="conveyor_belt_right_surface_foremost_link">
    <!-- Assumes a (size, size, size) cube link -->
    <inertial>
      <origin xyz="0 0 0"/>
      <mass value="0.01"/>
      <inertia ixx="1.66666666667e-05" ixy="0" ixz="0" iyy="1.66666666667e-05" iyz="0" izz="1.66666666667e-05"/>
    </inertial>
  </link>
  <joint name="belt_right_base_to_surface_foremost" type="fixed">
    <origin rpy="0 0 0" xyz="0.686298238155445 -0.0339999999950005 0.02174"/>
    <parent link="conveyor_belt_right_base_link"/>
    <child link="conveyor_belt_right_surface_foremost_link"/>
    <axis xyz="0 0 0"/>
  </joint>
  <!-- start of manually added component -->
  <joint name="gripper_y_left_to_belt" type="fixed">
    <parent link="gripper_y_left_link"/>
    <child link="conveyor_belt_left_base_link"/>
  </joint>
  <!-- prismatic joint travelling along conveyor belt plane -->
  <link name="conveyor_belt_left_link">
    <!-- Assumes a (size, size, size) cube link -->
    <inertial>
      <origin xyz="0 0 0"/>
      <mass value="0.5"/>
      <inertia ixx="0.000833333333333" ixy="0" ixz="0" iyy="0.000833333333333" iyz="0" izz="0.000833333333333"/>
    </inertial>
  </link>
  <joint name="conveyor_belt_left" type="prismatic">
    <origin rpy="0 0 0" xyz="0 0 0"/>
    <parent link="conveyor_belt_left_surface_foremost_link"/>
    <child link="conveyor_belt_left_link"/>
    <axis xyz="-1 0 0"/>
    <!-- TODO: swap limit out for macro from dimensioning notebook -->
    <limit effort="30" lower="0" upper="0.60" velocity="1"/>
  </joint>
  <!-- start of autogenerated component -->
  <link name="conveyor_belt_left_base_link">
    <inertial>
      <origin rpy="0 0 0" xyz="0.351579454282733 -0.0337525735461215 -0.00999999997239077"/>
      <mass value="1.76493912170865"/>
      <inertia ixx="0.00108186929664942" ixy="-4.24450588331179E-06" ixz="-4.73563126814083E-13" iyy="0.0531142162231874" iyz="-3.84792553638102E-14" izz="0.0532602149996055"/>
    </inertial>
    <visual>
      <origin rpy="0 0 0" xyz="0 0 0"/>
      <geometry>
        <mesh filename="package://conveyor_gripper_1_0_description/meshes/conveyor_belt_left_base_link.STL"/>
      </geometry>
      <material name="">
        <color rgba="1 1 1 1"/>
      </material>
    </visual>
    <collision>
      <origin rpy="0 0 0" xyz="0 0 0"/>
      <geometry>
        <mesh filename="package://conveyor_gripper_1_0_description/meshes/conveyor_belt_left_base_link.STL"/>
      </geometry>
    </collision>
  </link>
  <link name="conveyor_belt_left_foremost_link"/>
  <joint name="base_left_to_foremost" type="fixed">
    <origin rpy="0 0 0" xyz="0.718038238155445 -0.0339999999950005 0.02174"/>
    <parent link="conveyor_belt_left_base_link"/>
    <child link="conveyor_belt_left_foremost_link"/>
    <axis xyz="0 0 0"/>
  </joint>
  <link name="conveyor_belt_left_surface_foremost_link">
    <!-- Assumes a (size, size, size) cube link -->
    <inertial>
      <origin xyz="0 0 0"/>
      <mass value="0.01"/>
      <inertia ixx="1.66666666667e-05" ixy="0" ixz="0" iyy="1.66666666667e-05" iyz="0" izz="1.66666666667e-05"/>
    </inertial>
  </link>
  <joint name="belt_left_to_surface_foremost" type="fixed">
    <origin rpy="0 0 0" xyz="0.686298238155445 -0.0339999999950005 0.02174"/>
    <parent link="conveyor_belt_left_base_link"/>
    <child link="conveyor_belt_left_surface_foremost_link"/>
    <axis xyz="0 0 0"/>
  </joint>
  <link name="conveyor_belt_left_barcode_camera">
    <!-- Assumes a (size, size, size) cube link -->
    <inertial>
      <origin xyz="0 0 0"/>
      <mass value="0.1"/>
      <inertia ixx="0.000166666666667" ixy="0" ixz="0" iyy="0.000166666666667" iyz="0" izz="0.000166666666667"/>
    </inertial>
    <visual>
      <origin rpy="0 0 0" xyz="0 0 0"/>
      <geometry>
        <mesh filename="package://conveyor_gripper_1_0_description/meshes/conveyor_belt_left_barcode_camera.STL"/>
      </geometry>
      <material name="">
        <color rgba="1 1 1 1"/>
      </material>
    </visual>
  </link>
  <joint name="conveyor_base_left_to_barcode_camera" type="fixed">
    <!-- TODO: add option for calibrating barcode camera -->
    <origin rpy="1.3660676472658 0.00532358718963196 1.38245094245529" xyz="0.260007017149422 -0.122391992222825 -0.0116598009191592"/>
    <parent link="conveyor_belt_left_base_link"/>
    <child link="conveyor_belt_left_barcode_camera"/>
    <axis xyz="0 0 0"/>
  </joint>
  <link name="conveyor_belt_left_reflective_sensor">
    <!-- Assumes a (size, size, size) cube link -->
    <inertial>
      <origin xyz="0 0 0"/>
      <mass value="0.07"/>
      <inertia ixx="0.000116666666667" ixy="0" ixz="0" iyy="0.000116666666667" iyz="0" izz="0.000116666666667"/>
    </inertial>
    <visual>
      <origin rpy="0 0 0" xyz="0 0 0"/>
      <geometry>
        <mesh filename="package://conveyor_gripper_1_0_description/meshes/conveyor_belt_left_reflective_sensor.STL"/>
      </geometry>
      <material name="">
        <color rgba="1 1 1 1"/>
      </material>
    </visual>
  </link>
  <joint name="conveyor_belt_left_base_to_reflective" type="fixed">
    <origin rpy="-1.5707963267949 1.45855003581176E-16 -5.73827871115263E-16" xyz="0.242349119077722 -0.0938499999900007 -0.0408000000099999"/>
    <parent link="conveyor_belt_left_base_link"/>
    <child link="conveyor_belt_left_reflective_sensor"/>
    <axis xyz="0 0 0"/>
  </joint>
  <link name="conveyor_belt_left_safety_dist_sensor">
    <!-- Assumes a (size, size, size) cube link -->
    <inertial>
      <origin xyz="0 0 0"/>
      <mass value="0.206"/>
      <inertia ixx="0.000343333333333" ixy="0" ixz="0" iyy="0.000343333333333" iyz="0" izz="0.000343333333333"/>
    </inertial>
    <visual>
      <origin rpy="0 0 0" xyz="0 0 0"/>
      <geometry>
        <mesh filename="package://conveyor_gripper_1_0_description/meshes/conveyor_belt_left_safety_dist_sensor.STL"/>
      </geometry>
      <material name="">
        <color rgba="1 1 1 1"/>
      </material>
    </visual>
  </link>
  <joint name="conveyor_belt_left_base_to_safety_dist" type="fixed">
    <origin rpy="0 0 0" xyz="0.224026046737579 -0.0922499999900007 -0.0129951945604675"/>
    <parent link="conveyor_belt_left_base_link"/>
    <child link="conveyor_belt_left_safety_dist_sensor"/>
    <axis xyz="0 0 0"/>
  </joint>
  <joint name="press_base_to_manipulator_base" type="fixed">
    <origin rpy="0 0 0" xyz="0 0 1.9965"/>
    <parent link="manipulator_base_link"/>
    <child link="press_base_link"/>
  </joint>
  <!-- use for the mimics -->
  <link name="press_jaw_link">
    <inertial>
      <origin rpy="0 0 0" xyz="0.000015 -0.007431 0.049507"/>
      <mass value="2.0"/>
      <inertia ixx="0.0192083" ixy="0.0" ixz="0.0" iyy="0.4744167" iyz="0.0" izz="0.4635417"/>
    </inertial>
    <collision>
      <origin rpy="0 0 0" xyz="0 0 0"/>
      <geometry>
        <mesh filename="package://klt_press_1_0_description/meshes/press_jaw_right_link.STL"/>
      </geometry>
    </collision>
  </link>
  <joint name="press_jaw" type="prismatic">
    <origin rpy="0 0 0" xyz="0 -0.319 -0.135"/>
    <parent link="press_base_link"/>
    <child link="press_jaw_link"/>
    <axis xyz="0 1 0"/>
    <limit effort="557.947" lower="0.001" upper="0.23" velocity="0.0233333"/>
  </joint>
  <!-- start of Optical frames -->
  <link name="press_depth_camera_depth_optical_frame"/>
  <joint name="press_depth_camera_depth_optical" type="fixed">
    <origin rpy="0 0 0" xyz="0 0 0"/>
    <parent link="press_depth_camera_link"/>
    <child link="press_depth_camera_depth_optical_frame"/>
  </joint>
  <link name="press_depth_camera_rgb_optical_frame"/>
  <joint name="press_depth_camera_rgb_optical" type="fixed">
    <origin rpy="0 0 0" xyz="0.0145 0 0"/>
    <parent link="press_depth_camera_link"/>
    <child link="press_depth_camera_rgb_optical_frame"/>
  </joint>
  <!-- Start of autogenerated component -->
  <link name="press_base_link">
    <inertial>
      <origin rpy="0 0 0" xyz="0.000372 0.000122 -0.006491"/>
      <mass value="10.0"/>
      <inertia ixx="5.3921333" ixy="0.0" ixz="0.0" iyy="2.8044333" iyz="0.0" izz="8.0789667"/>
    </inertial>
    <visual>
      <origin rpy="0 0 0" xyz="0 0 0"/>
      <geometry>
        <mesh filename="package://klt_press_1_0_description/meshes/press_base_link.STL"/>
      </geometry>
      <material name="">
        <color rgba="0.698039215686274 0.698039215686274 0.698039215686274 1"/>
      </material>
    </visual>
    <collision>
      <origin rpy="0 0 0" xyz="0 0 0"/>
      <geometry>
        <mesh filename="package://klt_press_1_0_description/meshes/press_base_link.STL"/>
      </geometry>
    </collision>
  </link>
  <link name="press_jaw_right_link">
    <inertial>
      <origin rpy="0 0 0" xyz="0.000015 -0.007431 0.049507"/>
      <mass value="2.0"/>
      <inertia ixx="0.0192083" ixy="0.0" ixz="0.0" iyy="0.4744167" iyz="0.0" izz="0.4635417"/>
    </inertial>
    <visual>
      <origin rpy="0 0 0" xyz="0 0 0"/>
      <geometry>
        <mesh filename="package://klt_press_1_0_description/meshes/press_jaw_right_link.STL"/>
      </geometry>
      <material name="">
        <color rgba="0.250980392156863 0.250980392156863 0.250980392156863 1"/>
      </material>
    </visual>
  </link>
  <joint name="press_base_to_jaw_right" type="prismatic">
    <origin rpy="1.18057130309098E-16 4.52630720180711E-33 -3.83399731126472E-17" xyz="0 -0.319 -0.135"/>
    <parent link="press_base_link"/>
    <child link="press_jaw_right_link"/>
    <limit effort="557.947" lower="0.001" upper="0.23" velocity="0.0233333"/>
    <mimic joint="press_jaw" multiplier="1.0"/>
    <axis xyz="0 1 0"/>
  </joint>
  <link name="press_jaw_left_link">
    <inertial>
      <origin rpy="0 0 0" xyz="0.000015 -0.007431 0.049507"/>
      <mass value="2.0"/>
      <inertia ixx="0.0192083" ixy="0.0" ixz="0.0" iyy="0.4744167" iyz="0.0" izz="0.4635417"/>
    </inertial>
    <visual>
      <origin rpy="0 0 0" xyz="0 0 0"/>
      <geometry>
        <mesh filename="package://klt_press_1_0_description/meshes/press_jaw_left_link.STL"/>
      </geometry>
      <material name="">
        <color rgba="0.698039215686274 0.698039215686274 0.698039215686274 1"/>
      </material>
    </visual>
    <collision>
      <origin rpy="0 0 0" xyz="0 0 0"/>
      <geometry>
        <mesh filename="package://klt_press_1_0_description/meshes/press_jaw_left_link.STL"/>
      </geometry>
    </collision>
  </link>
  <joint name="press_base_to_jaw_left" type="prismatic">
    <origin rpy="0 0 3.14159265358979" xyz="0 0.319 -0.135"/>
    <parent link="press_base_link"/>
    <child link="press_jaw_left_link"/>
    <limit effort="557.947" lower="0.001" upper="0.23" velocity="0.0233333"/>
    <mimic joint="press_jaw" multiplier="1.0"/>
    <axis xyz="0 1 0"/>
  </joint>
  <link name="press_light_barrier_rear_receiver_link">
    <!-- Assumes a (size, size, size) cube link -->
    <inertial>
      <origin xyz="0 0 0"/>
      <mass value="0.03"/>
      <inertia ixx="5e-05" ixy="0" ixz="0" iyy="5e-05" iyz="0" izz="5e-05"/>
    </inertial>
    <visual>
      <origin rpy="0 0 0" xyz="0 0 0"/>
      <geometry>
        <mesh filename="package://klt_press_1_0_description/meshes/press_light_barrier_rear_receiver_link.STL"/>
      </geometry>
      <material name="">
        <color rgba="1 1 1 1"/>
      </material>
    </visual>
  </link>
  <joint name="press_to_rear_receiver" type="fixed">
    <origin rpy="-1.5707963267949 0 1.5707963267949" xyz="-0.09005 -0.34683 -0.1102"/>
    <parent link="press_base_link"/>
    <child link="press_light_barrier_rear_receiver_link"/>
    <axis xyz="0 0 0"/>
  </joint>
  <link name="press_light_barrier_front_receiver_link">
    <!-- Assumes a (size, size, size) cube link -->
    <inertial>
      <origin xyz="0 0 0"/>
      <mass value="0.03"/>
      <inertia ixx="5e-05" ixy="0" ixz="0" iyy="5e-05" iyz="0" izz="5e-05"/>
    </inertial>
    <visual>
      <origin rpy="0 0 0" xyz="0 0 0"/>
      <geometry>
        <mesh filename="package://klt_press_1_0_description/meshes/press_light_barrier_front_receiver_link.STL"/>
      </geometry>
      <material name="">
        <color rgba="1 1 1 1"/>
      </material>
    </visual>
  </link>
  <joint name="press_to_front_receiver" type="fixed">
    <origin rpy="-1.5707963267949 -1.51635886423709E-33 1.5707963267949" xyz="0.09005 -0.34683 -0.1102"/>
    <parent link="press_base_link"/>
    <child link="press_light_barrier_front_receiver_link"/>
    <axis xyz="0 0 0"/>
  </joint>
  <link name="press_light_barrier_rear_emitter_link">
    <!-- Assumes a (size, size, size) cube link -->
    <inertial>
      <origin xyz="0 0 0"/>
      <mass value="0.03"/>
      <inertia ixx="5e-05" ixy="0" ixz="0" iyy="5e-05" iyz="0" izz="5e-05"/>
    </inertial>
    <visual>
      <origin rpy="0 0 0" xyz="0 0 0"/>
      <geometry>
        <mesh filename="package://klt_press_1_0_description/meshes/press_light_barrier_rear_emitter_link.STL"/>
      </geometry>
      <material name="">
        <color rgba="1 1 1 1"/>
      </material>
    </visual>
  </link>
  <joint name="press_to_rear_emitter" type="fixed">
    <origin rpy="-1.5707963267949 0 -1.5707963267949" xyz="-0.090049999999999 0.34683 -0.1102"/>
    <parent link="press_base_link"/>
    <child link="press_light_barrier_rear_emitter_link"/>
    <axis xyz="0 0 0"/>
  </joint>
  <link name="press_light_barrier_front_emitter_link">
    <!-- Assumes a (size, size, size) cube link -->
    <inertial>
      <origin xyz="0 0 0"/>
      <mass value="0.03"/>
      <inertia ixx="5e-05" ixy="0" ixz="0" iyy="5e-05" iyz="0" izz="5e-05"/>
    </inertial>
    <visual>
      <origin rpy="0 0 0" xyz="0 0 0"/>
      <geometry>
        <mesh filename="package://klt_press_1_0_description/meshes/press_light_barrier_front_emitter_link.STL"/>
      </geometry>
      <material name="">
        <color rgba="1 1 1 1"/>
      </material>
    </visual>
  </link>
  <joint name="press_to_front_emitter" type="fixed">
    <origin rpy="-1.5707963267949 0 -1.5707963267949" xyz="0.090050000000001 0.34683 -0.1102"/>
    <parent link="press_base_link"/>
    <child link="press_light_barrier_front_emitter_link"/>
    <axis xyz="0 0 0"/>
  </joint>
  <link name="press_upper_limit_link">
    <!-- Assumes a (size, size, size) cube link -->
    <inertial>
      <origin xyz="0 0 0"/>
      <mass value="0.1"/>
      <inertia ixx="0.000166666666667" ixy="0" ixz="0" iyy="0.000166666666667" iyz="0" izz="0.000166666666667"/>
    </inertial>
  </link>
  <joint name="press_base_to_upper_limit" type="fixed">
    <origin rpy="0 0 0" xyz="0 0 -0.083"/>
    <parent link="press_base_link"/>
    <child link="press_upper_limit_link"/>
    <axis xyz="0 0 0"/>
  </joint>
  <link name="press_depth_camera_link">
    <!-- Assumes a (size, size, size) cube link -->
    <inertial>
      <origin xyz="0 0 0"/>
      <mass value="0.1"/>
      <inertia ixx="0.000166666666667" ixy="0" ixz="0" iyy="0.000166666666667" iyz="0" izz="0.000166666666667"/>
    </inertial>
    <visual>
      <origin rpy="0 0 0" xyz="0 0 0"/>
      <geometry>
        <mesh filename="package://klt_press_1_0_description/meshes/press_depth_camera_link.STL"/>
      </geometry>
      <material name="">
        <color rgba="1 1 1 1"/>
      </material>
    </visual>
  </link>
  <joint name="press_base_to_depth_camera" type="fixed">
    <origin rpy="-3.14159265358979 -5.28214878924751E-16 1.57079480536764" xyz="0.135499920277204 -0.0200000104977874 -0.0148"/>
    <parent link="press_base_link"/>
    <child link="press_depth_camera_link"/>
    <axis xyz="0 0 0"/>
  </joint>
  <joint name="base_to_design_elements" type="fixed">
    <parent link="base_link"/>
    <child link="design_elements_link"/>
  </joint>
  <link name="design_elements_link">
    <inertial>
      <origin rpy="0 0 0" xyz="-0.0839888788296438 -4.7711093603331E-05 0.967007714134433"/>
      <mass value="36.5366910563565"/>
      <inertia ixx="21.8912953115095" ixy="0.0732488950261167" ixz="1.26489469855065" iyy="32.0624509778293" iyz="0.00112967341454037" izz="22.9076113690761"/>
    </inertial>
    <visual>
      <origin rpy="0 0 0" xyz="0 0 0"/>
      <geometry>
        <mesh filename="package://soto_2_0_description/meshes/design_elements_link.STL"/>
      </geometry>
      <material name="">
        <color rgba="0.698039215686274 0.698039215686274 0.698039215686274 1"/>
      </material>
    </visual>
    <collision>
      <origin rpy="0 0 0" xyz="0 0 0"/>
      <geometry>
        <mesh filename="package://soto_2_0_description/meshes/design_elements_link.STL"/>
      </geometry>
    </collision>
  </link>
</robot>

