<robot name="soto_2_0_description">
  <link name="base_footprint" />
  <joint name="base_footprint_to_base" type="fixed">
    
    <origin rpy="0 0 0" xyz="0 0 0.1815" />
    <parent link="base_footprint" />
    <child link="base_link" />
  </joint>
  
  <link name="base_link">
    <inertial>
      <origin rpy="0 0 0" xyz="-0.030858267467835 0.000734792595130519 -0.0262663159827579" />
      <mass value="63.5292905960047" />
      <inertia ixx="3.63597230656031" ixy="0.026575132004481" ixz="0.167726202587328" iyy="26.1224110628601" iyz="6.86288099105268E-05" izz="29.4697351846051" />
    </inertial>
    <visual>
      <origin rpy="0 0 0" xyz="0 0 0" />
      <geometry>
        <mesh filename="package://drive_base_soto_2_0_description/meshes/base_link.STL" />
      </geometry>
      <material name="">
        <color rgba="0.529411764705882 0.549019607843137 0.549019607843137 1" />
      </material>
    </visual>
    <collision>
      <origin rpy="0 0 0" xyz="0 0 0" />
      <geometry>
        <mesh filename="package://drive_base_soto_2_0_description/meshes/base_link.STL" />
      </geometry>
    </collision>
  </link>
  <joint name="manipulator_base_to_base_link" type="fixed">
    <origin rpy="0 0 0" xyz="0.2365 0 -0.0385" />
    <parent link="base_link" />
    <child link="manipulator_base_link" />
  </joint>
  <link name="gripper_carrier_frame_link">
    <inertial>
      <origin rpy="0 0 0" xyz="0.419871261985957 -0.378092873023538 -0.172763052387008" />
      <mass value="22.6544046182285" />
      <inertia ixx="0.000978681072360067" ixy="5.36158454747139E-06" ixz="5.72288391326164E-05" iyy="0.212674313369314" iyz="-4.50383372113037E-05" izz="0.211729185697808" />
    </inertial>
    <visual>
      <origin rpy="0 0 0" xyz="0 0 0" />
      <geometry>
        <mesh filename="package://vertical_axis_soto_2_0_description/meshes/gripper_carrier_frame_link.STL" />
      </geometry>
      <material name="">
        <color rgba="0.752941176470588 0.752941176470588 0.752941176470588 1" />
      </material>
    </visual>
    <collision>
      <origin rpy="0 0 0" xyz="0 0 0" />
      <geometry>
        <mesh filename="package://vertical_axis_soto_2_0_description/meshes/gripper_carrier_frame_link.STL" />
      </geometry>
    </collision>
  </link>
  <joint name="vertical_axis_to_carrier_frame" type="fixed">
    <origin rpy="0 0 0" xyz="0 0 0.2565" />
    <parent link="vertical_axis_link" />
    <child link="gripper_carrier_frame_link" />
  </joint>
  
  <link name="manipulator_base_link">
    <inertial>
      <origin rpy="0 0 0" xyz="0.0140831490754253 -0.0103314828835449 1.03628074208567" />
      <mass value="49.4957057836692" />
      <inertia ixx="28.4337696303107" ixy="0.170730173040725" ixz="0.770352253194218" iyy="27.3913289655028" iyz="0.419406036104634" izz="15.9885561853555" />
    </inertial>
    <visual>
      <origin rpy="0 0 0" xyz="0 0 0" />
      <geometry>
        <mesh filename="package://vertical_axis_soto_2_0_description/meshes/manipulator_base_link.STL" />
      </geometry>
      <material name="">
        <color rgba="0.529411764705882 0.549019607843137 0.549019607843137 1" />
      </material>
    </visual>
    <collision>
      <origin rpy="0 0 0" xyz="0 0 0" />
      <geometry>
        <mesh filename="package://vertical_axis_soto_2_0_description/meshes/manipulator_base_link.STL" />
      </geometry>
    </collision>
  </link>
  <link name="vertical_axis_link">
    <inertial>
      <origin rpy="0 0 0" xyz="0.420000000000104 -0.147165343803046 0.0668738949005537" />
      <mass value="4.67274949695533" />
      <inertia ixx="0.605491366340649" ixy="-1.6991963391888E-13" ixz="2.22521653880925E-14" iyy="0.756041439643056" iyz="-0.0117324984712755" izz="1.35863466880556" />
    </inertial>
    <visual>
      <origin rpy="0 0 0" xyz="0 0 0.2565" />
      <geometry>
        <mesh filename="package://vertical_axis_soto_2_0_description/meshes/vertical_axis_link.STL" />
      </geometry>
      <material name="">
        <color rgba="0.647058823529412 0.619607843137255 0.588235294117647 1" />
      </material>
    </visual>
    <collision>
      <origin rpy="0 0 0" xyz="0 0 0.2565" />
      <geometry>
        <mesh filename="package://vertical_axis_soto_2_0_description/meshes/vertical_axis_link.STL" />
      </geometry>
    </collision>
  </link>
  <joint name="vertical_axis" type="prismatic">
    <origin rpy="0 0 0" xyz="-0.420000000000075 0.381609999999924 -0.488" />
    <parent link="manipulator_base_link" />
    <child link="vertical_axis_link" />
    <axis xyz="0 0 1" />
    <limit effort="1368.21" lower="0.355" upper="1.968" velocity="0.322917" />
  </joint>
  <joint name="gripper_rotate" type="revolute">
    <origin rpy="0 0 0" xyz="0.42 -0.378 -0.1425" />
    <parent link="gripper_carrier_frame_link" />
    <child link="gripper_base_link" />
    <axis xyz="0 0 1" />
    <limit effort="18.0" lower="-1.62316" upper="3.19395" velocity="1.84078" />
  </joint>
  
  <link name="gripper_base_link">
    <inertial>
      <origin rpy="0 0 0" xyz="-0.0291964947014054 0.00185928064465478 0.0571112330957645" />
      <mass value="4.43604003962018" />
      <inertia ixx="0.00848228102782677" ixy="-0.00397948149068779" ixz="-0.000197943829855595" iyy="0.0294439378703873" iyz="-4.43345350995509E-05" izz="0.0375329931767107" />
    </inertial>
    <visual>
      <origin rpy="0 0 0" xyz="0 0 0" />
      <geometry>
        <mesh filename="package://conveyor_gripper_1_0_description/meshes/gripper_base_link.STL" />
      </geometry>
      <material name="">
        <color rgba="1 1 1 1" />
      </material>
    </visual>
    <collision>
      <origin rpy="0 0 0" xyz="0 0 0" />
      <geometry>
        <mesh filename="package://conveyor_gripper_1_0_description/meshes/gripper_base_link.STL" />
      </geometry>
    </collision>
  </link>
  <link name="gripper_base_x_link">
    
    <inertial>
      <origin xyz="0 0 0" />
      <mass value="1.0" />
      <inertia ixx="0.00166666666667" ixy="0" ixz="0" iyy="0.00166666666667" iyz="0" izz="0.00166666666667" />
    </inertial>
    <visual>
      <origin rpy="0 0 0" xyz="0 0 0" />
      <geometry>
        <mesh filename="package://conveyor_gripper_1_0_description/meshes/gripper_base_x_link.STL" />
      </geometry>
      <material name="">
        <color rgba="0.752941176470588 0.752941176470588 0.752941176470588 1" />
      </material>
    </visual>
    <collision>
      <origin rpy="0 0 0" xyz="0 0 0" />
      <geometry>
        <mesh filename="package://conveyor_gripper_1_0_description/meshes/gripper_base_x_link.STL" />
      </geometry>
    </collision>
  </link>
  <joint name="gripper_base_x" type="prismatic">
    <origin rpy="0 0 0" xyz="-0.3105 0 0.0334999999999999" />
    <parent link="gripper_base_link" />
    <child link="gripper_base_x_link" />
    <axis xyz="1 0 0" />
    <limit effort="149.65" lower="0.002" upper="0.359" velocity="0.296" />
  </joint>
  
  <joint name="gripper_base_x_to_lateral_frame" type="fixed">
    <origin rpy="0 0 0" xyz="0.16682 0.00254 0.09900" />
    <parent link="gripper_base_x_link" />
    <child link="gripper_lateral_frame_link" />
    <axis xyz="0 0 0" />
  </joint>
  
  <link name="gripper_surface_tip_link" />
  <joint name="gripper_lateral_base_to_surface_tip" type="fixed">
    <origin rpy="0 0 0" xyz="0.5286 0 0.09824" />
    <parent link="gripper_lateral_frame_link" />
    <child link="gripper_surface_tip_link" />
  </joint>
  
  <link name="gripper_lateral_frame_link">
    <inertial>
      <origin rpy="0 0 0" xyz="0.0109523584667708 -0.00213924832383244 -0.0127104571800313" />
      <mass value="9.06374767181828" />
      <inertia ixx="0.152907857864764" ixy="-0.000359950628530387" ixz="-0.00123889187432906" iyy="0.0557080358972366" iyz="-0.000575501671994657" izz="0.206424853480047" />
    </inertial>
    <visual>
      <origin rpy="0 0 0" xyz="0 0 0" />
      <geometry>
        <mesh filename="package://conveyor_gripper_1_0_description/meshes/gripper_lateral_frame_link.STL" />
      </geometry>
      <material name="">
        <color rgba="0.752941176470588 0.752941176470588 0.752941176470588 1" />
      </material>
    </visual>
    <collision>
      <origin rpy="0 0 0" xyz="0 0 0" />
      <geometry>
        <mesh filename="package://conveyor_gripper_1_0_description/meshes/gripper_lateral_frame_link.STL" />
      </geometry>
    </collision>
  </link>
  <link name="gripper_y_right_link">
    <inertial>
      <origin rpy="0 0 0" xyz="0.00354228739566675 -0.0287875724844683 -0.0242552174069289" />
      <mass value="0.327260297311246" />
      <inertia ixx="0.000196526493426853" ixy="-2.29379028088093E-05" ixz="7.56584769951965E-05" iyy="0.000210428427291072" iyz="4.8646299306573E-05" izz="5.22867445641922E-05" />
    </inertial>
    <visual>
      <origin rpy="0 0 0" xyz="0 0 0" />
      <geometry>
        <mesh filename="package://conveyor_gripper_1_0_description/meshes/gripper_y_right_link.STL" />
      </geometry>
      <material name="">
        <color rgba="0.698039215686274 0.698039215686274 0.698039215686274 1" />
      </material>
    </visual>
    <collision>
      <origin rpy="0 0 0" xyz="0 0 0" />
      <geometry>
        <mesh filename="package://conveyor_gripper_1_0_description/meshes/gripper_y_right_link.STL" />
      </geometry>
    </collision>
  </link>
  <joint name="gripper_y_right" type="prismatic">
    <origin rpy="0 0 0" xyz="-0.1895 -0.291 0.0768" />
    <parent link="gripper_lateral_frame_link" />
    <child link="gripper_y_right_link" />
    <axis xyz="0 1 0" />
    <limit effort="36.9721" lower="0.002" upper="0.498" velocity="0.414175" />
  </joint>
  <link name="gripper_y_right_dist_x_sensor">
    
    <inertial>
      <origin xyz="0 0 0" />
      <mass value="0.206" />
      <inertia ixx="0.000343333333333" ixy="0" ixz="0" iyy="0.000343333333333" iyz="0" izz="0.000343333333333" />
    </inertial>
    <visual>
      <origin rpy="0 0 0" xyz="0 0 0" />
      <geometry>
        <mesh filename="package://conveyor_gripper_1_0_description/meshes/gripper_y_right_dist_x_sensor.STL" />
      </geometry>
      <material name="">
        <color rgba="1 1 1 1" />
      </material>
    </visual>
  </link>
  <joint name="gripper_y_right_to_dist_x_sensor" type="fixed">
    <origin rpy="1.5707963267949 8.45933770995668E-16 1.72247079380644E-16" xyz="-0.000773072340143593 -0.0340048054495324 0.0292" />
    <parent link="gripper_y_right_link" />
    <child link="gripper_y_right_dist_x_sensor" />
    <axis xyz="0 0 0" />
  </joint>
  <link name="gripper_y_left_link">
    <inertial>
      <origin rpy="0 0 0" xyz="0.00355881845944125 -0.0392124275155317 -0.0242552174069289" />
      <mass value="0.327260297311246" />
      <inertia ixx="0.000196526493426853" ixy="2.2946784360994E-05" ixz="7.58716206094717E-05" iyy="0.000210573949255188" iyz="-4.86462993065728E-05" izz="5.24322665283085E-05" />
    </inertial>
    <visual>
      <origin rpy="0 0 0" xyz="0 0 0" />
      <geometry>
        <mesh filename="package://conveyor_gripper_1_0_description/meshes/gripper_y_left_link.STL" />
      </geometry>
      <material name="">
        <color rgba="1 1 1 1" />
      </material>
    </visual>
    <collision>
      <origin rpy="0 0 0" xyz="0 0 0" />
      <geometry>
        <mesh filename="package://conveyor_gripper_1_0_description/meshes/gripper_y_left_link.STL" />
      </geometry>
    </collision>
  </link>
  <joint name="gripper_y_left" type="prismatic">
    <origin rpy="0 0 0" xyz="-0.1895 0.359 0.0768" />
    <parent link="gripper_lateral_frame_link" />
    <child link="gripper_y_left_link" />
    <axis xyz="0 -1 0" />
    <limit effort="36.9721" lower="0.002" upper="0.498" velocity="0.414175" />
  </joint>
  <link name="gripper_y_left_dist_x_sensor">
    
    <inertial>
      <origin xyz="0 0 0" />
      <mass value="0.206" />
      <inertia ixx="0.000343333333333" ixy="0" ixz="0" iyy="0.000343333333333" iyz="0" izz="0.000343333333333" />
    </inertial>
    <visual>
      <origin rpy="0 0 0" xyz="0 0 0" />
      <geometry>
        <mesh filename="package://conveyor_gripper_1_0_description/meshes/gripper_y_left_dist_x_sensor.STL" />
      </geometry>
      <material name="">
        <color rgba="1 1 1 1" />
      </material>
    </visual>
  </link>
  <joint name="gripper_y_left_to_dist_x_sensor" type="fixed">
    <origin rpy="-1.5707963267949 2.6257874588619E-16 4.90441639395184E-17" xyz="-0.00077307234014351 -0.0339951945504676 0.0292" />
    <parent link="gripper_y_left_link" />
    <child link="gripper_y_left_dist_x_sensor" />
    <axis xyz="0 0 0" />
  </joint>
  
  <joint name="gripper_y_right_to_belt_right" type="fixed">
    <parent link="gripper_y_right_link" />
    <child link="conveyor_belt_right_base_link" />
  </joint>
  
  <link name="conveyor_belt_right_link">
    
    <inertial>
      <origin xyz="0 0 0" />
      <mass value="0.5" />
      <inertia ixx="0.000833333333333" ixy="0" ixz="0" iyy="0.000833333333333" iyz="0" izz="0.000833333333333" />
    </inertial>
  </link>
  <joint name="conveyor_belt_right" type="prismatic">
    <origin rpy="0 0 0" xyz="0 0 0" />
    <parent link="conveyor_belt_right_surface_foremost_link" />
    <child link="conveyor_belt_right_link" />
    <axis xyz="-1 0 0" />
    
    <limit effort="30" lower="0" upper="0.60" velocity="1" />
  </joint>
  
  <link name="conveyor_belt_right_base_link">
    <inertial>
      <origin rpy="0 0 0" xyz="0.353839700449319 -0.0342492002501805 -0.0100000000278072" />
      <mass value="1.75237629293966" />
      <inertia ixx="0.00106107197657959" ixy="3.25747306440015E-06" ixz="3.63423703976073E-13" iyy="0.0518565044065418" iyz="-3.83928274166947E-14" izz="0.0519817058628901" />
    </inertial>
    <visual>
      <origin rpy="0 0 0" xyz="0 0 0" />
      <geometry>
        <mesh filename="package://conveyor_gripper_1_0_description/meshes/conveyor_belt_right_base_link.STL" />
      </geometry>
      <material name="">
        <color rgba="0.698039215686274 0.698039215686274 0.698039215686274 1" />
      </material>
    </visual>
    <collision>
      <origin rpy="0 0 0" xyz="0 0 0" />
      <geometry>
        <mesh filename="package://conveyor_gripper_1_0_description/meshes/conveyor_belt_right_base_link.STL" />
      </geometry>
    </collision>
  </link>
  <link name="conveyor_belt_right_foremost_link" />
  <joint name="belt_right_base_to_foremost" type="fixed">
    <origin rpy="0 0 0" xyz="0.718038238155445 -0.0339999999950005 0.02174" />
    <parent link="conveyor_belt_right_base_link" />
    <child link="conveyor_belt_right_foremost_link" />
    <axis xyz="0 0 0" />
  </joint>
  <link name="conveyor_belt_right_surface_foremost_link">
    
    <inertial>
      <origin xyz="0 0 0" />
      <mass value="0.01" />
      <inertia ixx="1.66666666667e-05" ixy="0" ixz="0" iyy="1.66666666667e-05" iyz="0" izz="1.66666666667e-05" />
    </inertial>
  </link>
  <joint name="belt_right_base_to_surface_foremost" type="fixed">
    <origin rpy="0 0 0" xyz="0.686298238155445 -0.0339999999950005 0.02174" />
    <parent link="conveyor_belt_right_base_link" />
    <child link="conveyor_belt_right_surface_foremost_link" />
    <axis xyz="0 0 0" />
  </joint>
  
  <joint name="gripper_y_left_to_belt" type="fixed">
    <parent link="gripper_y_left_link" />
    <child link="conveyor_belt_left_base_link" />
  </joint>
  
  <link name="conveyor_belt_left_link">
    
    <inertial>
      <origin xyz="0 0 0" />
      <mass value="0.5" />
      <inertia ixx="0.000833333333333" ixy="0" ixz="0" iyy="0.000833333333333" iyz="0" izz="0.000833333333333" />
    </inertial>
  </link>
  <joint name="conveyor_belt_left" type="prismatic">
    <origin rpy="0 0 0" xyz="0 0 0" />
    <parent link="conveyor_belt_left_surface_foremost_link" />
    <child link="conveyor_belt_left_link" />
    <axis xyz="-1 0 0" />
    
    <limit effort="30" lower="0" upper="0.60" velocity="1" />
  </joint>
  
  <link name="conveyor_belt_left_base_link">
    <inertial>
      <origin rpy="0 0 0" xyz="0.351579454282733 -0.0337525735461215 -0.00999999997239077" />
      <mass value="1.76493912170865" />
      <inertia ixx="0.00108186929664942" ixy="-4.24450588331179E-06" ixz="-4.73563126814083E-13" iyy="0.0531142162231874" iyz="-3.84792553638102E-14" izz="0.0532602149996055" />
    </inertial>
    <visual>
      <origin rpy="0 0 0" xyz="0 0 0" />
      <geometry>
        <mesh filename="package://conveyor_gripper_1_0_description/meshes/conveyor_belt_left_base_link.STL" />
      </geometry>
      <material name="">
        <color rgba="1 1 1 1" />
      </material>
    </visual>
    <collision>
      <origin rpy="0 0 0" xyz="0 0 0" />
      <geometry>
        <mesh filename="package://conveyor_gripper_1_0_description/meshes/conveyor_belt_left_base_link.STL" />
      </geometry>
    </collision>
  </link>
  <link name="conveyor_belt_left_foremost_link" />
  <joint name="base_left_to_foremost" type="fixed">
    <origin rpy="0 0 0" xyz="0.718038238155445 -0.0339999999950005 0.02174" />
    <parent link="conveyor_belt_left_base_link" />
    <child link="conveyor_belt_left_foremost_link" />
    <axis xyz="0 0 0" />
  </joint>
  <link name="conveyor_belt_left_surface_foremost_link">
    
    <inertial>
      <origin xyz="0 0 0" />
      <mass value="0.01" />
      <inertia ixx="1.66666666667e-05" ixy="0" ixz="0" iyy="1.66666666667e-05" iyz="0" izz="1.66666666667e-05" />
    </inertial>
  </link>
  <joint name="belt_left_to_surface_foremost" type="fixed">
    <origin rpy="0 0 0" xyz="0.686298238155445 -0.0339999999950005 0.02174" />
    <parent link="conveyor_belt_left_base_link" />
    <child link="conveyor_belt_left_surface_foremost_link" />
    <axis xyz="0 0 0" />
  </joint>
  <link name="conveyor_belt_left_barcode_camera">
    
    <inertial>
      <origin xyz="0 0 0" />
      <mass value="0.1" />
      <inertia ixx="0.000166666666667" ixy="0" ixz="0" iyy="0.000166666666667" iyz="0" izz="0.000166666666667" />
    </inertial>
    <visual>
      <origin rpy="0 0 0" xyz="0 0 0" />
      <geometry>
        <mesh filename="package://conveyor_gripper_1_0_description/meshes/conveyor_belt_left_barcode_camera.STL" />
      </geometry>
      <material name="">
        <color rgba="1 1 1 1" />
      </material>
    </visual>
  </link>
  <joint name="conveyor_base_left_to_barcode_camera" type="fixed">
    
    <origin rpy="1.3660676472658 0.00532358718963196 1.38245094245529" xyz="0.260007017149422 -0.122391992222825 -0.0116598009191592" />
    <parent link="conveyor_belt_left_base_link" />
    <child link="conveyor_belt_left_barcode_camera" />
    <axis xyz="0 0 0" />
  </joint>
  <link name="conveyor_belt_left_reflective_sensor">
    
    <inertial>
      <origin xyz="0 0 0" />
      <mass value="0.07" />
      <inertia ixx="0.000116666666667" ixy="0" ixz="0" iyy="0.000116666666667" iyz="0" izz="0.000116666666667" />
    </inertial>
    <visual>
      <origin rpy="0 0 0" xyz="0 0 0" />
      <geometry>
        <mesh filename="package://conveyor_gripper_1_0_description/meshes/conveyor_belt_left_reflective_sensor.STL" />
      </geometry>
      <material name="">
        <color rgba="1 1 1 1" />
      </material>
    </visual>
  </link>
  <joint name="conveyor_belt_left_base_to_reflective" type="fixed">
    <origin rpy="-1.5707963267949 1.45855003581176E-16 -5.73827871115263E-16" xyz="0.242349119077722 -0.0938499999900007 -0.0408000000099999" />
    <parent link="conveyor_belt_left_base_link" />
    <child link="conveyor_belt_left_reflective_sensor" />
    <axis xyz="0 0 0" />
  </joint>
  <link name="conveyor_belt_left_safety_dist_sensor">
    
    <inertial>
      <origin xyz="0 0 0" />
      <mass value="0.206" />
      <inertia ixx="0.000343333333333" ixy="0" ixz="0" iyy="0.000343333333333" iyz="0" izz="0.000343333333333" />
    </inertial>
    <visual>
      <origin rpy="0 0 0" xyz="0 0 0" />
      <geometry>
        <mesh filename="package://conveyor_gripper_1_0_description/meshes/conveyor_belt_left_safety_dist_sensor.STL" />
      </geometry>
      <material name="">
        <color rgba="1 1 1 1" />
      </material>
    </visual>
  </link>
  <joint name="conveyor_belt_left_base_to_safety_dist" type="fixed">
    <origin rpy="0 0 0" xyz="0.224026046737579 -0.0922499999900007 -0.0129951945604675" />
    <parent link="conveyor_belt_left_base_link" />
    <child link="conveyor_belt_left_safety_dist_sensor" />
    <axis xyz="0 0 0" />
  </joint>
  </robot>